[2024-10-22 14:56:14,787][flwr][INFO] - Starting Flower simulation, config: num_rounds=100, no round_timeout
[2024-10-22 14:56:17,899][flwr][INFO] - Flower VCE: Ray initialized with resources: {'CPU': 256.0, 'GPU': 5.0, 'accelerator_type:G': 1.0, 'object_store_memory': 75885819494.0, 'node:115.145.172.224': 1.0, 'node:__internal_head__': 1.0, 'memory': 167066912154.0}
[2024-10-22 14:56:17,900][flwr][INFO] - Optimize your simulation with Flower VCE: https://flower.ai/docs/framework/how-to-run-simulations.html
[2024-10-22 14:56:17,900][flwr][INFO] - Flower VCE: Resources for each Virtual Client: {'num_cpus': 16, 'num_gpus': 0.25}
[2024-10-22 14:56:17,918][flwr][INFO] - Flower VCE: Creating VirtualClientEngineActorPool with 16 actors
[2024-10-22 14:56:17,918][flwr][INFO] - [INIT]
[2024-10-22 14:56:17,918][flwr][INFO] - Requesting initial parameters from one random client
[2024-10-22 14:56:24,679][flwr][INFO] - Received initial parameters from one random client
[2024-10-22 14:56:24,680][flwr][INFO] - Evaluating initial global parameters
[2024-10-22 14:56:45,152][flwr][INFO] - initial parameters (loss, other metrics): 501.9215474128723, {'accuracy': 0.08955431754874651}
[2024-10-22 14:56:45,153][flwr][INFO] - 
[2024-10-22 14:56:45,153][flwr][INFO] - [ROUND 1]
[2024-10-22 14:56:45,153][flwr][INFO] - configure_fit: strategy sampled 5 clients (out of 50)
[2024-10-22 14:56:50,549][flwr][ERROR] - Traceback (most recent call last):
  File "/home/abdenour/.local/lib/python3.10/site-packages/flwr/simulation/ray_transport/ray_client_proxy.py", line 94, in _submit_job
    out_mssg, updated_context = self.actor_pool.get_client_result(
  File "/home/abdenour/.local/lib/python3.10/site-packages/flwr/simulation/ray_transport/ray_actor.py", line 398, in get_client_result
    return self._fetch_future_result(cid)
  File "/home/abdenour/.local/lib/python3.10/site-packages/flwr/simulation/ray_transport/ray_actor.py", line 279, in _fetch_future_result
    res_cid, out_mssg, updated_context = ray.get(
  File "/home/abdenour/.local/lib/python3.10/site-packages/ray/_private/auto_init_hook.py", line 21, in auto_init_wrapper
    return fn(*args, **kwargs)
  File "/home/abdenour/.local/lib/python3.10/site-packages/ray/_private/client_mode_hook.py", line 103, in wrapper
    return func(*args, **kwargs)
  File "/home/abdenour/.local/lib/python3.10/site-packages/ray/_private/worker.py", line 2667, in get
    values, debugger_breakpoint = worker.get_objects(object_refs, timeout=timeout)
  File "/home/abdenour/.local/lib/python3.10/site-packages/ray/_private/worker.py", line 864, in get_objects
    raise value.as_instanceof_cause()
ray.exceptions.RayTaskError(ClientAppException): [36mray::ClientAppActor.run()[39m (pid=3341814, ip=115.145.172.224, actor_id=50d8ef4247febf9234280d4401000000, repr=<flwr.simulation.ray_transport.ray_actor.ClientAppActor object at 0x7fa78c789a20>)
  File "/home/abdenour/.local/lib/python3.10/site-packages/flwr/client/client_app.py", line 143, in __call__
    return self._call(message, context)
  File "/home/abdenour/.local/lib/python3.10/site-packages/flwr/client/client_app.py", line 126, in ffn
    out_message = handle_legacy_message_from_msgtype(
  File "/home/abdenour/.local/lib/python3.10/site-packages/flwr/client/message_handler/message_handler.py", line 95, in handle_legacy_message_from_msgtype
    client = client_fn(context)
  File "/home/abdenour/fl_with_flower/fednova_vgg16/fednova_vgg16/client.py", line 133, in client_fn
    return FlowerClient(trainset, valset, num_classes, config_fit, client_dataset_ratio, context.node_config).to_client()
  File "/home/abdenour/fl_with_flower/fednova_vgg16/fednova_vgg16/client.py", line 40, in __init__
    self.model = self.model.to(self.device)
  File "/home/abdenour/anaconda3/envs/fl/lib/python3.10/site-packages/torch/nn/modules/module.py", line 1174, in to
    return self._apply(convert)
  File "/home/abdenour/anaconda3/envs/fl/lib/python3.10/site-packages/torch/nn/modules/module.py", line 780, in _apply
    module._apply(fn)
  File "/home/abdenour/anaconda3/envs/fl/lib/python3.10/site-packages/torch/nn/modules/module.py", line 780, in _apply
    module._apply(fn)
  File "/home/abdenour/anaconda3/envs/fl/lib/python3.10/site-packages/torch/nn/modules/module.py", line 805, in _apply
    param_applied = fn(param)
  File "/home/abdenour/anaconda3/envs/fl/lib/python3.10/site-packages/torch/nn/modules/module.py", line 1160, in convert
    return t.to(
torch.OutOfMemoryError: CUDA out of memory. Tried to allocate 64.00 MiB. GPU 0 has a total capacity of 10.75 GiB of which 24.75 MiB is free. Process 3341815 has 10.09 GiB memory in use. Including non-PyTorch memory, this process has 648.00 MiB memory in use. Of the allocated memory 468.40 MiB is allocated by PyTorch, and 25.60 MiB is reserved by PyTorch but unallocated. If reserved but unallocated memory is large try setting PYTORCH_CUDA_ALLOC_CONF=expandable_segments:True to avoid fragmentation.  See documentation for Memory Management  (https://pytorch.org/docs/stable/notes/cuda.html#environment-variables)

The above exception was the direct cause of the following exception:

[36mray::ClientAppActor.run()[39m (pid=3341814, ip=115.145.172.224, actor_id=50d8ef4247febf9234280d4401000000, repr=<flwr.simulation.ray_transport.ray_actor.ClientAppActor object at 0x7fa78c789a20>)
  File "/home/abdenour/.local/lib/python3.10/site-packages/flwr/simulation/ray_transport/ray_actor.py", line 63, in run
    raise ClientAppException(str(ex)) from ex
flwr.client.client_app.ClientAppException: 
Exception ClientAppException occurred. Message: CUDA out of memory. Tried to allocate 64.00 MiB. GPU 0 has a total capacity of 10.75 GiB of which 24.75 MiB is free. Process 3341815 has 10.09 GiB memory in use. Including non-PyTorch memory, this process has 648.00 MiB memory in use. Of the allocated memory 468.40 MiB is allocated by PyTorch, and 25.60 MiB is reserved by PyTorch but unallocated. If reserved but unallocated memory is large try setting PYTORCH_CUDA_ALLOC_CONF=expandable_segments:True to avoid fragmentation.  See documentation for Memory Management  (https://pytorch.org/docs/stable/notes/cuda.html#environment-variables)

[2024-10-22 14:56:50,549][flwr][ERROR] - [36mray::ClientAppActor.run()[39m (pid=3341814, ip=115.145.172.224, actor_id=50d8ef4247febf9234280d4401000000, repr=<flwr.simulation.ray_transport.ray_actor.ClientAppActor object at 0x7fa78c789a20>)
  File "/home/abdenour/.local/lib/python3.10/site-packages/flwr/client/client_app.py", line 143, in __call__
    return self._call(message, context)
  File "/home/abdenour/.local/lib/python3.10/site-packages/flwr/client/client_app.py", line 126, in ffn
    out_message = handle_legacy_message_from_msgtype(
  File "/home/abdenour/.local/lib/python3.10/site-packages/flwr/client/message_handler/message_handler.py", line 95, in handle_legacy_message_from_msgtype
    client = client_fn(context)
  File "/home/abdenour/fl_with_flower/fednova_vgg16/fednova_vgg16/client.py", line 133, in client_fn
    return FlowerClient(trainset, valset, num_classes, config_fit, client_dataset_ratio, context.node_config).to_client()
  File "/home/abdenour/fl_with_flower/fednova_vgg16/fednova_vgg16/client.py", line 40, in __init__
    self.model = self.model.to(self.device)
  File "/home/abdenour/anaconda3/envs/fl/lib/python3.10/site-packages/torch/nn/modules/module.py", line 1174, in to
    return self._apply(convert)
  File "/home/abdenour/anaconda3/envs/fl/lib/python3.10/site-packages/torch/nn/modules/module.py", line 780, in _apply
    module._apply(fn)
  File "/home/abdenour/anaconda3/envs/fl/lib/python3.10/site-packages/torch/nn/modules/module.py", line 780, in _apply
    module._apply(fn)
  File "/home/abdenour/anaconda3/envs/fl/lib/python3.10/site-packages/torch/nn/modules/module.py", line 805, in _apply
    param_applied = fn(param)
  File "/home/abdenour/anaconda3/envs/fl/lib/python3.10/site-packages/torch/nn/modules/module.py", line 1160, in convert
    return t.to(
torch.OutOfMemoryError: CUDA out of memory. Tried to allocate 64.00 MiB. GPU 0 has a total capacity of 10.75 GiB of which 24.75 MiB is free. Process 3341815 has 10.09 GiB memory in use. Including non-PyTorch memory, this process has 648.00 MiB memory in use. Of the allocated memory 468.40 MiB is allocated by PyTorch, and 25.60 MiB is reserved by PyTorch but unallocated. If reserved but unallocated memory is large try setting PYTORCH_CUDA_ALLOC_CONF=expandable_segments:True to avoid fragmentation.  See documentation for Memory Management  (https://pytorch.org/docs/stable/notes/cuda.html#environment-variables)

The above exception was the direct cause of the following exception:

[36mray::ClientAppActor.run()[39m (pid=3341814, ip=115.145.172.224, actor_id=50d8ef4247febf9234280d4401000000, repr=<flwr.simulation.ray_transport.ray_actor.ClientAppActor object at 0x7fa78c789a20>)
  File "/home/abdenour/.local/lib/python3.10/site-packages/flwr/simulation/ray_transport/ray_actor.py", line 63, in run
    raise ClientAppException(str(ex)) from ex
flwr.client.client_app.ClientAppException: 
Exception ClientAppException occurred. Message: CUDA out of memory. Tried to allocate 64.00 MiB. GPU 0 has a total capacity of 10.75 GiB of which 24.75 MiB is free. Process 3341815 has 10.09 GiB memory in use. Including non-PyTorch memory, this process has 648.00 MiB memory in use. Of the allocated memory 468.40 MiB is allocated by PyTorch, and 25.60 MiB is reserved by PyTorch but unallocated. If reserved but unallocated memory is large try setting PYTORCH_CUDA_ALLOC_CONF=expandable_segments:True to avoid fragmentation.  See documentation for Memory Management  (https://pytorch.org/docs/stable/notes/cuda.html#environment-variables)
[2024-10-22 14:56:51,123][flwr][ERROR] - Traceback (most recent call last):
  File "/home/abdenour/.local/lib/python3.10/site-packages/flwr/simulation/ray_transport/ray_client_proxy.py", line 94, in _submit_job
    out_mssg, updated_context = self.actor_pool.get_client_result(
  File "/home/abdenour/.local/lib/python3.10/site-packages/flwr/simulation/ray_transport/ray_actor.py", line 398, in get_client_result
    return self._fetch_future_result(cid)
  File "/home/abdenour/.local/lib/python3.10/site-packages/flwr/simulation/ray_transport/ray_actor.py", line 279, in _fetch_future_result
    res_cid, out_mssg, updated_context = ray.get(
  File "/home/abdenour/.local/lib/python3.10/site-packages/ray/_private/auto_init_hook.py", line 21, in auto_init_wrapper
    return fn(*args, **kwargs)
  File "/home/abdenour/.local/lib/python3.10/site-packages/ray/_private/client_mode_hook.py", line 103, in wrapper
    return func(*args, **kwargs)
  File "/home/abdenour/.local/lib/python3.10/site-packages/ray/_private/worker.py", line 2667, in get
    values, debugger_breakpoint = worker.get_objects(object_refs, timeout=timeout)
  File "/home/abdenour/.local/lib/python3.10/site-packages/ray/_private/worker.py", line 864, in get_objects
    raise value.as_instanceof_cause()
ray.exceptions.RayTaskError(ClientAppException): [36mray::ClientAppActor.run()[39m (pid=3341813, ip=115.145.172.224, actor_id=e06687632bf1b1159dbb9c2c01000000, repr=<flwr.simulation.ray_transport.ray_actor.ClientAppActor object at 0x7faf50689a50>)
  File "/home/abdenour/.local/lib/python3.10/site-packages/flwr/client/client_app.py", line 143, in __call__
    return self._call(message, context)
  File "/home/abdenour/.local/lib/python3.10/site-packages/flwr/client/client_app.py", line 126, in ffn
    out_message = handle_legacy_message_from_msgtype(
  File "/home/abdenour/.local/lib/python3.10/site-packages/flwr/client/message_handler/message_handler.py", line 95, in handle_legacy_message_from_msgtype
    client = client_fn(context)
  File "/home/abdenour/fl_with_flower/fednova_vgg16/fednova_vgg16/client.py", line 133, in client_fn
    return FlowerClient(trainset, valset, num_classes, config_fit, client_dataset_ratio, context.node_config).to_client()
  File "/home/abdenour/fl_with_flower/fednova_vgg16/fednova_vgg16/client.py", line 40, in __init__
    self.model = self.model.to(self.device)
  File "/home/abdenour/anaconda3/envs/fl/lib/python3.10/site-packages/torch/nn/modules/module.py", line 1174, in to
    return self._apply(convert)
  File "/home/abdenour/anaconda3/envs/fl/lib/python3.10/site-packages/torch/nn/modules/module.py", line 780, in _apply
    module._apply(fn)
  File "/home/abdenour/anaconda3/envs/fl/lib/python3.10/site-packages/torch/nn/modules/module.py", line 780, in _apply
    module._apply(fn)
  File "/home/abdenour/anaconda3/envs/fl/lib/python3.10/site-packages/torch/nn/modules/module.py", line 805, in _apply
    param_applied = fn(param)
  File "/home/abdenour/anaconda3/envs/fl/lib/python3.10/site-packages/torch/nn/modules/module.py", line 1160, in convert
    return t.to(
RuntimeError: CUDA error: out of memory
CUDA kernel errors might be asynchronously reported at some other API call, so the stacktrace below might be incorrect.
For debugging consider passing CUDA_LAUNCH_BLOCKING=1
Compile with `TORCH_USE_CUDA_DSA` to enable device-side assertions.


The above exception was the direct cause of the following exception:

[36mray::ClientAppActor.run()[39m (pid=3341813, ip=115.145.172.224, actor_id=e06687632bf1b1159dbb9c2c01000000, repr=<flwr.simulation.ray_transport.ray_actor.ClientAppActor object at 0x7faf50689a50>)
  File "/home/abdenour/.local/lib/python3.10/site-packages/flwr/simulation/ray_transport/ray_actor.py", line 63, in run
    raise ClientAppException(str(ex)) from ex
flwr.client.client_app.ClientAppException: 
Exception ClientAppException occurred. Message: CUDA error: out of memory
CUDA kernel errors might be asynchronously reported at some other API call, so the stacktrace below might be incorrect.
For debugging consider passing CUDA_LAUNCH_BLOCKING=1
Compile with `TORCH_USE_CUDA_DSA` to enable device-side assertions.

[2024-10-22 14:56:51,123][flwr][ERROR] - [36mray::ClientAppActor.run()[39m (pid=3341813, ip=115.145.172.224, actor_id=e06687632bf1b1159dbb9c2c01000000, repr=<flwr.simulation.ray_transport.ray_actor.ClientAppActor object at 0x7faf50689a50>)
  File "/home/abdenour/.local/lib/python3.10/site-packages/flwr/client/client_app.py", line 143, in __call__
    return self._call(message, context)
  File "/home/abdenour/.local/lib/python3.10/site-packages/flwr/client/client_app.py", line 126, in ffn
    out_message = handle_legacy_message_from_msgtype(
  File "/home/abdenour/.local/lib/python3.10/site-packages/flwr/client/message_handler/message_handler.py", line 95, in handle_legacy_message_from_msgtype
    client = client_fn(context)
  File "/home/abdenour/fl_with_flower/fednova_vgg16/fednova_vgg16/client.py", line 133, in client_fn
    return FlowerClient(trainset, valset, num_classes, config_fit, client_dataset_ratio, context.node_config).to_client()
  File "/home/abdenour/fl_with_flower/fednova_vgg16/fednova_vgg16/client.py", line 40, in __init__
    self.model = self.model.to(self.device)
  File "/home/abdenour/anaconda3/envs/fl/lib/python3.10/site-packages/torch/nn/modules/module.py", line 1174, in to
    return self._apply(convert)
  File "/home/abdenour/anaconda3/envs/fl/lib/python3.10/site-packages/torch/nn/modules/module.py", line 780, in _apply
    module._apply(fn)
  File "/home/abdenour/anaconda3/envs/fl/lib/python3.10/site-packages/torch/nn/modules/module.py", line 780, in _apply
    module._apply(fn)
  File "/home/abdenour/anaconda3/envs/fl/lib/python3.10/site-packages/torch/nn/modules/module.py", line 805, in _apply
    param_applied = fn(param)
  File "/home/abdenour/anaconda3/envs/fl/lib/python3.10/site-packages/torch/nn/modules/module.py", line 1160, in convert
    return t.to(
RuntimeError: CUDA error: out of memory
CUDA kernel errors might be asynchronously reported at some other API call, so the stacktrace below might be incorrect.
For debugging consider passing CUDA_LAUNCH_BLOCKING=1
Compile with `TORCH_USE_CUDA_DSA` to enable device-side assertions.


The above exception was the direct cause of the following exception:

[36mray::ClientAppActor.run()[39m (pid=3341813, ip=115.145.172.224, actor_id=e06687632bf1b1159dbb9c2c01000000, repr=<flwr.simulation.ray_transport.ray_actor.ClientAppActor object at 0x7faf50689a50>)
  File "/home/abdenour/.local/lib/python3.10/site-packages/flwr/simulation/ray_transport/ray_actor.py", line 63, in run
    raise ClientAppException(str(ex)) from ex
flwr.client.client_app.ClientAppException: 
Exception ClientAppException occurred. Message: CUDA error: out of memory
CUDA kernel errors might be asynchronously reported at some other API call, so the stacktrace below might be incorrect.
For debugging consider passing CUDA_LAUNCH_BLOCKING=1
Compile with `TORCH_USE_CUDA_DSA` to enable device-side assertions.
[2024-10-22 14:56:51,895][flwr][ERROR] - Traceback (most recent call last):
  File "/home/abdenour/.local/lib/python3.10/site-packages/flwr/simulation/ray_transport/ray_client_proxy.py", line 94, in _submit_job
    out_mssg, updated_context = self.actor_pool.get_client_result(
  File "/home/abdenour/.local/lib/python3.10/site-packages/flwr/simulation/ray_transport/ray_actor.py", line 398, in get_client_result
    return self._fetch_future_result(cid)
  File "/home/abdenour/.local/lib/python3.10/site-packages/flwr/simulation/ray_transport/ray_actor.py", line 279, in _fetch_future_result
    res_cid, out_mssg, updated_context = ray.get(
  File "/home/abdenour/.local/lib/python3.10/site-packages/ray/_private/auto_init_hook.py", line 21, in auto_init_wrapper
    return fn(*args, **kwargs)
  File "/home/abdenour/.local/lib/python3.10/site-packages/ray/_private/client_mode_hook.py", line 103, in wrapper
    return func(*args, **kwargs)
  File "/home/abdenour/.local/lib/python3.10/site-packages/ray/_private/worker.py", line 2667, in get
    values, debugger_breakpoint = worker.get_objects(object_refs, timeout=timeout)
  File "/home/abdenour/.local/lib/python3.10/site-packages/ray/_private/worker.py", line 864, in get_objects
    raise value.as_instanceof_cause()
ray.exceptions.RayTaskError(ClientAppException): [36mray::ClientAppActor.run()[39m (pid=3341812, ip=115.145.172.224, actor_id=b1c85204e13efdf6edbfd66901000000, repr=<flwr.simulation.ray_transport.ray_actor.ClientAppActor object at 0x7f3da8095a20>)
  File "/home/abdenour/.local/lib/python3.10/site-packages/flwr/client/client_app.py", line 143, in __call__
    return self._call(message, context)
  File "/home/abdenour/.local/lib/python3.10/site-packages/flwr/client/client_app.py", line 126, in ffn
    out_message = handle_legacy_message_from_msgtype(
  File "/home/abdenour/.local/lib/python3.10/site-packages/flwr/client/message_handler/message_handler.py", line 95, in handle_legacy_message_from_msgtype
    client = client_fn(context)
  File "/home/abdenour/fl_with_flower/fednova_vgg16/fednova_vgg16/client.py", line 133, in client_fn
    return FlowerClient(trainset, valset, num_classes, config_fit, client_dataset_ratio, context.node_config).to_client()
  File "/home/abdenour/fl_with_flower/fednova_vgg16/fednova_vgg16/client.py", line 40, in __init__
    self.model = self.model.to(self.device)
  File "/home/abdenour/anaconda3/envs/fl/lib/python3.10/site-packages/torch/nn/modules/module.py", line 1174, in to
    return self._apply(convert)
  File "/home/abdenour/anaconda3/envs/fl/lib/python3.10/site-packages/torch/nn/modules/module.py", line 780, in _apply
    module._apply(fn)
  File "/home/abdenour/anaconda3/envs/fl/lib/python3.10/site-packages/torch/nn/modules/module.py", line 780, in _apply
    module._apply(fn)
  File "/home/abdenour/anaconda3/envs/fl/lib/python3.10/site-packages/torch/nn/modules/module.py", line 805, in _apply
    param_applied = fn(param)
  File "/home/abdenour/anaconda3/envs/fl/lib/python3.10/site-packages/torch/nn/modules/module.py", line 1160, in convert
    return t.to(
RuntimeError: CUDA error: out of memory
CUDA kernel errors might be asynchronously reported at some other API call, so the stacktrace below might be incorrect.
For debugging consider passing CUDA_LAUNCH_BLOCKING=1
Compile with `TORCH_USE_CUDA_DSA` to enable device-side assertions.


The above exception was the direct cause of the following exception:

[36mray::ClientAppActor.run()[39m (pid=3341812, ip=115.145.172.224, actor_id=b1c85204e13efdf6edbfd66901000000, repr=<flwr.simulation.ray_transport.ray_actor.ClientAppActor object at 0x7f3da8095a20>)
  File "/home/abdenour/.local/lib/python3.10/site-packages/flwr/simulation/ray_transport/ray_actor.py", line 63, in run
    raise ClientAppException(str(ex)) from ex
flwr.client.client_app.ClientAppException: 
Exception ClientAppException occurred. Message: CUDA error: out of memory
CUDA kernel errors might be asynchronously reported at some other API call, so the stacktrace below might be incorrect.
For debugging consider passing CUDA_LAUNCH_BLOCKING=1
Compile with `TORCH_USE_CUDA_DSA` to enable device-side assertions.

[2024-10-22 14:56:51,896][flwr][ERROR] - [36mray::ClientAppActor.run()[39m (pid=3341812, ip=115.145.172.224, actor_id=b1c85204e13efdf6edbfd66901000000, repr=<flwr.simulation.ray_transport.ray_actor.ClientAppActor object at 0x7f3da8095a20>)
  File "/home/abdenour/.local/lib/python3.10/site-packages/flwr/client/client_app.py", line 143, in __call__
    return self._call(message, context)
  File "/home/abdenour/.local/lib/python3.10/site-packages/flwr/client/client_app.py", line 126, in ffn
    out_message = handle_legacy_message_from_msgtype(
  File "/home/abdenour/.local/lib/python3.10/site-packages/flwr/client/message_handler/message_handler.py", line 95, in handle_legacy_message_from_msgtype
    client = client_fn(context)
  File "/home/abdenour/fl_with_flower/fednova_vgg16/fednova_vgg16/client.py", line 133, in client_fn
    return FlowerClient(trainset, valset, num_classes, config_fit, client_dataset_ratio, context.node_config).to_client()
  File "/home/abdenour/fl_with_flower/fednova_vgg16/fednova_vgg16/client.py", line 40, in __init__
    self.model = self.model.to(self.device)
  File "/home/abdenour/anaconda3/envs/fl/lib/python3.10/site-packages/torch/nn/modules/module.py", line 1174, in to
    return self._apply(convert)
  File "/home/abdenour/anaconda3/envs/fl/lib/python3.10/site-packages/torch/nn/modules/module.py", line 780, in _apply
    module._apply(fn)
  File "/home/abdenour/anaconda3/envs/fl/lib/python3.10/site-packages/torch/nn/modules/module.py", line 780, in _apply
    module._apply(fn)
  File "/home/abdenour/anaconda3/envs/fl/lib/python3.10/site-packages/torch/nn/modules/module.py", line 805, in _apply
    param_applied = fn(param)
  File "/home/abdenour/anaconda3/envs/fl/lib/python3.10/site-packages/torch/nn/modules/module.py", line 1160, in convert
    return t.to(
RuntimeError: CUDA error: out of memory
CUDA kernel errors might be asynchronously reported at some other API call, so the stacktrace below might be incorrect.
For debugging consider passing CUDA_LAUNCH_BLOCKING=1
Compile with `TORCH_USE_CUDA_DSA` to enable device-side assertions.


The above exception was the direct cause of the following exception:

[36mray::ClientAppActor.run()[39m (pid=3341812, ip=115.145.172.224, actor_id=b1c85204e13efdf6edbfd66901000000, repr=<flwr.simulation.ray_transport.ray_actor.ClientAppActor object at 0x7f3da8095a20>)
  File "/home/abdenour/.local/lib/python3.10/site-packages/flwr/simulation/ray_transport/ray_actor.py", line 63, in run
    raise ClientAppException(str(ex)) from ex
flwr.client.client_app.ClientAppException: 
Exception ClientAppException occurred. Message: CUDA error: out of memory
CUDA kernel errors might be asynchronously reported at some other API call, so the stacktrace below might be incorrect.
For debugging consider passing CUDA_LAUNCH_BLOCKING=1
Compile with `TORCH_USE_CUDA_DSA` to enable device-side assertions.
[2024-10-22 14:57:24,242][flwr][INFO] - aggregate_fit: received 2 results and 3 failures
[2024-10-22 14:57:24,819][flwr][WARNING] - No fit_metrics_aggregation_fn provided
[2024-10-22 14:57:44,095][flwr][INFO] - fit progress: (1, 806.6016161441803, {'accuracy': 0.18913649025069637}, 58.94166136253625)
[2024-10-22 14:57:44,095][flwr][INFO] - configure_evaluate: strategy sampled 2 clients (out of 50)
[2024-10-22 14:57:47,453][flwr][INFO] - aggregate_evaluate: received 2 results and 0 failures
[2024-10-22 14:57:47,454][flwr][INFO] - 
[2024-10-22 14:57:47,454][flwr][INFO] - [ROUND 2]
[2024-10-22 14:57:47,454][flwr][INFO] - configure_fit: strategy sampled 5 clients (out of 50)
[2024-10-22 14:57:50,207][flwr][ERROR] - Traceback (most recent call last):
  File "/home/abdenour/.local/lib/python3.10/site-packages/flwr/simulation/ray_transport/ray_client_proxy.py", line 94, in _submit_job
    out_mssg, updated_context = self.actor_pool.get_client_result(
  File "/home/abdenour/.local/lib/python3.10/site-packages/flwr/simulation/ray_transport/ray_actor.py", line 398, in get_client_result
    return self._fetch_future_result(cid)
  File "/home/abdenour/.local/lib/python3.10/site-packages/flwr/simulation/ray_transport/ray_actor.py", line 279, in _fetch_future_result
    res_cid, out_mssg, updated_context = ray.get(
  File "/home/abdenour/.local/lib/python3.10/site-packages/ray/_private/auto_init_hook.py", line 21, in auto_init_wrapper
    return fn(*args, **kwargs)
  File "/home/abdenour/.local/lib/python3.10/site-packages/ray/_private/client_mode_hook.py", line 103, in wrapper
    return func(*args, **kwargs)
  File "/home/abdenour/.local/lib/python3.10/site-packages/ray/_private/worker.py", line 2667, in get
    values, debugger_breakpoint = worker.get_objects(object_refs, timeout=timeout)
  File "/home/abdenour/.local/lib/python3.10/site-packages/ray/_private/worker.py", line 864, in get_objects
    raise value.as_instanceof_cause()
ray.exceptions.RayTaskError(ClientAppException): [36mray::ClientAppActor.run()[39m (pid=3341812, ip=115.145.172.224, actor_id=b1c85204e13efdf6edbfd66901000000, repr=<flwr.simulation.ray_transport.ray_actor.ClientAppActor object at 0x7f3da8095a20>)
  File "/home/abdenour/.local/lib/python3.10/site-packages/flwr/client/client_app.py", line 143, in __call__
    return self._call(message, context)
  File "/home/abdenour/.local/lib/python3.10/site-packages/flwr/client/client_app.py", line 126, in ffn
    out_message = handle_legacy_message_from_msgtype(
  File "/home/abdenour/.local/lib/python3.10/site-packages/flwr/client/message_handler/message_handler.py", line 95, in handle_legacy_message_from_msgtype
    client = client_fn(context)
  File "/home/abdenour/fl_with_flower/fednova_vgg16/fednova_vgg16/client.py", line 133, in client_fn
    return FlowerClient(trainset, valset, num_classes, config_fit, client_dataset_ratio, context.node_config).to_client()
  File "/home/abdenour/fl_with_flower/fednova_vgg16/fednova_vgg16/client.py", line 40, in __init__
    self.model = self.model.to(self.device)
  File "/home/abdenour/anaconda3/envs/fl/lib/python3.10/site-packages/torch/nn/modules/module.py", line 1174, in to
    return self._apply(convert)
  File "/home/abdenour/anaconda3/envs/fl/lib/python3.10/site-packages/torch/nn/modules/module.py", line 780, in _apply
    module._apply(fn)
  File "/home/abdenour/anaconda3/envs/fl/lib/python3.10/site-packages/torch/nn/modules/module.py", line 780, in _apply
    module._apply(fn)
  File "/home/abdenour/anaconda3/envs/fl/lib/python3.10/site-packages/torch/nn/modules/module.py", line 805, in _apply
    param_applied = fn(param)
  File "/home/abdenour/anaconda3/envs/fl/lib/python3.10/site-packages/torch/nn/modules/module.py", line 1160, in convert
    return t.to(
RuntimeError: CUDA error: out of memory
CUDA kernel errors might be asynchronously reported at some other API call, so the stacktrace below might be incorrect.
For debugging consider passing CUDA_LAUNCH_BLOCKING=1
Compile with `TORCH_USE_CUDA_DSA` to enable device-side assertions.


The above exception was the direct cause of the following exception:

[36mray::ClientAppActor.run()[39m (pid=3341812, ip=115.145.172.224, actor_id=b1c85204e13efdf6edbfd66901000000, repr=<flwr.simulation.ray_transport.ray_actor.ClientAppActor object at 0x7f3da8095a20>)
  File "/home/abdenour/.local/lib/python3.10/site-packages/flwr/simulation/ray_transport/ray_actor.py", line 63, in run
    raise ClientAppException(str(ex)) from ex
flwr.client.client_app.ClientAppException: 
Exception ClientAppException occurred. Message: CUDA error: out of memory
CUDA kernel errors might be asynchronously reported at some other API call, so the stacktrace below might be incorrect.
For debugging consider passing CUDA_LAUNCH_BLOCKING=1
Compile with `TORCH_USE_CUDA_DSA` to enable device-side assertions.

[2024-10-22 14:57:50,207][flwr][ERROR] - [36mray::ClientAppActor.run()[39m (pid=3341812, ip=115.145.172.224, actor_id=b1c85204e13efdf6edbfd66901000000, repr=<flwr.simulation.ray_transport.ray_actor.ClientAppActor object at 0x7f3da8095a20>)
  File "/home/abdenour/.local/lib/python3.10/site-packages/flwr/client/client_app.py", line 143, in __call__
    return self._call(message, context)
  File "/home/abdenour/.local/lib/python3.10/site-packages/flwr/client/client_app.py", line 126, in ffn
    out_message = handle_legacy_message_from_msgtype(
  File "/home/abdenour/.local/lib/python3.10/site-packages/flwr/client/message_handler/message_handler.py", line 95, in handle_legacy_message_from_msgtype
    client = client_fn(context)
  File "/home/abdenour/fl_with_flower/fednova_vgg16/fednova_vgg16/client.py", line 133, in client_fn
    return FlowerClient(trainset, valset, num_classes, config_fit, client_dataset_ratio, context.node_config).to_client()
  File "/home/abdenour/fl_with_flower/fednova_vgg16/fednova_vgg16/client.py", line 40, in __init__
    self.model = self.model.to(self.device)
  File "/home/abdenour/anaconda3/envs/fl/lib/python3.10/site-packages/torch/nn/modules/module.py", line 1174, in to
    return self._apply(convert)
  File "/home/abdenour/anaconda3/envs/fl/lib/python3.10/site-packages/torch/nn/modules/module.py", line 780, in _apply
    module._apply(fn)
  File "/home/abdenour/anaconda3/envs/fl/lib/python3.10/site-packages/torch/nn/modules/module.py", line 780, in _apply
    module._apply(fn)
  File "/home/abdenour/anaconda3/envs/fl/lib/python3.10/site-packages/torch/nn/modules/module.py", line 805, in _apply
    param_applied = fn(param)
  File "/home/abdenour/anaconda3/envs/fl/lib/python3.10/site-packages/torch/nn/modules/module.py", line 1160, in convert
    return t.to(
RuntimeError: CUDA error: out of memory
CUDA kernel errors might be asynchronously reported at some other API call, so the stacktrace below might be incorrect.
For debugging consider passing CUDA_LAUNCH_BLOCKING=1
Compile with `TORCH_USE_CUDA_DSA` to enable device-side assertions.


The above exception was the direct cause of the following exception:

[36mray::ClientAppActor.run()[39m (pid=3341812, ip=115.145.172.224, actor_id=b1c85204e13efdf6edbfd66901000000, repr=<flwr.simulation.ray_transport.ray_actor.ClientAppActor object at 0x7f3da8095a20>)
  File "/home/abdenour/.local/lib/python3.10/site-packages/flwr/simulation/ray_transport/ray_actor.py", line 63, in run
    raise ClientAppException(str(ex)) from ex
flwr.client.client_app.ClientAppException: 
Exception ClientAppException occurred. Message: CUDA error: out of memory
CUDA kernel errors might be asynchronously reported at some other API call, so the stacktrace below might be incorrect.
For debugging consider passing CUDA_LAUNCH_BLOCKING=1
Compile with `TORCH_USE_CUDA_DSA` to enable device-side assertions.
[2024-10-22 14:57:50,702][flwr][ERROR] - Traceback (most recent call last):
  File "/home/abdenour/.local/lib/python3.10/site-packages/flwr/simulation/ray_transport/ray_client_proxy.py", line 94, in _submit_job
    out_mssg, updated_context = self.actor_pool.get_client_result(
  File "/home/abdenour/.local/lib/python3.10/site-packages/flwr/simulation/ray_transport/ray_actor.py", line 398, in get_client_result
    return self._fetch_future_result(cid)
  File "/home/abdenour/.local/lib/python3.10/site-packages/flwr/simulation/ray_transport/ray_actor.py", line 279, in _fetch_future_result
    res_cid, out_mssg, updated_context = ray.get(
  File "/home/abdenour/.local/lib/python3.10/site-packages/ray/_private/auto_init_hook.py", line 21, in auto_init_wrapper
    return fn(*args, **kwargs)
  File "/home/abdenour/.local/lib/python3.10/site-packages/ray/_private/client_mode_hook.py", line 103, in wrapper
    return func(*args, **kwargs)
  File "/home/abdenour/.local/lib/python3.10/site-packages/ray/_private/worker.py", line 2667, in get
    values, debugger_breakpoint = worker.get_objects(object_refs, timeout=timeout)
  File "/home/abdenour/.local/lib/python3.10/site-packages/ray/_private/worker.py", line 864, in get_objects
    raise value.as_instanceof_cause()
ray.exceptions.RayTaskError(ClientAppException): [36mray::ClientAppActor.run()[39m (pid=3341813, ip=115.145.172.224, actor_id=e06687632bf1b1159dbb9c2c01000000, repr=<flwr.simulation.ray_transport.ray_actor.ClientAppActor object at 0x7faf50689a50>)
  File "/home/abdenour/.local/lib/python3.10/site-packages/flwr/client/client_app.py", line 143, in __call__
    return self._call(message, context)
  File "/home/abdenour/.local/lib/python3.10/site-packages/flwr/client/client_app.py", line 126, in ffn
    out_message = handle_legacy_message_from_msgtype(
  File "/home/abdenour/.local/lib/python3.10/site-packages/flwr/client/message_handler/message_handler.py", line 95, in handle_legacy_message_from_msgtype
    client = client_fn(context)
  File "/home/abdenour/fl_with_flower/fednova_vgg16/fednova_vgg16/client.py", line 133, in client_fn
    return FlowerClient(trainset, valset, num_classes, config_fit, client_dataset_ratio, context.node_config).to_client()
  File "/home/abdenour/fl_with_flower/fednova_vgg16/fednova_vgg16/client.py", line 40, in __init__
    self.model = self.model.to(self.device)
  File "/home/abdenour/anaconda3/envs/fl/lib/python3.10/site-packages/torch/nn/modules/module.py", line 1174, in to
    return self._apply(convert)
  File "/home/abdenour/anaconda3/envs/fl/lib/python3.10/site-packages/torch/nn/modules/module.py", line 780, in _apply
    module._apply(fn)
  File "/home/abdenour/anaconda3/envs/fl/lib/python3.10/site-packages/torch/nn/modules/module.py", line 780, in _apply
    module._apply(fn)
  File "/home/abdenour/anaconda3/envs/fl/lib/python3.10/site-packages/torch/nn/modules/module.py", line 805, in _apply
    param_applied = fn(param)
  File "/home/abdenour/anaconda3/envs/fl/lib/python3.10/site-packages/torch/nn/modules/module.py", line 1160, in convert
    return t.to(
RuntimeError: CUDA error: out of memory
CUDA kernel errors might be asynchronously reported at some other API call, so the stacktrace below might be incorrect.
For debugging consider passing CUDA_LAUNCH_BLOCKING=1
Compile with `TORCH_USE_CUDA_DSA` to enable device-side assertions.


The above exception was the direct cause of the following exception:

[36mray::ClientAppActor.run()[39m (pid=3341813, ip=115.145.172.224, actor_id=e06687632bf1b1159dbb9c2c01000000, repr=<flwr.simulation.ray_transport.ray_actor.ClientAppActor object at 0x7faf50689a50>)
  File "/home/abdenour/.local/lib/python3.10/site-packages/flwr/simulation/ray_transport/ray_actor.py", line 63, in run
    raise ClientAppException(str(ex)) from ex
flwr.client.client_app.ClientAppException: 
Exception ClientAppException occurred. Message: CUDA error: out of memory
CUDA kernel errors might be asynchronously reported at some other API call, so the stacktrace below might be incorrect.
For debugging consider passing CUDA_LAUNCH_BLOCKING=1
Compile with `TORCH_USE_CUDA_DSA` to enable device-side assertions.

[2024-10-22 14:57:50,702][flwr][ERROR] - [36mray::ClientAppActor.run()[39m (pid=3341813, ip=115.145.172.224, actor_id=e06687632bf1b1159dbb9c2c01000000, repr=<flwr.simulation.ray_transport.ray_actor.ClientAppActor object at 0x7faf50689a50>)
  File "/home/abdenour/.local/lib/python3.10/site-packages/flwr/client/client_app.py", line 143, in __call__
    return self._call(message, context)
  File "/home/abdenour/.local/lib/python3.10/site-packages/flwr/client/client_app.py", line 126, in ffn
    out_message = handle_legacy_message_from_msgtype(
  File "/home/abdenour/.local/lib/python3.10/site-packages/flwr/client/message_handler/message_handler.py", line 95, in handle_legacy_message_from_msgtype
    client = client_fn(context)
  File "/home/abdenour/fl_with_flower/fednova_vgg16/fednova_vgg16/client.py", line 133, in client_fn
    return FlowerClient(trainset, valset, num_classes, config_fit, client_dataset_ratio, context.node_config).to_client()
  File "/home/abdenour/fl_with_flower/fednova_vgg16/fednova_vgg16/client.py", line 40, in __init__
    self.model = self.model.to(self.device)
  File "/home/abdenour/anaconda3/envs/fl/lib/python3.10/site-packages/torch/nn/modules/module.py", line 1174, in to
    return self._apply(convert)
  File "/home/abdenour/anaconda3/envs/fl/lib/python3.10/site-packages/torch/nn/modules/module.py", line 780, in _apply
    module._apply(fn)
  File "/home/abdenour/anaconda3/envs/fl/lib/python3.10/site-packages/torch/nn/modules/module.py", line 780, in _apply
    module._apply(fn)
  File "/home/abdenour/anaconda3/envs/fl/lib/python3.10/site-packages/torch/nn/modules/module.py", line 805, in _apply
    param_applied = fn(param)
  File "/home/abdenour/anaconda3/envs/fl/lib/python3.10/site-packages/torch/nn/modules/module.py", line 1160, in convert
    return t.to(
RuntimeError: CUDA error: out of memory
CUDA kernel errors might be asynchronously reported at some other API call, so the stacktrace below might be incorrect.
For debugging consider passing CUDA_LAUNCH_BLOCKING=1
Compile with `TORCH_USE_CUDA_DSA` to enable device-side assertions.


The above exception was the direct cause of the following exception:

[36mray::ClientAppActor.run()[39m (pid=3341813, ip=115.145.172.224, actor_id=e06687632bf1b1159dbb9c2c01000000, repr=<flwr.simulation.ray_transport.ray_actor.ClientAppActor object at 0x7faf50689a50>)
  File "/home/abdenour/.local/lib/python3.10/site-packages/flwr/simulation/ray_transport/ray_actor.py", line 63, in run
    raise ClientAppException(str(ex)) from ex
flwr.client.client_app.ClientAppException: 
Exception ClientAppException occurred. Message: CUDA error: out of memory
CUDA kernel errors might be asynchronously reported at some other API call, so the stacktrace below might be incorrect.
For debugging consider passing CUDA_LAUNCH_BLOCKING=1
Compile with `TORCH_USE_CUDA_DSA` to enable device-side assertions.
[2024-10-22 14:57:50,950][flwr][ERROR] - Traceback (most recent call last):
  File "/home/abdenour/.local/lib/python3.10/site-packages/flwr/simulation/ray_transport/ray_client_proxy.py", line 94, in _submit_job
    out_mssg, updated_context = self.actor_pool.get_client_result(
  File "/home/abdenour/.local/lib/python3.10/site-packages/flwr/simulation/ray_transport/ray_actor.py", line 398, in get_client_result
    return self._fetch_future_result(cid)
  File "/home/abdenour/.local/lib/python3.10/site-packages/flwr/simulation/ray_transport/ray_actor.py", line 279, in _fetch_future_result
    res_cid, out_mssg, updated_context = ray.get(
  File "/home/abdenour/.local/lib/python3.10/site-packages/ray/_private/auto_init_hook.py", line 21, in auto_init_wrapper
    return fn(*args, **kwargs)
  File "/home/abdenour/.local/lib/python3.10/site-packages/ray/_private/client_mode_hook.py", line 103, in wrapper
    return func(*args, **kwargs)
  File "/home/abdenour/.local/lib/python3.10/site-packages/ray/_private/worker.py", line 2667, in get
    values, debugger_breakpoint = worker.get_objects(object_refs, timeout=timeout)
  File "/home/abdenour/.local/lib/python3.10/site-packages/ray/_private/worker.py", line 864, in get_objects
    raise value.as_instanceof_cause()
ray.exceptions.RayTaskError(ClientAppException): [36mray::ClientAppActor.run()[39m (pid=3341814, ip=115.145.172.224, actor_id=50d8ef4247febf9234280d4401000000, repr=<flwr.simulation.ray_transport.ray_actor.ClientAppActor object at 0x7fa78c789a20>)
  File "/home/abdenour/.local/lib/python3.10/site-packages/flwr/client/client_app.py", line 143, in __call__
    return self._call(message, context)
  File "/home/abdenour/.local/lib/python3.10/site-packages/flwr/client/client_app.py", line 126, in ffn
    out_message = handle_legacy_message_from_msgtype(
  File "/home/abdenour/.local/lib/python3.10/site-packages/flwr/client/message_handler/message_handler.py", line 95, in handle_legacy_message_from_msgtype
    client = client_fn(context)
  File "/home/abdenour/fl_with_flower/fednova_vgg16/fednova_vgg16/client.py", line 133, in client_fn
    return FlowerClient(trainset, valset, num_classes, config_fit, client_dataset_ratio, context.node_config).to_client()
  File "/home/abdenour/fl_with_flower/fednova_vgg16/fednova_vgg16/client.py", line 40, in __init__
    self.model = self.model.to(self.device)
  File "/home/abdenour/anaconda3/envs/fl/lib/python3.10/site-packages/torch/nn/modules/module.py", line 1174, in to
    return self._apply(convert)
  File "/home/abdenour/anaconda3/envs/fl/lib/python3.10/site-packages/torch/nn/modules/module.py", line 780, in _apply
    module._apply(fn)
  File "/home/abdenour/anaconda3/envs/fl/lib/python3.10/site-packages/torch/nn/modules/module.py", line 780, in _apply
    module._apply(fn)
  File "/home/abdenour/anaconda3/envs/fl/lib/python3.10/site-packages/torch/nn/modules/module.py", line 805, in _apply
    param_applied = fn(param)
  File "/home/abdenour/anaconda3/envs/fl/lib/python3.10/site-packages/torch/nn/modules/module.py", line 1160, in convert
    return t.to(
torch.OutOfMemoryError: CUDA out of memory. Tried to allocate 64.00 MiB. GPU 0 has a total capacity of 10.75 GiB of which 24.75 MiB is free. Process 3341815 has 10.09 GiB memory in use. Including non-PyTorch memory, this process has 648.00 MiB memory in use. Of the allocated memory 468.40 MiB is allocated by PyTorch, and 25.60 MiB is reserved by PyTorch but unallocated. If reserved but unallocated memory is large try setting PYTORCH_CUDA_ALLOC_CONF=expandable_segments:True to avoid fragmentation.  See documentation for Memory Management  (https://pytorch.org/docs/stable/notes/cuda.html#environment-variables)

The above exception was the direct cause of the following exception:

[36mray::ClientAppActor.run()[39m (pid=3341814, ip=115.145.172.224, actor_id=50d8ef4247febf9234280d4401000000, repr=<flwr.simulation.ray_transport.ray_actor.ClientAppActor object at 0x7fa78c789a20>)
  File "/home/abdenour/.local/lib/python3.10/site-packages/flwr/simulation/ray_transport/ray_actor.py", line 63, in run
    raise ClientAppException(str(ex)) from ex
flwr.client.client_app.ClientAppException: 
Exception ClientAppException occurred. Message: CUDA out of memory. Tried to allocate 64.00 MiB. GPU 0 has a total capacity of 10.75 GiB of which 24.75 MiB is free. Process 3341815 has 10.09 GiB memory in use. Including non-PyTorch memory, this process has 648.00 MiB memory in use. Of the allocated memory 468.40 MiB is allocated by PyTorch, and 25.60 MiB is reserved by PyTorch but unallocated. If reserved but unallocated memory is large try setting PYTORCH_CUDA_ALLOC_CONF=expandable_segments:True to avoid fragmentation.  See documentation for Memory Management  (https://pytorch.org/docs/stable/notes/cuda.html#environment-variables)

[2024-10-22 14:57:50,950][flwr][ERROR] - [36mray::ClientAppActor.run()[39m (pid=3341814, ip=115.145.172.224, actor_id=50d8ef4247febf9234280d4401000000, repr=<flwr.simulation.ray_transport.ray_actor.ClientAppActor object at 0x7fa78c789a20>)
  File "/home/abdenour/.local/lib/python3.10/site-packages/flwr/client/client_app.py", line 143, in __call__
    return self._call(message, context)
  File "/home/abdenour/.local/lib/python3.10/site-packages/flwr/client/client_app.py", line 126, in ffn
    out_message = handle_legacy_message_from_msgtype(
  File "/home/abdenour/.local/lib/python3.10/site-packages/flwr/client/message_handler/message_handler.py", line 95, in handle_legacy_message_from_msgtype
    client = client_fn(context)
  File "/home/abdenour/fl_with_flower/fednova_vgg16/fednova_vgg16/client.py", line 133, in client_fn
    return FlowerClient(trainset, valset, num_classes, config_fit, client_dataset_ratio, context.node_config).to_client()
  File "/home/abdenour/fl_with_flower/fednova_vgg16/fednova_vgg16/client.py", line 40, in __init__
    self.model = self.model.to(self.device)
  File "/home/abdenour/anaconda3/envs/fl/lib/python3.10/site-packages/torch/nn/modules/module.py", line 1174, in to
    return self._apply(convert)
  File "/home/abdenour/anaconda3/envs/fl/lib/python3.10/site-packages/torch/nn/modules/module.py", line 780, in _apply
    module._apply(fn)
  File "/home/abdenour/anaconda3/envs/fl/lib/python3.10/site-packages/torch/nn/modules/module.py", line 780, in _apply
    module._apply(fn)
  File "/home/abdenour/anaconda3/envs/fl/lib/python3.10/site-packages/torch/nn/modules/module.py", line 805, in _apply
    param_applied = fn(param)
  File "/home/abdenour/anaconda3/envs/fl/lib/python3.10/site-packages/torch/nn/modules/module.py", line 1160, in convert
    return t.to(
torch.OutOfMemoryError: CUDA out of memory. Tried to allocate 64.00 MiB. GPU 0 has a total capacity of 10.75 GiB of which 24.75 MiB is free. Process 3341815 has 10.09 GiB memory in use. Including non-PyTorch memory, this process has 648.00 MiB memory in use. Of the allocated memory 468.40 MiB is allocated by PyTorch, and 25.60 MiB is reserved by PyTorch but unallocated. If reserved but unallocated memory is large try setting PYTORCH_CUDA_ALLOC_CONF=expandable_segments:True to avoid fragmentation.  See documentation for Memory Management  (https://pytorch.org/docs/stable/notes/cuda.html#environment-variables)

The above exception was the direct cause of the following exception:

[36mray::ClientAppActor.run()[39m (pid=3341814, ip=115.145.172.224, actor_id=50d8ef4247febf9234280d4401000000, repr=<flwr.simulation.ray_transport.ray_actor.ClientAppActor object at 0x7fa78c789a20>)
  File "/home/abdenour/.local/lib/python3.10/site-packages/flwr/simulation/ray_transport/ray_actor.py", line 63, in run
    raise ClientAppException(str(ex)) from ex
flwr.client.client_app.ClientAppException: 
Exception ClientAppException occurred. Message: CUDA out of memory. Tried to allocate 64.00 MiB. GPU 0 has a total capacity of 10.75 GiB of which 24.75 MiB is free. Process 3341815 has 10.09 GiB memory in use. Including non-PyTorch memory, this process has 648.00 MiB memory in use. Of the allocated memory 468.40 MiB is allocated by PyTorch, and 25.60 MiB is reserved by PyTorch but unallocated. If reserved but unallocated memory is large try setting PYTORCH_CUDA_ALLOC_CONF=expandable_segments:True to avoid fragmentation.  See documentation for Memory Management  (https://pytorch.org/docs/stable/notes/cuda.html#environment-variables)
[2024-10-22 14:58:38,425][flwr][INFO] - aggregate_fit: received 2 results and 3 failures
[2024-10-22 14:58:57,323][flwr][INFO] - fit progress: (2, 359.2996200323105, {'accuracy': 0.3798050139275766}, 132.16983555816114)
[2024-10-22 14:58:57,323][flwr][INFO] - configure_evaluate: strategy sampled 2 clients (out of 50)
[2024-10-22 14:59:00,720][flwr][INFO] - aggregate_evaluate: received 2 results and 0 failures
[2024-10-22 14:59:00,720][flwr][INFO] - 
[2024-10-22 14:59:00,721][flwr][INFO] - [ROUND 3]
[2024-10-22 14:59:00,721][flwr][INFO] - configure_fit: strategy sampled 5 clients (out of 50)
[2024-10-22 14:59:03,363][flwr][ERROR] - Traceback (most recent call last):
  File "/home/abdenour/.local/lib/python3.10/site-packages/flwr/simulation/ray_transport/ray_client_proxy.py", line 94, in _submit_job
    out_mssg, updated_context = self.actor_pool.get_client_result(
  File "/home/abdenour/.local/lib/python3.10/site-packages/flwr/simulation/ray_transport/ray_actor.py", line 398, in get_client_result
    return self._fetch_future_result(cid)
  File "/home/abdenour/.local/lib/python3.10/site-packages/flwr/simulation/ray_transport/ray_actor.py", line 279, in _fetch_future_result
    res_cid, out_mssg, updated_context = ray.get(
  File "/home/abdenour/.local/lib/python3.10/site-packages/ray/_private/auto_init_hook.py", line 21, in auto_init_wrapper
    return fn(*args, **kwargs)
  File "/home/abdenour/.local/lib/python3.10/site-packages/ray/_private/client_mode_hook.py", line 103, in wrapper
    return func(*args, **kwargs)
  File "/home/abdenour/.local/lib/python3.10/site-packages/ray/_private/worker.py", line 2667, in get
    values, debugger_breakpoint = worker.get_objects(object_refs, timeout=timeout)
  File "/home/abdenour/.local/lib/python3.10/site-packages/ray/_private/worker.py", line 864, in get_objects
    raise value.as_instanceof_cause()
ray.exceptions.RayTaskError(ClientAppException): [36mray::ClientAppActor.run()[39m (pid=3341814, ip=115.145.172.224, actor_id=50d8ef4247febf9234280d4401000000, repr=<flwr.simulation.ray_transport.ray_actor.ClientAppActor object at 0x7fa78c789a20>)
  File "/home/abdenour/.local/lib/python3.10/site-packages/flwr/client/client_app.py", line 143, in __call__
    return self._call(message, context)
  File "/home/abdenour/.local/lib/python3.10/site-packages/flwr/client/client_app.py", line 126, in ffn
    out_message = handle_legacy_message_from_msgtype(
  File "/home/abdenour/.local/lib/python3.10/site-packages/flwr/client/message_handler/message_handler.py", line 95, in handle_legacy_message_from_msgtype
    client = client_fn(context)
  File "/home/abdenour/fl_with_flower/fednova_vgg16/fednova_vgg16/client.py", line 133, in client_fn
    return FlowerClient(trainset, valset, num_classes, config_fit, client_dataset_ratio, context.node_config).to_client()
  File "/home/abdenour/fl_with_flower/fednova_vgg16/fednova_vgg16/client.py", line 40, in __init__
    self.model = self.model.to(self.device)
  File "/home/abdenour/anaconda3/envs/fl/lib/python3.10/site-packages/torch/nn/modules/module.py", line 1174, in to
    return self._apply(convert)
  File "/home/abdenour/anaconda3/envs/fl/lib/python3.10/site-packages/torch/nn/modules/module.py", line 780, in _apply
    module._apply(fn)
  File "/home/abdenour/anaconda3/envs/fl/lib/python3.10/site-packages/torch/nn/modules/module.py", line 780, in _apply
    module._apply(fn)
  File "/home/abdenour/anaconda3/envs/fl/lib/python3.10/site-packages/torch/nn/modules/module.py", line 805, in _apply
    param_applied = fn(param)
  File "/home/abdenour/anaconda3/envs/fl/lib/python3.10/site-packages/torch/nn/modules/module.py", line 1160, in convert
    return t.to(
torch.OutOfMemoryError: CUDA out of memory. Tried to allocate 64.00 MiB. GPU 0 has a total capacity of 10.75 GiB of which 22.75 MiB is free. Process 3341815 has 10.09 GiB memory in use. Including non-PyTorch memory, this process has 648.00 MiB memory in use. Of the allocated memory 468.40 MiB is allocated by PyTorch, and 25.60 MiB is reserved by PyTorch but unallocated. If reserved but unallocated memory is large try setting PYTORCH_CUDA_ALLOC_CONF=expandable_segments:True to avoid fragmentation.  See documentation for Memory Management  (https://pytorch.org/docs/stable/notes/cuda.html#environment-variables)

The above exception was the direct cause of the following exception:

[36mray::ClientAppActor.run()[39m (pid=3341814, ip=115.145.172.224, actor_id=50d8ef4247febf9234280d4401000000, repr=<flwr.simulation.ray_transport.ray_actor.ClientAppActor object at 0x7fa78c789a20>)
  File "/home/abdenour/.local/lib/python3.10/site-packages/flwr/simulation/ray_transport/ray_actor.py", line 63, in run
    raise ClientAppException(str(ex)) from ex
flwr.client.client_app.ClientAppException: 
Exception ClientAppException occurred. Message: CUDA out of memory. Tried to allocate 64.00 MiB. GPU 0 has a total capacity of 10.75 GiB of which 22.75 MiB is free. Process 3341815 has 10.09 GiB memory in use. Including non-PyTorch memory, this process has 648.00 MiB memory in use. Of the allocated memory 468.40 MiB is allocated by PyTorch, and 25.60 MiB is reserved by PyTorch but unallocated. If reserved but unallocated memory is large try setting PYTORCH_CUDA_ALLOC_CONF=expandable_segments:True to avoid fragmentation.  See documentation for Memory Management  (https://pytorch.org/docs/stable/notes/cuda.html#environment-variables)

[2024-10-22 14:59:03,363][flwr][ERROR] - [36mray::ClientAppActor.run()[39m (pid=3341814, ip=115.145.172.224, actor_id=50d8ef4247febf9234280d4401000000, repr=<flwr.simulation.ray_transport.ray_actor.ClientAppActor object at 0x7fa78c789a20>)
  File "/home/abdenour/.local/lib/python3.10/site-packages/flwr/client/client_app.py", line 143, in __call__
    return self._call(message, context)
  File "/home/abdenour/.local/lib/python3.10/site-packages/flwr/client/client_app.py", line 126, in ffn
    out_message = handle_legacy_message_from_msgtype(
  File "/home/abdenour/.local/lib/python3.10/site-packages/flwr/client/message_handler/message_handler.py", line 95, in handle_legacy_message_from_msgtype
    client = client_fn(context)
  File "/home/abdenour/fl_with_flower/fednova_vgg16/fednova_vgg16/client.py", line 133, in client_fn
    return FlowerClient(trainset, valset, num_classes, config_fit, client_dataset_ratio, context.node_config).to_client()
  File "/home/abdenour/fl_with_flower/fednova_vgg16/fednova_vgg16/client.py", line 40, in __init__
    self.model = self.model.to(self.device)
  File "/home/abdenour/anaconda3/envs/fl/lib/python3.10/site-packages/torch/nn/modules/module.py", line 1174, in to
    return self._apply(convert)
  File "/home/abdenour/anaconda3/envs/fl/lib/python3.10/site-packages/torch/nn/modules/module.py", line 780, in _apply
    module._apply(fn)
  File "/home/abdenour/anaconda3/envs/fl/lib/python3.10/site-packages/torch/nn/modules/module.py", line 780, in _apply
    module._apply(fn)
  File "/home/abdenour/anaconda3/envs/fl/lib/python3.10/site-packages/torch/nn/modules/module.py", line 805, in _apply
    param_applied = fn(param)
  File "/home/abdenour/anaconda3/envs/fl/lib/python3.10/site-packages/torch/nn/modules/module.py", line 1160, in convert
    return t.to(
torch.OutOfMemoryError: CUDA out of memory. Tried to allocate 64.00 MiB. GPU 0 has a total capacity of 10.75 GiB of which 22.75 MiB is free. Process 3341815 has 10.09 GiB memory in use. Including non-PyTorch memory, this process has 648.00 MiB memory in use. Of the allocated memory 468.40 MiB is allocated by PyTorch, and 25.60 MiB is reserved by PyTorch but unallocated. If reserved but unallocated memory is large try setting PYTORCH_CUDA_ALLOC_CONF=expandable_segments:True to avoid fragmentation.  See documentation for Memory Management  (https://pytorch.org/docs/stable/notes/cuda.html#environment-variables)

The above exception was the direct cause of the following exception:

[36mray::ClientAppActor.run()[39m (pid=3341814, ip=115.145.172.224, actor_id=50d8ef4247febf9234280d4401000000, repr=<flwr.simulation.ray_transport.ray_actor.ClientAppActor object at 0x7fa78c789a20>)
  File "/home/abdenour/.local/lib/python3.10/site-packages/flwr/simulation/ray_transport/ray_actor.py", line 63, in run
    raise ClientAppException(str(ex)) from ex
flwr.client.client_app.ClientAppException: 
Exception ClientAppException occurred. Message: CUDA out of memory. Tried to allocate 64.00 MiB. GPU 0 has a total capacity of 10.75 GiB of which 22.75 MiB is free. Process 3341815 has 10.09 GiB memory in use. Including non-PyTorch memory, this process has 648.00 MiB memory in use. Of the allocated memory 468.40 MiB is allocated by PyTorch, and 25.60 MiB is reserved by PyTorch but unallocated. If reserved but unallocated memory is large try setting PYTORCH_CUDA_ALLOC_CONF=expandable_segments:True to avoid fragmentation.  See documentation for Memory Management  (https://pytorch.org/docs/stable/notes/cuda.html#environment-variables)
[2024-10-22 14:59:04,062][flwr][ERROR] - Traceback (most recent call last):
  File "/home/abdenour/.local/lib/python3.10/site-packages/flwr/simulation/ray_transport/ray_client_proxy.py", line 94, in _submit_job
    out_mssg, updated_context = self.actor_pool.get_client_result(
  File "/home/abdenour/.local/lib/python3.10/site-packages/flwr/simulation/ray_transport/ray_actor.py", line 398, in get_client_result
    return self._fetch_future_result(cid)
  File "/home/abdenour/.local/lib/python3.10/site-packages/flwr/simulation/ray_transport/ray_actor.py", line 279, in _fetch_future_result
    res_cid, out_mssg, updated_context = ray.get(
  File "/home/abdenour/.local/lib/python3.10/site-packages/ray/_private/auto_init_hook.py", line 21, in auto_init_wrapper
    return fn(*args, **kwargs)
  File "/home/abdenour/.local/lib/python3.10/site-packages/ray/_private/client_mode_hook.py", line 103, in wrapper
    return func(*args, **kwargs)
  File "/home/abdenour/.local/lib/python3.10/site-packages/ray/_private/worker.py", line 2667, in get
    values, debugger_breakpoint = worker.get_objects(object_refs, timeout=timeout)
  File "/home/abdenour/.local/lib/python3.10/site-packages/ray/_private/worker.py", line 864, in get_objects
    raise value.as_instanceof_cause()
ray.exceptions.RayTaskError(ClientAppException): [36mray::ClientAppActor.run()[39m (pid=3341813, ip=115.145.172.224, actor_id=e06687632bf1b1159dbb9c2c01000000, repr=<flwr.simulation.ray_transport.ray_actor.ClientAppActor object at 0x7faf50689a50>)
  File "/home/abdenour/.local/lib/python3.10/site-packages/flwr/client/client_app.py", line 143, in __call__
    return self._call(message, context)
  File "/home/abdenour/.local/lib/python3.10/site-packages/flwr/client/client_app.py", line 126, in ffn
    out_message = handle_legacy_message_from_msgtype(
  File "/home/abdenour/.local/lib/python3.10/site-packages/flwr/client/message_handler/message_handler.py", line 95, in handle_legacy_message_from_msgtype
    client = client_fn(context)
  File "/home/abdenour/fl_with_flower/fednova_vgg16/fednova_vgg16/client.py", line 133, in client_fn
    return FlowerClient(trainset, valset, num_classes, config_fit, client_dataset_ratio, context.node_config).to_client()
  File "/home/abdenour/fl_with_flower/fednova_vgg16/fednova_vgg16/client.py", line 40, in __init__
    self.model = self.model.to(self.device)
  File "/home/abdenour/anaconda3/envs/fl/lib/python3.10/site-packages/torch/nn/modules/module.py", line 1174, in to
    return self._apply(convert)
  File "/home/abdenour/anaconda3/envs/fl/lib/python3.10/site-packages/torch/nn/modules/module.py", line 780, in _apply
    module._apply(fn)
  File "/home/abdenour/anaconda3/envs/fl/lib/python3.10/site-packages/torch/nn/modules/module.py", line 780, in _apply
    module._apply(fn)
  File "/home/abdenour/anaconda3/envs/fl/lib/python3.10/site-packages/torch/nn/modules/module.py", line 805, in _apply
    param_applied = fn(param)
  File "/home/abdenour/anaconda3/envs/fl/lib/python3.10/site-packages/torch/nn/modules/module.py", line 1160, in convert
    return t.to(
RuntimeError: CUDA error: out of memory
CUDA kernel errors might be asynchronously reported at some other API call, so the stacktrace below might be incorrect.
For debugging consider passing CUDA_LAUNCH_BLOCKING=1
Compile with `TORCH_USE_CUDA_DSA` to enable device-side assertions.


The above exception was the direct cause of the following exception:

[36mray::ClientAppActor.run()[39m (pid=3341813, ip=115.145.172.224, actor_id=e06687632bf1b1159dbb9c2c01000000, repr=<flwr.simulation.ray_transport.ray_actor.ClientAppActor object at 0x7faf50689a50>)
  File "/home/abdenour/.local/lib/python3.10/site-packages/flwr/simulation/ray_transport/ray_actor.py", line 63, in run
    raise ClientAppException(str(ex)) from ex
flwr.client.client_app.ClientAppException: 
Exception ClientAppException occurred. Message: CUDA error: out of memory
CUDA kernel errors might be asynchronously reported at some other API call, so the stacktrace below might be incorrect.
For debugging consider passing CUDA_LAUNCH_BLOCKING=1
Compile with `TORCH_USE_CUDA_DSA` to enable device-side assertions.

[2024-10-22 14:59:04,062][flwr][ERROR] - [36mray::ClientAppActor.run()[39m (pid=3341813, ip=115.145.172.224, actor_id=e06687632bf1b1159dbb9c2c01000000, repr=<flwr.simulation.ray_transport.ray_actor.ClientAppActor object at 0x7faf50689a50>)
  File "/home/abdenour/.local/lib/python3.10/site-packages/flwr/client/client_app.py", line 143, in __call__
    return self._call(message, context)
  File "/home/abdenour/.local/lib/python3.10/site-packages/flwr/client/client_app.py", line 126, in ffn
    out_message = handle_legacy_message_from_msgtype(
  File "/home/abdenour/.local/lib/python3.10/site-packages/flwr/client/message_handler/message_handler.py", line 95, in handle_legacy_message_from_msgtype
    client = client_fn(context)
  File "/home/abdenour/fl_with_flower/fednova_vgg16/fednova_vgg16/client.py", line 133, in client_fn
    return FlowerClient(trainset, valset, num_classes, config_fit, client_dataset_ratio, context.node_config).to_client()
  File "/home/abdenour/fl_with_flower/fednova_vgg16/fednova_vgg16/client.py", line 40, in __init__
    self.model = self.model.to(self.device)
  File "/home/abdenour/anaconda3/envs/fl/lib/python3.10/site-packages/torch/nn/modules/module.py", line 1174, in to
    return self._apply(convert)
  File "/home/abdenour/anaconda3/envs/fl/lib/python3.10/site-packages/torch/nn/modules/module.py", line 780, in _apply
    module._apply(fn)
  File "/home/abdenour/anaconda3/envs/fl/lib/python3.10/site-packages/torch/nn/modules/module.py", line 780, in _apply
    module._apply(fn)
  File "/home/abdenour/anaconda3/envs/fl/lib/python3.10/site-packages/torch/nn/modules/module.py", line 805, in _apply
    param_applied = fn(param)
  File "/home/abdenour/anaconda3/envs/fl/lib/python3.10/site-packages/torch/nn/modules/module.py", line 1160, in convert
    return t.to(
RuntimeError: CUDA error: out of memory
CUDA kernel errors might be asynchronously reported at some other API call, so the stacktrace below might be incorrect.
For debugging consider passing CUDA_LAUNCH_BLOCKING=1
Compile with `TORCH_USE_CUDA_DSA` to enable device-side assertions.


The above exception was the direct cause of the following exception:

[36mray::ClientAppActor.run()[39m (pid=3341813, ip=115.145.172.224, actor_id=e06687632bf1b1159dbb9c2c01000000, repr=<flwr.simulation.ray_transport.ray_actor.ClientAppActor object at 0x7faf50689a50>)
  File "/home/abdenour/.local/lib/python3.10/site-packages/flwr/simulation/ray_transport/ray_actor.py", line 63, in run
    raise ClientAppException(str(ex)) from ex
flwr.client.client_app.ClientAppException: 
Exception ClientAppException occurred. Message: CUDA error: out of memory
CUDA kernel errors might be asynchronously reported at some other API call, so the stacktrace below might be incorrect.
For debugging consider passing CUDA_LAUNCH_BLOCKING=1
Compile with `TORCH_USE_CUDA_DSA` to enable device-side assertions.
[2024-10-22 14:59:04,724][flwr][ERROR] - Traceback (most recent call last):
  File "/home/abdenour/.local/lib/python3.10/site-packages/flwr/simulation/ray_transport/ray_client_proxy.py", line 94, in _submit_job
    out_mssg, updated_context = self.actor_pool.get_client_result(
  File "/home/abdenour/.local/lib/python3.10/site-packages/flwr/simulation/ray_transport/ray_actor.py", line 398, in get_client_result
    return self._fetch_future_result(cid)
  File "/home/abdenour/.local/lib/python3.10/site-packages/flwr/simulation/ray_transport/ray_actor.py", line 279, in _fetch_future_result
    res_cid, out_mssg, updated_context = ray.get(
  File "/home/abdenour/.local/lib/python3.10/site-packages/ray/_private/auto_init_hook.py", line 21, in auto_init_wrapper
    return fn(*args, **kwargs)
  File "/home/abdenour/.local/lib/python3.10/site-packages/ray/_private/client_mode_hook.py", line 103, in wrapper
    return func(*args, **kwargs)
  File "/home/abdenour/.local/lib/python3.10/site-packages/ray/_private/worker.py", line 2667, in get
    values, debugger_breakpoint = worker.get_objects(object_refs, timeout=timeout)
  File "/home/abdenour/.local/lib/python3.10/site-packages/ray/_private/worker.py", line 864, in get_objects
    raise value.as_instanceof_cause()
ray.exceptions.RayTaskError(ClientAppException): [36mray::ClientAppActor.run()[39m (pid=3341812, ip=115.145.172.224, actor_id=b1c85204e13efdf6edbfd66901000000, repr=<flwr.simulation.ray_transport.ray_actor.ClientAppActor object at 0x7f3da8095a20>)
  File "/home/abdenour/.local/lib/python3.10/site-packages/flwr/client/client_app.py", line 143, in __call__
    return self._call(message, context)
  File "/home/abdenour/.local/lib/python3.10/site-packages/flwr/client/client_app.py", line 126, in ffn
    out_message = handle_legacy_message_from_msgtype(
  File "/home/abdenour/.local/lib/python3.10/site-packages/flwr/client/message_handler/message_handler.py", line 95, in handle_legacy_message_from_msgtype
    client = client_fn(context)
  File "/home/abdenour/fl_with_flower/fednova_vgg16/fednova_vgg16/client.py", line 133, in client_fn
    return FlowerClient(trainset, valset, num_classes, config_fit, client_dataset_ratio, context.node_config).to_client()
  File "/home/abdenour/fl_with_flower/fednova_vgg16/fednova_vgg16/client.py", line 40, in __init__
    self.model = self.model.to(self.device)
  File "/home/abdenour/anaconda3/envs/fl/lib/python3.10/site-packages/torch/nn/modules/module.py", line 1174, in to
    return self._apply(convert)
  File "/home/abdenour/anaconda3/envs/fl/lib/python3.10/site-packages/torch/nn/modules/module.py", line 780, in _apply
    module._apply(fn)
  File "/home/abdenour/anaconda3/envs/fl/lib/python3.10/site-packages/torch/nn/modules/module.py", line 780, in _apply
    module._apply(fn)
  File "/home/abdenour/anaconda3/envs/fl/lib/python3.10/site-packages/torch/nn/modules/module.py", line 805, in _apply
    param_applied = fn(param)
  File "/home/abdenour/anaconda3/envs/fl/lib/python3.10/site-packages/torch/nn/modules/module.py", line 1160, in convert
    return t.to(
RuntimeError: CUDA error: out of memory
CUDA kernel errors might be asynchronously reported at some other API call, so the stacktrace below might be incorrect.
For debugging consider passing CUDA_LAUNCH_BLOCKING=1
Compile with `TORCH_USE_CUDA_DSA` to enable device-side assertions.


The above exception was the direct cause of the following exception:

[36mray::ClientAppActor.run()[39m (pid=3341812, ip=115.145.172.224, actor_id=b1c85204e13efdf6edbfd66901000000, repr=<flwr.simulation.ray_transport.ray_actor.ClientAppActor object at 0x7f3da8095a20>)
  File "/home/abdenour/.local/lib/python3.10/site-packages/flwr/simulation/ray_transport/ray_actor.py", line 63, in run
    raise ClientAppException(str(ex)) from ex
flwr.client.client_app.ClientAppException: 
Exception ClientAppException occurred. Message: CUDA error: out of memory
CUDA kernel errors might be asynchronously reported at some other API call, so the stacktrace below might be incorrect.
For debugging consider passing CUDA_LAUNCH_BLOCKING=1
Compile with `TORCH_USE_CUDA_DSA` to enable device-side assertions.

[2024-10-22 14:59:04,725][flwr][ERROR] - [36mray::ClientAppActor.run()[39m (pid=3341812, ip=115.145.172.224, actor_id=b1c85204e13efdf6edbfd66901000000, repr=<flwr.simulation.ray_transport.ray_actor.ClientAppActor object at 0x7f3da8095a20>)
  File "/home/abdenour/.local/lib/python3.10/site-packages/flwr/client/client_app.py", line 143, in __call__
    return self._call(message, context)
  File "/home/abdenour/.local/lib/python3.10/site-packages/flwr/client/client_app.py", line 126, in ffn
    out_message = handle_legacy_message_from_msgtype(
  File "/home/abdenour/.local/lib/python3.10/site-packages/flwr/client/message_handler/message_handler.py", line 95, in handle_legacy_message_from_msgtype
    client = client_fn(context)
  File "/home/abdenour/fl_with_flower/fednova_vgg16/fednova_vgg16/client.py", line 133, in client_fn
    return FlowerClient(trainset, valset, num_classes, config_fit, client_dataset_ratio, context.node_config).to_client()
  File "/home/abdenour/fl_with_flower/fednova_vgg16/fednova_vgg16/client.py", line 40, in __init__
    self.model = self.model.to(self.device)
  File "/home/abdenour/anaconda3/envs/fl/lib/python3.10/site-packages/torch/nn/modules/module.py", line 1174, in to
    return self._apply(convert)
  File "/home/abdenour/anaconda3/envs/fl/lib/python3.10/site-packages/torch/nn/modules/module.py", line 780, in _apply
    module._apply(fn)
  File "/home/abdenour/anaconda3/envs/fl/lib/python3.10/site-packages/torch/nn/modules/module.py", line 780, in _apply
    module._apply(fn)
  File "/home/abdenour/anaconda3/envs/fl/lib/python3.10/site-packages/torch/nn/modules/module.py", line 805, in _apply
    param_applied = fn(param)
  File "/home/abdenour/anaconda3/envs/fl/lib/python3.10/site-packages/torch/nn/modules/module.py", line 1160, in convert
    return t.to(
RuntimeError: CUDA error: out of memory
CUDA kernel errors might be asynchronously reported at some other API call, so the stacktrace below might be incorrect.
For debugging consider passing CUDA_LAUNCH_BLOCKING=1
Compile with `TORCH_USE_CUDA_DSA` to enable device-side assertions.


The above exception was the direct cause of the following exception:

[36mray::ClientAppActor.run()[39m (pid=3341812, ip=115.145.172.224, actor_id=b1c85204e13efdf6edbfd66901000000, repr=<flwr.simulation.ray_transport.ray_actor.ClientAppActor object at 0x7f3da8095a20>)
  File "/home/abdenour/.local/lib/python3.10/site-packages/flwr/simulation/ray_transport/ray_actor.py", line 63, in run
    raise ClientAppException(str(ex)) from ex
flwr.client.client_app.ClientAppException: 
Exception ClientAppException occurred. Message: CUDA error: out of memory
CUDA kernel errors might be asynchronously reported at some other API call, so the stacktrace below might be incorrect.
For debugging consider passing CUDA_LAUNCH_BLOCKING=1
Compile with `TORCH_USE_CUDA_DSA` to enable device-side assertions.
