[2024-09-08 00:04:34,793][flwr][INFO] - Starting Flower simulation, config: num_rounds=100, no round_timeout
[2024-09-08 00:04:37,929][flwr][INFO] - Flower VCE: Ray initialized with resources: {'GPU': 5.0, 'accelerator_type:G': 1.0, 'memory': 169114439885.0, 'CPU': 256.0, 'node:__internal_head__': 1.0, 'node:115.145.172.224': 1.0, 'object_store_memory': 76763331379.0}
[2024-09-08 00:04:37,930][flwr][INFO] - Optimize your simulation with Flower VCE: https://flower.ai/docs/framework/how-to-run-simulations.html
[2024-09-08 00:04:37,930][flwr][INFO] - Flower VCE: Resources for each Virtual Client: {'num_cpus': 16, 'num_gpus': 0.25}
[2024-09-08 00:04:37,958][flwr][INFO] - Flower VCE: Creating VirtualClientEngineActorPool with 16 actors
[2024-09-08 00:04:37,959][flwr][INFO] - [INIT]
[2024-09-08 00:04:37,959][flwr][INFO] - Requesting initial parameters from one random client
[2024-09-08 00:04:42,803][flwr][INFO] - Received initial parameters from one random client
[2024-09-08 00:04:42,803][flwr][INFO] - Evaluating initial global parameters
[2024-09-08 00:05:42,250][flwr][INFO] - initial parameters (loss, other metrics): 3128.231836080551, {'accuracy': 0.06645516074450085}
[2024-09-08 00:05:42,250][flwr][INFO] - 
[2024-09-08 00:05:42,251][flwr][INFO] - [ROUND 1]
[2024-09-08 00:05:42,251][flwr][INFO] - configure_fit: strategy sampled 5 clients (out of 50)
[2024-09-08 00:05:46,731][flwr][ERROR] - Traceback (most recent call last):
  File "/home/abdenour/.local/lib/python3.10/site-packages/flwr/simulation/ray_transport/ray_client_proxy.py", line 94, in _submit_job
    out_mssg, updated_context = self.actor_pool.get_client_result(
  File "/home/abdenour/.local/lib/python3.10/site-packages/flwr/simulation/ray_transport/ray_actor.py", line 398, in get_client_result
    return self._fetch_future_result(cid)
  File "/home/abdenour/.local/lib/python3.10/site-packages/flwr/simulation/ray_transport/ray_actor.py", line 279, in _fetch_future_result
    res_cid, out_mssg, updated_context = ray.get(
  File "/home/abdenour/.local/lib/python3.10/site-packages/ray/_private/auto_init_hook.py", line 21, in auto_init_wrapper
    return fn(*args, **kwargs)
  File "/home/abdenour/.local/lib/python3.10/site-packages/ray/_private/client_mode_hook.py", line 103, in wrapper
    return func(*args, **kwargs)
  File "/home/abdenour/.local/lib/python3.10/site-packages/ray/_private/worker.py", line 2667, in get
    values, debugger_breakpoint = worker.get_objects(object_refs, timeout=timeout)
  File "/home/abdenour/.local/lib/python3.10/site-packages/ray/_private/worker.py", line 864, in get_objects
    raise value.as_instanceof_cause()
ray.exceptions.RayTaskError(ClientAppException): [36mray::ClientAppActor.run()[39m (pid=241120, ip=115.145.172.224, actor_id=987481fb4b5d2360669e566001000000, repr=<flwr.simulation.ray_transport.ray_actor.ClientAppActor object at 0x7f68887856f0>)
  File "/home/abdenour/.local/lib/python3.10/site-packages/flwr/client/client_app.py", line 143, in __call__
    return self._call(message, context)
  File "/home/abdenour/.local/lib/python3.10/site-packages/flwr/client/client_app.py", line 126, in ffn
    out_message = handle_legacy_message_from_msgtype(
  File "/home/abdenour/.local/lib/python3.10/site-packages/flwr/client/message_handler/message_handler.py", line 129, in handle_legacy_message_from_msgtype
    fit_res = maybe_call_fit(
  File "/home/abdenour/.local/lib/python3.10/site-packages/flwr/client/client.py", line 234, in maybe_call_fit
    return client.fit(fit_ins)
  File "/home/abdenour/.local/lib/python3.10/site-packages/flwr/client/numpy_client.py", line 238, in _fit
    results = self.numpy_client.fit(parameters, ins.config)  # type: ignore
  File "/home/abdenour/fl_with_flower/fedavg_mobilnet/fedavg_mobilnet/client.py", line 46, in fit
    train(self.model, trainloader, optimizer, epochs=epochs, device=self.device)
  File "/home/abdenour/fl_with_flower/fedavg_mobilnet/fedavg_mobilnet/utils.py", line 40, in train
    loss = criterion(net(images), labels)
  File "/home/abdenour/anaconda3/envs/fl/lib/python3.10/site-packages/torch/nn/modules/module.py", line 1553, in _wrapped_call_impl
    return self._call_impl(*args, **kwargs)
  File "/home/abdenour/anaconda3/envs/fl/lib/python3.10/site-packages/torch/nn/modules/module.py", line 1562, in _call_impl
    return forward_call(*args, **kwargs)
  File "/home/abdenour/anaconda3/envs/fl/lib/python3.10/site-packages/torchvision/models/mobilenetv2.py", line 174, in forward
    return self._forward_impl(x)
  File "/home/abdenour/anaconda3/envs/fl/lib/python3.10/site-packages/torchvision/models/mobilenetv2.py", line 166, in _forward_impl
    x = self.features(x)
  File "/home/abdenour/anaconda3/envs/fl/lib/python3.10/site-packages/torch/nn/modules/module.py", line 1553, in _wrapped_call_impl
    return self._call_impl(*args, **kwargs)
  File "/home/abdenour/anaconda3/envs/fl/lib/python3.10/site-packages/torch/nn/modules/module.py", line 1562, in _call_impl
    return forward_call(*args, **kwargs)
  File "/home/abdenour/anaconda3/envs/fl/lib/python3.10/site-packages/torch/nn/modules/container.py", line 219, in forward
    input = module(input)
  File "/home/abdenour/anaconda3/envs/fl/lib/python3.10/site-packages/torch/nn/modules/module.py", line 1553, in _wrapped_call_impl
    return self._call_impl(*args, **kwargs)
  File "/home/abdenour/anaconda3/envs/fl/lib/python3.10/site-packages/torch/nn/modules/module.py", line 1562, in _call_impl
    return forward_call(*args, **kwargs)
  File "/home/abdenour/anaconda3/envs/fl/lib/python3.10/site-packages/torchvision/models/mobilenetv2.py", line 62, in forward
    return x + self.conv(x)
  File "/home/abdenour/anaconda3/envs/fl/lib/python3.10/site-packages/torch/nn/modules/module.py", line 1553, in _wrapped_call_impl
    return self._call_impl(*args, **kwargs)
  File "/home/abdenour/anaconda3/envs/fl/lib/python3.10/site-packages/torch/nn/modules/module.py", line 1562, in _call_impl
    return forward_call(*args, **kwargs)
  File "/home/abdenour/anaconda3/envs/fl/lib/python3.10/site-packages/torch/nn/modules/container.py", line 219, in forward
    input = module(input)
  File "/home/abdenour/anaconda3/envs/fl/lib/python3.10/site-packages/torch/nn/modules/module.py", line 1553, in _wrapped_call_impl
    return self._call_impl(*args, **kwargs)
  File "/home/abdenour/anaconda3/envs/fl/lib/python3.10/site-packages/torch/nn/modules/module.py", line 1562, in _call_impl
    return forward_call(*args, **kwargs)
  File "/home/abdenour/anaconda3/envs/fl/lib/python3.10/site-packages/torch/nn/modules/container.py", line 219, in forward
    input = module(input)
  File "/home/abdenour/anaconda3/envs/fl/lib/python3.10/site-packages/torch/nn/modules/module.py", line 1553, in _wrapped_call_impl
    return self._call_impl(*args, **kwargs)
  File "/home/abdenour/anaconda3/envs/fl/lib/python3.10/site-packages/torch/nn/modules/module.py", line 1562, in _call_impl
    return forward_call(*args, **kwargs)
  File "/home/abdenour/anaconda3/envs/fl/lib/python3.10/site-packages/torch/nn/modules/conv.py", line 458, in forward
    return self._conv_forward(input, self.weight, self.bias)
  File "/home/abdenour/anaconda3/envs/fl/lib/python3.10/site-packages/torch/nn/modules/conv.py", line 454, in _conv_forward
    return F.conv2d(input, weight, bias, self.stride,
torch.OutOfMemoryError: CUDA out of memory. Tried to allocate 12.00 MiB. GPU 0 has a total capacity of 10.75 GiB of which 4.75 MiB is free. Process 241123 has 5.56 GiB memory in use. Including non-PyTorch memory, this process has 4.82 GiB memory in use. Process 241122 has 182.00 MiB memory in use. Process 241121 has 182.00 MiB memory in use. Of the allocated memory 4.54 GiB is allocated by PyTorch, and 104.08 MiB is reserved by PyTorch but unallocated. If reserved but unallocated memory is large try setting PYTORCH_CUDA_ALLOC_CONF=expandable_segments:True to avoid fragmentation.  See documentation for Memory Management  (https://pytorch.org/docs/stable/notes/cuda.html#environment-variables)

The above exception was the direct cause of the following exception:

[36mray::ClientAppActor.run()[39m (pid=241120, ip=115.145.172.224, actor_id=987481fb4b5d2360669e566001000000, repr=<flwr.simulation.ray_transport.ray_actor.ClientAppActor object at 0x7f68887856f0>)
  File "/home/abdenour/.local/lib/python3.10/site-packages/flwr/simulation/ray_transport/ray_actor.py", line 63, in run
    raise ClientAppException(str(ex)) from ex
flwr.client.client_app.ClientAppException: 
Exception ClientAppException occurred. Message: CUDA out of memory. Tried to allocate 12.00 MiB. GPU 0 has a total capacity of 10.75 GiB of which 4.75 MiB is free. Process 241123 has 5.56 GiB memory in use. Including non-PyTorch memory, this process has 4.82 GiB memory in use. Process 241122 has 182.00 MiB memory in use. Process 241121 has 182.00 MiB memory in use. Of the allocated memory 4.54 GiB is allocated by PyTorch, and 104.08 MiB is reserved by PyTorch but unallocated. If reserved but unallocated memory is large try setting PYTORCH_CUDA_ALLOC_CONF=expandable_segments:True to avoid fragmentation.  See documentation for Memory Management  (https://pytorch.org/docs/stable/notes/cuda.html#environment-variables)

[2024-09-08 00:05:46,731][flwr][ERROR] - [36mray::ClientAppActor.run()[39m (pid=241120, ip=115.145.172.224, actor_id=987481fb4b5d2360669e566001000000, repr=<flwr.simulation.ray_transport.ray_actor.ClientAppActor object at 0x7f68887856f0>)
  File "/home/abdenour/.local/lib/python3.10/site-packages/flwr/client/client_app.py", line 143, in __call__
    return self._call(message, context)
  File "/home/abdenour/.local/lib/python3.10/site-packages/flwr/client/client_app.py", line 126, in ffn
    out_message = handle_legacy_message_from_msgtype(
  File "/home/abdenour/.local/lib/python3.10/site-packages/flwr/client/message_handler/message_handler.py", line 129, in handle_legacy_message_from_msgtype
    fit_res = maybe_call_fit(
  File "/home/abdenour/.local/lib/python3.10/site-packages/flwr/client/client.py", line 234, in maybe_call_fit
    return client.fit(fit_ins)
  File "/home/abdenour/.local/lib/python3.10/site-packages/flwr/client/numpy_client.py", line 238, in _fit
    results = self.numpy_client.fit(parameters, ins.config)  # type: ignore
  File "/home/abdenour/fl_with_flower/fedavg_mobilnet/fedavg_mobilnet/client.py", line 46, in fit
    train(self.model, trainloader, optimizer, epochs=epochs, device=self.device)
  File "/home/abdenour/fl_with_flower/fedavg_mobilnet/fedavg_mobilnet/utils.py", line 40, in train
    loss = criterion(net(images), labels)
  File "/home/abdenour/anaconda3/envs/fl/lib/python3.10/site-packages/torch/nn/modules/module.py", line 1553, in _wrapped_call_impl
    return self._call_impl(*args, **kwargs)
  File "/home/abdenour/anaconda3/envs/fl/lib/python3.10/site-packages/torch/nn/modules/module.py", line 1562, in _call_impl
    return forward_call(*args, **kwargs)
  File "/home/abdenour/anaconda3/envs/fl/lib/python3.10/site-packages/torchvision/models/mobilenetv2.py", line 174, in forward
    return self._forward_impl(x)
  File "/home/abdenour/anaconda3/envs/fl/lib/python3.10/site-packages/torchvision/models/mobilenetv2.py", line 166, in _forward_impl
    x = self.features(x)
  File "/home/abdenour/anaconda3/envs/fl/lib/python3.10/site-packages/torch/nn/modules/module.py", line 1553, in _wrapped_call_impl
    return self._call_impl(*args, **kwargs)
  File "/home/abdenour/anaconda3/envs/fl/lib/python3.10/site-packages/torch/nn/modules/module.py", line 1562, in _call_impl
    return forward_call(*args, **kwargs)
  File "/home/abdenour/anaconda3/envs/fl/lib/python3.10/site-packages/torch/nn/modules/container.py", line 219, in forward
    input = module(input)
  File "/home/abdenour/anaconda3/envs/fl/lib/python3.10/site-packages/torch/nn/modules/module.py", line 1553, in _wrapped_call_impl
    return self._call_impl(*args, **kwargs)
  File "/home/abdenour/anaconda3/envs/fl/lib/python3.10/site-packages/torch/nn/modules/module.py", line 1562, in _call_impl
    return forward_call(*args, **kwargs)
  File "/home/abdenour/anaconda3/envs/fl/lib/python3.10/site-packages/torchvision/models/mobilenetv2.py", line 62, in forward
    return x + self.conv(x)
  File "/home/abdenour/anaconda3/envs/fl/lib/python3.10/site-packages/torch/nn/modules/module.py", line 1553, in _wrapped_call_impl
    return self._call_impl(*args, **kwargs)
  File "/home/abdenour/anaconda3/envs/fl/lib/python3.10/site-packages/torch/nn/modules/module.py", line 1562, in _call_impl
    return forward_call(*args, **kwargs)
  File "/home/abdenour/anaconda3/envs/fl/lib/python3.10/site-packages/torch/nn/modules/container.py", line 219, in forward
    input = module(input)
  File "/home/abdenour/anaconda3/envs/fl/lib/python3.10/site-packages/torch/nn/modules/module.py", line 1553, in _wrapped_call_impl
    return self._call_impl(*args, **kwargs)
  File "/home/abdenour/anaconda3/envs/fl/lib/python3.10/site-packages/torch/nn/modules/module.py", line 1562, in _call_impl
    return forward_call(*args, **kwargs)
  File "/home/abdenour/anaconda3/envs/fl/lib/python3.10/site-packages/torch/nn/modules/container.py", line 219, in forward
    input = module(input)
  File "/home/abdenour/anaconda3/envs/fl/lib/python3.10/site-packages/torch/nn/modules/module.py", line 1553, in _wrapped_call_impl
    return self._call_impl(*args, **kwargs)
  File "/home/abdenour/anaconda3/envs/fl/lib/python3.10/site-packages/torch/nn/modules/module.py", line 1562, in _call_impl
    return forward_call(*args, **kwargs)
  File "/home/abdenour/anaconda3/envs/fl/lib/python3.10/site-packages/torch/nn/modules/conv.py", line 458, in forward
    return self._conv_forward(input, self.weight, self.bias)
  File "/home/abdenour/anaconda3/envs/fl/lib/python3.10/site-packages/torch/nn/modules/conv.py", line 454, in _conv_forward
    return F.conv2d(input, weight, bias, self.stride,
torch.OutOfMemoryError: CUDA out of memory. Tried to allocate 12.00 MiB. GPU 0 has a total capacity of 10.75 GiB of which 4.75 MiB is free. Process 241123 has 5.56 GiB memory in use. Including non-PyTorch memory, this process has 4.82 GiB memory in use. Process 241122 has 182.00 MiB memory in use. Process 241121 has 182.00 MiB memory in use. Of the allocated memory 4.54 GiB is allocated by PyTorch, and 104.08 MiB is reserved by PyTorch but unallocated. If reserved but unallocated memory is large try setting PYTORCH_CUDA_ALLOC_CONF=expandable_segments:True to avoid fragmentation.  See documentation for Memory Management  (https://pytorch.org/docs/stable/notes/cuda.html#environment-variables)

The above exception was the direct cause of the following exception:

[36mray::ClientAppActor.run()[39m (pid=241120, ip=115.145.172.224, actor_id=987481fb4b5d2360669e566001000000, repr=<flwr.simulation.ray_transport.ray_actor.ClientAppActor object at 0x7f68887856f0>)
  File "/home/abdenour/.local/lib/python3.10/site-packages/flwr/simulation/ray_transport/ray_actor.py", line 63, in run
    raise ClientAppException(str(ex)) from ex
flwr.client.client_app.ClientAppException: 
Exception ClientAppException occurred. Message: CUDA out of memory. Tried to allocate 12.00 MiB. GPU 0 has a total capacity of 10.75 GiB of which 4.75 MiB is free. Process 241123 has 5.56 GiB memory in use. Including non-PyTorch memory, this process has 4.82 GiB memory in use. Process 241122 has 182.00 MiB memory in use. Process 241121 has 182.00 MiB memory in use. Of the allocated memory 4.54 GiB is allocated by PyTorch, and 104.08 MiB is reserved by PyTorch but unallocated. If reserved but unallocated memory is large try setting PYTORCH_CUDA_ALLOC_CONF=expandable_segments:True to avoid fragmentation.  See documentation for Memory Management  (https://pytorch.org/docs/stable/notes/cuda.html#environment-variables)
[2024-09-08 00:05:46,887][flwr][ERROR] - Traceback (most recent call last):
  File "/home/abdenour/.local/lib/python3.10/site-packages/flwr/simulation/ray_transport/ray_client_proxy.py", line 94, in _submit_job
    out_mssg, updated_context = self.actor_pool.get_client_result(
  File "/home/abdenour/.local/lib/python3.10/site-packages/flwr/simulation/ray_transport/ray_actor.py", line 398, in get_client_result
    return self._fetch_future_result(cid)
  File "/home/abdenour/.local/lib/python3.10/site-packages/flwr/simulation/ray_transport/ray_actor.py", line 279, in _fetch_future_result
    res_cid, out_mssg, updated_context = ray.get(
  File "/home/abdenour/.local/lib/python3.10/site-packages/ray/_private/auto_init_hook.py", line 21, in auto_init_wrapper
    return fn(*args, **kwargs)
  File "/home/abdenour/.local/lib/python3.10/site-packages/ray/_private/client_mode_hook.py", line 103, in wrapper
    return func(*args, **kwargs)
  File "/home/abdenour/.local/lib/python3.10/site-packages/ray/_private/worker.py", line 2667, in get
    values, debugger_breakpoint = worker.get_objects(object_refs, timeout=timeout)
  File "/home/abdenour/.local/lib/python3.10/site-packages/ray/_private/worker.py", line 864, in get_objects
    raise value.as_instanceof_cause()
ray.exceptions.RayTaskError(ClientAppException): [36mray::ClientAppActor.run()[39m (pid=241122, ip=115.145.172.224, actor_id=28ee19a52a8989d19149871201000000, repr=<flwr.simulation.ray_transport.ray_actor.ClientAppActor object at 0x7f774c789660>)
  File "/home/abdenour/.local/lib/python3.10/site-packages/flwr/client/client_app.py", line 143, in __call__
    return self._call(message, context)
  File "/home/abdenour/.local/lib/python3.10/site-packages/flwr/client/client_app.py", line 126, in ffn
    out_message = handle_legacy_message_from_msgtype(
  File "/home/abdenour/.local/lib/python3.10/site-packages/flwr/client/message_handler/message_handler.py", line 129, in handle_legacy_message_from_msgtype
    fit_res = maybe_call_fit(
  File "/home/abdenour/.local/lib/python3.10/site-packages/flwr/client/client.py", line 234, in maybe_call_fit
    return client.fit(fit_ins)
  File "/home/abdenour/.local/lib/python3.10/site-packages/flwr/client/numpy_client.py", line 238, in _fit
    results = self.numpy_client.fit(parameters, ins.config)  # type: ignore
  File "/home/abdenour/fl_with_flower/fedavg_mobilnet/fedavg_mobilnet/client.py", line 46, in fit
    train(self.model, trainloader, optimizer, epochs=epochs, device=self.device)
  File "/home/abdenour/fl_with_flower/fedavg_mobilnet/fedavg_mobilnet/utils.py", line 38, in train
    images, labels = batch["image"].to(device), batch["label"].to(device)
torch.OutOfMemoryError: CUDA out of memory. Tried to allocate 38.00 MiB. GPU 0 has a total capacity of 10.75 GiB of which 4.75 MiB is free. Process 241123 has 5.56 GiB memory in use. Process 241120 has 4.82 GiB memory in use. Including non-PyTorch memory, this process has 182.00 MiB memory in use. Process 241121 has 182.00 MiB memory in use. Of the allocated memory 8.73 MiB is allocated by PyTorch, and 19.27 MiB is reserved by PyTorch but unallocated. If reserved but unallocated memory is large try setting PYTORCH_CUDA_ALLOC_CONF=expandable_segments:True to avoid fragmentation.  See documentation for Memory Management  (https://pytorch.org/docs/stable/notes/cuda.html#environment-variables)

The above exception was the direct cause of the following exception:

[36mray::ClientAppActor.run()[39m (pid=241122, ip=115.145.172.224, actor_id=28ee19a52a8989d19149871201000000, repr=<flwr.simulation.ray_transport.ray_actor.ClientAppActor object at 0x7f774c789660>)
  File "/home/abdenour/.local/lib/python3.10/site-packages/flwr/simulation/ray_transport/ray_actor.py", line 63, in run
    raise ClientAppException(str(ex)) from ex
flwr.client.client_app.ClientAppException: 
Exception ClientAppException occurred. Message: CUDA out of memory. Tried to allocate 38.00 MiB. GPU 0 has a total capacity of 10.75 GiB of which 4.75 MiB is free. Process 241123 has 5.56 GiB memory in use. Process 241120 has 4.82 GiB memory in use. Including non-PyTorch memory, this process has 182.00 MiB memory in use. Process 241121 has 182.00 MiB memory in use. Of the allocated memory 8.73 MiB is allocated by PyTorch, and 19.27 MiB is reserved by PyTorch but unallocated. If reserved but unallocated memory is large try setting PYTORCH_CUDA_ALLOC_CONF=expandable_segments:True to avoid fragmentation.  See documentation for Memory Management  (https://pytorch.org/docs/stable/notes/cuda.html#environment-variables)

[2024-09-08 00:05:46,887][flwr][ERROR] - Traceback (most recent call last):
  File "/home/abdenour/.local/lib/python3.10/site-packages/flwr/simulation/ray_transport/ray_client_proxy.py", line 94, in _submit_job
    out_mssg, updated_context = self.actor_pool.get_client_result(
  File "/home/abdenour/.local/lib/python3.10/site-packages/flwr/simulation/ray_transport/ray_actor.py", line 398, in get_client_result
    return self._fetch_future_result(cid)
  File "/home/abdenour/.local/lib/python3.10/site-packages/flwr/simulation/ray_transport/ray_actor.py", line 279, in _fetch_future_result
    res_cid, out_mssg, updated_context = ray.get(
  File "/home/abdenour/.local/lib/python3.10/site-packages/ray/_private/auto_init_hook.py", line 21, in auto_init_wrapper
    return fn(*args, **kwargs)
  File "/home/abdenour/.local/lib/python3.10/site-packages/ray/_private/client_mode_hook.py", line 103, in wrapper
    return func(*args, **kwargs)
  File "/home/abdenour/.local/lib/python3.10/site-packages/ray/_private/worker.py", line 2667, in get
    values, debugger_breakpoint = worker.get_objects(object_refs, timeout=timeout)
  File "/home/abdenour/.local/lib/python3.10/site-packages/ray/_private/worker.py", line 864, in get_objects
    raise value.as_instanceof_cause()
ray.exceptions.RayTaskError(ClientAppException): [36mray::ClientAppActor.run()[39m (pid=241121, ip=115.145.172.224, actor_id=18e71555ed294bd91cd317e401000000, repr=<flwr.simulation.ray_transport.ray_actor.ClientAppActor object at 0x7f0a245916f0>)
  File "/home/abdenour/.local/lib/python3.10/site-packages/flwr/client/client_app.py", line 143, in __call__
    return self._call(message, context)
  File "/home/abdenour/.local/lib/python3.10/site-packages/flwr/client/client_app.py", line 126, in ffn
    out_message = handle_legacy_message_from_msgtype(
  File "/home/abdenour/.local/lib/python3.10/site-packages/flwr/client/message_handler/message_handler.py", line 129, in handle_legacy_message_from_msgtype
    fit_res = maybe_call_fit(
  File "/home/abdenour/.local/lib/python3.10/site-packages/flwr/client/client.py", line 234, in maybe_call_fit
    return client.fit(fit_ins)
  File "/home/abdenour/.local/lib/python3.10/site-packages/flwr/client/numpy_client.py", line 238, in _fit
    results = self.numpy_client.fit(parameters, ins.config)  # type: ignore
  File "/home/abdenour/fl_with_flower/fedavg_mobilnet/fedavg_mobilnet/client.py", line 46, in fit
    train(self.model, trainloader, optimizer, epochs=epochs, device=self.device)
  File "/home/abdenour/fl_with_flower/fedavg_mobilnet/fedavg_mobilnet/utils.py", line 38, in train
    images, labels = batch["image"].to(device), batch["label"].to(device)
torch.OutOfMemoryError: CUDA out of memory. Tried to allocate 38.00 MiB. GPU 0 has a total capacity of 10.75 GiB of which 4.75 MiB is free. Process 241123 has 5.56 GiB memory in use. Process 241120 has 4.82 GiB memory in use. Process 241122 has 182.00 MiB memory in use. Including non-PyTorch memory, this process has 182.00 MiB memory in use. Of the allocated memory 8.73 MiB is allocated by PyTorch, and 19.27 MiB is reserved by PyTorch but unallocated. If reserved but unallocated memory is large try setting PYTORCH_CUDA_ALLOC_CONF=expandable_segments:True to avoid fragmentation.  See documentation for Memory Management  (https://pytorch.org/docs/stable/notes/cuda.html#environment-variables)

The above exception was the direct cause of the following exception:

[36mray::ClientAppActor.run()[39m (pid=241121, ip=115.145.172.224, actor_id=18e71555ed294bd91cd317e401000000, repr=<flwr.simulation.ray_transport.ray_actor.ClientAppActor object at 0x7f0a245916f0>)
  File "/home/abdenour/.local/lib/python3.10/site-packages/flwr/simulation/ray_transport/ray_actor.py", line 63, in run
    raise ClientAppException(str(ex)) from ex
flwr.client.client_app.ClientAppException: 
Exception ClientAppException occurred. Message: CUDA out of memory. Tried to allocate 38.00 MiB. GPU 0 has a total capacity of 10.75 GiB of which 4.75 MiB is free. Process 241123 has 5.56 GiB memory in use. Process 241120 has 4.82 GiB memory in use. Process 241122 has 182.00 MiB memory in use. Including non-PyTorch memory, this process has 182.00 MiB memory in use. Of the allocated memory 8.73 MiB is allocated by PyTorch, and 19.27 MiB is reserved by PyTorch but unallocated. If reserved but unallocated memory is large try setting PYTORCH_CUDA_ALLOC_CONF=expandable_segments:True to avoid fragmentation.  See documentation for Memory Management  (https://pytorch.org/docs/stable/notes/cuda.html#environment-variables)

[2024-09-08 00:05:46,888][flwr][ERROR] - [36mray::ClientAppActor.run()[39m (pid=241122, ip=115.145.172.224, actor_id=28ee19a52a8989d19149871201000000, repr=<flwr.simulation.ray_transport.ray_actor.ClientAppActor object at 0x7f774c789660>)
  File "/home/abdenour/.local/lib/python3.10/site-packages/flwr/client/client_app.py", line 143, in __call__
    return self._call(message, context)
  File "/home/abdenour/.local/lib/python3.10/site-packages/flwr/client/client_app.py", line 126, in ffn
    out_message = handle_legacy_message_from_msgtype(
  File "/home/abdenour/.local/lib/python3.10/site-packages/flwr/client/message_handler/message_handler.py", line 129, in handle_legacy_message_from_msgtype
    fit_res = maybe_call_fit(
  File "/home/abdenour/.local/lib/python3.10/site-packages/flwr/client/client.py", line 234, in maybe_call_fit
    return client.fit(fit_ins)
  File "/home/abdenour/.local/lib/python3.10/site-packages/flwr/client/numpy_client.py", line 238, in _fit
    results = self.numpy_client.fit(parameters, ins.config)  # type: ignore
  File "/home/abdenour/fl_with_flower/fedavg_mobilnet/fedavg_mobilnet/client.py", line 46, in fit
    train(self.model, trainloader, optimizer, epochs=epochs, device=self.device)
  File "/home/abdenour/fl_with_flower/fedavg_mobilnet/fedavg_mobilnet/utils.py", line 38, in train
    images, labels = batch["image"].to(device), batch["label"].to(device)
torch.OutOfMemoryError: CUDA out of memory. Tried to allocate 38.00 MiB. GPU 0 has a total capacity of 10.75 GiB of which 4.75 MiB is free. Process 241123 has 5.56 GiB memory in use. Process 241120 has 4.82 GiB memory in use. Including non-PyTorch memory, this process has 182.00 MiB memory in use. Process 241121 has 182.00 MiB memory in use. Of the allocated memory 8.73 MiB is allocated by PyTorch, and 19.27 MiB is reserved by PyTorch but unallocated. If reserved but unallocated memory is large try setting PYTORCH_CUDA_ALLOC_CONF=expandable_segments:True to avoid fragmentation.  See documentation for Memory Management  (https://pytorch.org/docs/stable/notes/cuda.html#environment-variables)

The above exception was the direct cause of the following exception:

[36mray::ClientAppActor.run()[39m (pid=241122, ip=115.145.172.224, actor_id=28ee19a52a8989d19149871201000000, repr=<flwr.simulation.ray_transport.ray_actor.ClientAppActor object at 0x7f774c789660>)
  File "/home/abdenour/.local/lib/python3.10/site-packages/flwr/simulation/ray_transport/ray_actor.py", line 63, in run
    raise ClientAppException(str(ex)) from ex
flwr.client.client_app.ClientAppException: 
Exception ClientAppException occurred. Message: CUDA out of memory. Tried to allocate 38.00 MiB. GPU 0 has a total capacity of 10.75 GiB of which 4.75 MiB is free. Process 241123 has 5.56 GiB memory in use. Process 241120 has 4.82 GiB memory in use. Including non-PyTorch memory, this process has 182.00 MiB memory in use. Process 241121 has 182.00 MiB memory in use. Of the allocated memory 8.73 MiB is allocated by PyTorch, and 19.27 MiB is reserved by PyTorch but unallocated. If reserved but unallocated memory is large try setting PYTORCH_CUDA_ALLOC_CONF=expandable_segments:True to avoid fragmentation.  See documentation for Memory Management  (https://pytorch.org/docs/stable/notes/cuda.html#environment-variables)
[2024-09-08 00:05:46,888][flwr][ERROR] - [36mray::ClientAppActor.run()[39m (pid=241121, ip=115.145.172.224, actor_id=18e71555ed294bd91cd317e401000000, repr=<flwr.simulation.ray_transport.ray_actor.ClientAppActor object at 0x7f0a245916f0>)
  File "/home/abdenour/.local/lib/python3.10/site-packages/flwr/client/client_app.py", line 143, in __call__
    return self._call(message, context)
  File "/home/abdenour/.local/lib/python3.10/site-packages/flwr/client/client_app.py", line 126, in ffn
    out_message = handle_legacy_message_from_msgtype(
  File "/home/abdenour/.local/lib/python3.10/site-packages/flwr/client/message_handler/message_handler.py", line 129, in handle_legacy_message_from_msgtype
    fit_res = maybe_call_fit(
  File "/home/abdenour/.local/lib/python3.10/site-packages/flwr/client/client.py", line 234, in maybe_call_fit
    return client.fit(fit_ins)
  File "/home/abdenour/.local/lib/python3.10/site-packages/flwr/client/numpy_client.py", line 238, in _fit
    results = self.numpy_client.fit(parameters, ins.config)  # type: ignore
  File "/home/abdenour/fl_with_flower/fedavg_mobilnet/fedavg_mobilnet/client.py", line 46, in fit
    train(self.model, trainloader, optimizer, epochs=epochs, device=self.device)
  File "/home/abdenour/fl_with_flower/fedavg_mobilnet/fedavg_mobilnet/utils.py", line 38, in train
    images, labels = batch["image"].to(device), batch["label"].to(device)
torch.OutOfMemoryError: CUDA out of memory. Tried to allocate 38.00 MiB. GPU 0 has a total capacity of 10.75 GiB of which 4.75 MiB is free. Process 241123 has 5.56 GiB memory in use. Process 241120 has 4.82 GiB memory in use. Process 241122 has 182.00 MiB memory in use. Including non-PyTorch memory, this process has 182.00 MiB memory in use. Of the allocated memory 8.73 MiB is allocated by PyTorch, and 19.27 MiB is reserved by PyTorch but unallocated. If reserved but unallocated memory is large try setting PYTORCH_CUDA_ALLOC_CONF=expandable_segments:True to avoid fragmentation.  See documentation for Memory Management  (https://pytorch.org/docs/stable/notes/cuda.html#environment-variables)

The above exception was the direct cause of the following exception:

[36mray::ClientAppActor.run()[39m (pid=241121, ip=115.145.172.224, actor_id=18e71555ed294bd91cd317e401000000, repr=<flwr.simulation.ray_transport.ray_actor.ClientAppActor object at 0x7f0a245916f0>)
  File "/home/abdenour/.local/lib/python3.10/site-packages/flwr/simulation/ray_transport/ray_actor.py", line 63, in run
    raise ClientAppException(str(ex)) from ex
flwr.client.client_app.ClientAppException: 
Exception ClientAppException occurred. Message: CUDA out of memory. Tried to allocate 38.00 MiB. GPU 0 has a total capacity of 10.75 GiB of which 4.75 MiB is free. Process 241123 has 5.56 GiB memory in use. Process 241120 has 4.82 GiB memory in use. Process 241122 has 182.00 MiB memory in use. Including non-PyTorch memory, this process has 182.00 MiB memory in use. Of the allocated memory 8.73 MiB is allocated by PyTorch, and 19.27 MiB is reserved by PyTorch but unallocated. If reserved but unallocated memory is large try setting PYTORCH_CUDA_ALLOC_CONF=expandable_segments:True to avoid fragmentation.  See documentation for Memory Management  (https://pytorch.org/docs/stable/notes/cuda.html#environment-variables)
[2024-09-08 00:05:57,099][flwr][INFO] - aggregate_fit: received 2 results and 3 failures
[2024-09-08 00:05:57,196][flwr][WARNING] - No fit_metrics_aggregation_fn provided
