[2024-09-10 13:54:53,117][flwr][INFO] - Starting Flower simulation, config: num_rounds=100, no round_timeout
[2024-09-10 13:54:58,940][flwr][INFO] - Flower VCE: Ray initialized with resources: {'CPU': 32.0, 'object_store_memory': 8297915596.0, 'node:115.145.171.128': 1.0, 'memory': 16595831195.0, 'accelerator_type:G': 1.0, 'GPU': 1.0, 'node:__internal_head__': 1.0}
[2024-09-10 13:54:58,940][flwr][INFO] - Optimize your simulation with Flower VCE: https://flower.ai/docs/framework/how-to-run-simulations.html
[2024-09-10 13:54:58,940][flwr][INFO] - Flower VCE: Resources for each Virtual Client: {'num_cpus': 16, 'num_gpus': 0.25}
[2024-09-10 13:54:58,950][flwr][INFO] - Flower VCE: Creating VirtualClientEngineActorPool with 2 actors
[2024-09-10 13:54:58,950][flwr][INFO] - [INIT]
[2024-09-10 13:54:58,950][flwr][INFO] - Requesting initial parameters from one random client
[2024-09-10 13:55:01,648][flwr][INFO] - Received initial parameters from one random client
[2024-09-10 13:55:01,648][flwr][INFO] - Evaluating initial global parameters
[2024-09-10 13:55:06,020][flwr][INFO] - initial parameters (loss, other metrics): 236.5128493309021, {'accuracy': 0.12247880736626718}
[2024-09-10 13:55:06,020][flwr][INFO] - 
[2024-09-10 13:55:06,020][flwr][INFO] - [ROUND 1]
[2024-09-10 13:55:06,020][flwr][INFO] - configure_fit: strategy sampled 5 clients (out of 50)
[2024-09-10 13:55:08,335][flwr][ERROR] - Traceback (most recent call last):
  File "/home/abdenour/miniconda3/envs/fl_with_flower/lib/python3.11/site-packages/flwr/simulation/ray_transport/ray_client_proxy.py", line 94, in _submit_job
    out_mssg, updated_context = self.actor_pool.get_client_result(
                                ^^^^^^^^^^^^^^^^^^^^^^^^^^^^^^^^^^
  File "/home/abdenour/miniconda3/envs/fl_with_flower/lib/python3.11/site-packages/flwr/simulation/ray_transport/ray_actor.py", line 398, in get_client_result
    return self._fetch_future_result(cid)
           ^^^^^^^^^^^^^^^^^^^^^^^^^^^^^^
  File "/home/abdenour/miniconda3/envs/fl_with_flower/lib/python3.11/site-packages/flwr/simulation/ray_transport/ray_actor.py", line 279, in _fetch_future_result
    res_cid, out_mssg, updated_context = ray.get(
                                         ^^^^^^^^
  File "/home/abdenour/miniconda3/envs/fl_with_flower/lib/python3.11/site-packages/ray/_private/auto_init_hook.py", line 21, in auto_init_wrapper
    return fn(*args, **kwargs)
           ^^^^^^^^^^^^^^^^^^^
  File "/home/abdenour/miniconda3/envs/fl_with_flower/lib/python3.11/site-packages/ray/_private/client_mode_hook.py", line 103, in wrapper
    return func(*args, **kwargs)
           ^^^^^^^^^^^^^^^^^^^^^
  File "/home/abdenour/miniconda3/envs/fl_with_flower/lib/python3.11/site-packages/ray/_private/worker.py", line 2667, in get
    values, debugger_breakpoint = worker.get_objects(object_refs, timeout=timeout)
                                  ^^^^^^^^^^^^^^^^^^^^^^^^^^^^^^^^^^^^^^^^^^^^^^^^
  File "/home/abdenour/miniconda3/envs/fl_with_flower/lib/python3.11/site-packages/ray/_private/worker.py", line 864, in get_objects
    raise value.as_instanceof_cause()
ray.exceptions.RayTaskError(ClientAppException): [36mray::ClientAppActor.run()[39m (pid=10227, ip=115.145.171.128, actor_id=4130a17356adc963491580af01000000, repr=<flwr.simulation.ray_transport.ray_actor.ClientAppActor object at 0x78fb9c17b350>)
                  ^^^^^^^^^^^^^^^^^^^^^^^^^^^^^^^^^^^^^
  File "/home/abdenour/miniconda3/envs/fl_with_flower/lib/python3.11/site-packages/flwr/client/client_app.py", line 143, in __call__
    return self._call(message, context)
           ^^^^^^^^^^^^^^^^^^^^^^^^^^^^
  File "/home/abdenour/miniconda3/envs/fl_with_flower/lib/python3.11/site-packages/flwr/client/client_app.py", line 126, in ffn
    out_message = handle_legacy_message_from_msgtype(
                  ^^^^^^^^^^^^^^^^^^^^^^^^^^^^^^^^^^^
  File "/home/abdenour/miniconda3/envs/fl_with_flower/lib/python3.11/site-packages/flwr/client/message_handler/message_handler.py", line 129, in handle_legacy_message_from_msgtype
    fit_res = maybe_call_fit(
              ^^^^^^^^^^^^^^^
  File "/home/abdenour/miniconda3/envs/fl_with_flower/lib/python3.11/site-packages/flwr/client/client.py", line 234, in maybe_call_fit
    return client.fit(fit_ins)
           ^^^^^^^^^^^^^^^^^^^
  File "/home/abdenour/miniconda3/envs/fl_with_flower/lib/python3.11/site-packages/flwr/client/numpy_client.py", line 238, in _fit
    results = self.numpy_client.fit(parameters, ins.config)  # type: ignore
              ^^^^^^^^^^^^^^^^^^^^^^^^^^^^^^^^^^^^^^^^^^^^^
  File "/home/abdenour/PycharmProjects/fl_with_flower/fedavg_mobilnet_poisoned/fedavg_mobilnet/client.py", line 46, in fit
    train(self.model, trainloader, optimizer, epochs=epochs, device=self.device)
  File "/home/abdenour/PycharmProjects/fl_with_flower/fedavg_mobilnet_poisoned/fedavg_mobilnet/utils.py", line 41, in train
    loss.backward()
  File "/home/abdenour/miniconda3/envs/fl_with_flower/lib/python3.11/site-packages/torch/_tensor.py", line 492, in backward
    torch.autograd.backward(
  File "/home/abdenour/miniconda3/envs/fl_with_flower/lib/python3.11/site-packages/torch/autograd/__init__.py", line 251, in backward
    Variable._execution_engine.run_backward(  # Calls into the C++ engine to run the backward pass
RuntimeError: cuDNN error: CUDNN_STATUS_NOT_INITIALIZED

The above exception was the direct cause of the following exception:

[36mray::ClientAppActor.run()[39m (pid=10227, ip=115.145.171.128, actor_id=4130a17356adc963491580af01000000, repr=<flwr.simulation.ray_transport.ray_actor.ClientAppActor object at 0x78fb9c17b350>)
           ^^^^^^^^^^^^^^^^^^^^^^^^^^^^^^^^^^^^
           ^^^^^^^^^^^^^^^^^^^^^^^^^^^^^^^
  File "/home/abdenour/miniconda3/envs/fl_with_flower/lib/python3.11/site-packages/flwr/simulation/ray_transport/ray_actor.py", line 63, in run
    raise ClientAppException(str(ex)) from ex
flwr.client.client_app.ClientAppException: 
Exception ClientAppException occurred. Message: cuDNN error: CUDNN_STATUS_NOT_INITIALIZED

[2024-09-10 13:55:08,335][flwr][ERROR] - [36mray::ClientAppActor.run()[39m (pid=10227, ip=115.145.171.128, actor_id=4130a17356adc963491580af01000000, repr=<flwr.simulation.ray_transport.ray_actor.ClientAppActor object at 0x78fb9c17b350>)
                  ^^^^^^^^^^^^^^^^^^^^^^^^^^^^^^^^^^^^^
  File "/home/abdenour/miniconda3/envs/fl_with_flower/lib/python3.11/site-packages/flwr/client/client_app.py", line 143, in __call__
    return self._call(message, context)
           ^^^^^^^^^^^^^^^^^^^^^^^^^^^^
  File "/home/abdenour/miniconda3/envs/fl_with_flower/lib/python3.11/site-packages/flwr/client/client_app.py", line 126, in ffn
    out_message = handle_legacy_message_from_msgtype(
                  ^^^^^^^^^^^^^^^^^^^^^^^^^^^^^^^^^^^
  File "/home/abdenour/miniconda3/envs/fl_with_flower/lib/python3.11/site-packages/flwr/client/message_handler/message_handler.py", line 129, in handle_legacy_message_from_msgtype
    fit_res = maybe_call_fit(
              ^^^^^^^^^^^^^^^
  File "/home/abdenour/miniconda3/envs/fl_with_flower/lib/python3.11/site-packages/flwr/client/client.py", line 234, in maybe_call_fit
    return client.fit(fit_ins)
           ^^^^^^^^^^^^^^^^^^^
  File "/home/abdenour/miniconda3/envs/fl_with_flower/lib/python3.11/site-packages/flwr/client/numpy_client.py", line 238, in _fit
    results = self.numpy_client.fit(parameters, ins.config)  # type: ignore
              ^^^^^^^^^^^^^^^^^^^^^^^^^^^^^^^^^^^^^^^^^^^^^
  File "/home/abdenour/PycharmProjects/fl_with_flower/fedavg_mobilnet_poisoned/fedavg_mobilnet/client.py", line 46, in fit
    train(self.model, trainloader, optimizer, epochs=epochs, device=self.device)
  File "/home/abdenour/PycharmProjects/fl_with_flower/fedavg_mobilnet_poisoned/fedavg_mobilnet/utils.py", line 41, in train
    loss.backward()
  File "/home/abdenour/miniconda3/envs/fl_with_flower/lib/python3.11/site-packages/torch/_tensor.py", line 492, in backward
    torch.autograd.backward(
  File "/home/abdenour/miniconda3/envs/fl_with_flower/lib/python3.11/site-packages/torch/autograd/__init__.py", line 251, in backward
    Variable._execution_engine.run_backward(  # Calls into the C++ engine to run the backward pass
RuntimeError: cuDNN error: CUDNN_STATUS_NOT_INITIALIZED

The above exception was the direct cause of the following exception:

[36mray::ClientAppActor.run()[39m (pid=10227, ip=115.145.171.128, actor_id=4130a17356adc963491580af01000000, repr=<flwr.simulation.ray_transport.ray_actor.ClientAppActor object at 0x78fb9c17b350>)
           ^^^^^^^^^^^^^^^^^^^^^^^^^^^^^^^^^^^^
           ^^^^^^^^^^^^^^^^^^^^^^^^^^^^^^^
  File "/home/abdenour/miniconda3/envs/fl_with_flower/lib/python3.11/site-packages/flwr/simulation/ray_transport/ray_actor.py", line 63, in run
    raise ClientAppException(str(ex)) from ex
flwr.client.client_app.ClientAppException: 
Exception ClientAppException occurred. Message: cuDNN error: CUDNN_STATUS_NOT_INITIALIZED
[2024-09-10 13:55:08,560][flwr][ERROR] - Traceback (most recent call last):
  File "/home/abdenour/miniconda3/envs/fl_with_flower/lib/python3.11/site-packages/flwr/simulation/ray_transport/ray_client_proxy.py", line 94, in _submit_job
    out_mssg, updated_context = self.actor_pool.get_client_result(
                                ^^^^^^^^^^^^^^^^^^^^^^^^^^^^^^^^^^
  File "/home/abdenour/miniconda3/envs/fl_with_flower/lib/python3.11/site-packages/flwr/simulation/ray_transport/ray_actor.py", line 398, in get_client_result
    return self._fetch_future_result(cid)
           ^^^^^^^^^^^^^^^^^^^^^^^^^^^^^^
  File "/home/abdenour/miniconda3/envs/fl_with_flower/lib/python3.11/site-packages/flwr/simulation/ray_transport/ray_actor.py", line 279, in _fetch_future_result
    res_cid, out_mssg, updated_context = ray.get(
                                         ^^^^^^^^
  File "/home/abdenour/miniconda3/envs/fl_with_flower/lib/python3.11/site-packages/ray/_private/auto_init_hook.py", line 21, in auto_init_wrapper
    return fn(*args, **kwargs)
           ^^^^^^^^^^^^^^^^^^^
  File "/home/abdenour/miniconda3/envs/fl_with_flower/lib/python3.11/site-packages/ray/_private/client_mode_hook.py", line 103, in wrapper
    return func(*args, **kwargs)
           ^^^^^^^^^^^^^^^^^^^^^
  File "/home/abdenour/miniconda3/envs/fl_with_flower/lib/python3.11/site-packages/ray/_private/worker.py", line 2667, in get
    values, debugger_breakpoint = worker.get_objects(object_refs, timeout=timeout)
                                  ^^^^^^^^^^^^^^^^^^^^^^^^^^^^^^^^^^^^^^^^^^^^^^^^
  File "/home/abdenour/miniconda3/envs/fl_with_flower/lib/python3.11/site-packages/ray/_private/worker.py", line 864, in get_objects
    raise value.as_instanceof_cause()
ray.exceptions.RayTaskError(ClientAppException): [36mray::ClientAppActor.run()[39m (pid=10227, ip=115.145.171.128, actor_id=4130a17356adc963491580af01000000, repr=<flwr.simulation.ray_transport.ray_actor.ClientAppActor object at 0x78fb9c17b350>)
                  ^^^^^^^^^^^^^^^^^^^^^^^^^^^^^^^^^^^^^
  File "/home/abdenour/miniconda3/envs/fl_with_flower/lib/python3.11/site-packages/flwr/client/client_app.py", line 143, in __call__
    return self._call(message, context)
           ^^^^^^^^^^^^^^^^^^^^^^^^^^^^
  File "/home/abdenour/miniconda3/envs/fl_with_flower/lib/python3.11/site-packages/flwr/client/client_app.py", line 126, in ffn
    out_message = handle_legacy_message_from_msgtype(
                  ^^^^^^^^^^^^^^^^^^^^^^^^^^^^^^^^^^^
  File "/home/abdenour/miniconda3/envs/fl_with_flower/lib/python3.11/site-packages/flwr/client/message_handler/message_handler.py", line 129, in handle_legacy_message_from_msgtype
    fit_res = maybe_call_fit(
              ^^^^^^^^^^^^^^^
  File "/home/abdenour/miniconda3/envs/fl_with_flower/lib/python3.11/site-packages/flwr/client/client.py", line 234, in maybe_call_fit
    return client.fit(fit_ins)
           ^^^^^^^^^^^^^^^^^^^
  File "/home/abdenour/miniconda3/envs/fl_with_flower/lib/python3.11/site-packages/flwr/client/numpy_client.py", line 238, in _fit
    results = self.numpy_client.fit(parameters, ins.config)  # type: ignore
              ^^^^^^^^^^^^^^^^^^^^^^^^^^^^^^^^^^^^^^^^^^^^^
  File "/home/abdenour/PycharmProjects/fl_with_flower/fedavg_mobilnet_poisoned/fedavg_mobilnet/client.py", line 46, in fit
    train(self.model, trainloader, optimizer, epochs=epochs, device=self.device)
  File "/home/abdenour/PycharmProjects/fl_with_flower/fedavg_mobilnet_poisoned/fedavg_mobilnet/utils.py", line 41, in train
    loss.backward()
  File "/home/abdenour/miniconda3/envs/fl_with_flower/lib/python3.11/site-packages/torch/_tensor.py", line 492, in backward
    torch.autograd.backward(
  File "/home/abdenour/miniconda3/envs/fl_with_flower/lib/python3.11/site-packages/torch/autograd/__init__.py", line 251, in backward
    Variable._execution_engine.run_backward(  # Calls into the C++ engine to run the backward pass
RuntimeError: cuDNN error: CUDNN_STATUS_NOT_INITIALIZED

The above exception was the direct cause of the following exception:

[36mray::ClientAppActor.run()[39m (pid=10227, ip=115.145.171.128, actor_id=4130a17356adc963491580af01000000, repr=<flwr.simulation.ray_transport.ray_actor.ClientAppActor object at 0x78fb9c17b350>)
           ^^^^^^^^^^^^^^^^^^^^^^^^^^^^^^^^^^^^
           ^^^^^^^^^^^^^^^^^^^^^^^^^^^^^^^
  File "/home/abdenour/miniconda3/envs/fl_with_flower/lib/python3.11/site-packages/flwr/simulation/ray_transport/ray_actor.py", line 63, in run
    raise ClientAppException(str(ex)) from ex
flwr.client.client_app.ClientAppException: 
Exception ClientAppException occurred. Message: cuDNN error: CUDNN_STATUS_NOT_INITIALIZED

[2024-09-10 13:55:08,561][flwr][ERROR] - [36mray::ClientAppActor.run()[39m (pid=10227, ip=115.145.171.128, actor_id=4130a17356adc963491580af01000000, repr=<flwr.simulation.ray_transport.ray_actor.ClientAppActor object at 0x78fb9c17b350>)
                  ^^^^^^^^^^^^^^^^^^^^^^^^^^^^^^^^^^^^^
  File "/home/abdenour/miniconda3/envs/fl_with_flower/lib/python3.11/site-packages/flwr/client/client_app.py", line 143, in __call__
    return self._call(message, context)
           ^^^^^^^^^^^^^^^^^^^^^^^^^^^^
  File "/home/abdenour/miniconda3/envs/fl_with_flower/lib/python3.11/site-packages/flwr/client/client_app.py", line 126, in ffn
    out_message = handle_legacy_message_from_msgtype(
                  ^^^^^^^^^^^^^^^^^^^^^^^^^^^^^^^^^^^
  File "/home/abdenour/miniconda3/envs/fl_with_flower/lib/python3.11/site-packages/flwr/client/message_handler/message_handler.py", line 129, in handle_legacy_message_from_msgtype
    fit_res = maybe_call_fit(
              ^^^^^^^^^^^^^^^
  File "/home/abdenour/miniconda3/envs/fl_with_flower/lib/python3.11/site-packages/flwr/client/client.py", line 234, in maybe_call_fit
    return client.fit(fit_ins)
           ^^^^^^^^^^^^^^^^^^^
  File "/home/abdenour/miniconda3/envs/fl_with_flower/lib/python3.11/site-packages/flwr/client/numpy_client.py", line 238, in _fit
    results = self.numpy_client.fit(parameters, ins.config)  # type: ignore
              ^^^^^^^^^^^^^^^^^^^^^^^^^^^^^^^^^^^^^^^^^^^^^
  File "/home/abdenour/PycharmProjects/fl_with_flower/fedavg_mobilnet_poisoned/fedavg_mobilnet/client.py", line 46, in fit
    train(self.model, trainloader, optimizer, epochs=epochs, device=self.device)
  File "/home/abdenour/PycharmProjects/fl_with_flower/fedavg_mobilnet_poisoned/fedavg_mobilnet/utils.py", line 41, in train
    loss.backward()
  File "/home/abdenour/miniconda3/envs/fl_with_flower/lib/python3.11/site-packages/torch/_tensor.py", line 492, in backward
    torch.autograd.backward(
  File "/home/abdenour/miniconda3/envs/fl_with_flower/lib/python3.11/site-packages/torch/autograd/__init__.py", line 251, in backward
    Variable._execution_engine.run_backward(  # Calls into the C++ engine to run the backward pass
RuntimeError: cuDNN error: CUDNN_STATUS_NOT_INITIALIZED

The above exception was the direct cause of the following exception:

[36mray::ClientAppActor.run()[39m (pid=10227, ip=115.145.171.128, actor_id=4130a17356adc963491580af01000000, repr=<flwr.simulation.ray_transport.ray_actor.ClientAppActor object at 0x78fb9c17b350>)
           ^^^^^^^^^^^^^^^^^^^^^^^^^^^^^^^^^^^^
           ^^^^^^^^^^^^^^^^^^^^^^^^^^^^^^^
  File "/home/abdenour/miniconda3/envs/fl_with_flower/lib/python3.11/site-packages/flwr/simulation/ray_transport/ray_actor.py", line 63, in run
    raise ClientAppException(str(ex)) from ex
flwr.client.client_app.ClientAppException: 
Exception ClientAppException occurred. Message: cuDNN error: CUDNN_STATUS_NOT_INITIALIZED
[2024-09-10 13:55:09,273][flwr][INFO] - aggregate_fit: received 3 results and 2 failures
[2024-09-10 13:55:09,296][flwr][WARNING] - No fit_metrics_aggregation_fn provided
[2024-09-10 13:55:13,426][flwr][INFO] - fit progress: (1, 205.49209713935852, {'accuracy': 0.36977491961414793}, 7.405205891999913)
[2024-09-10 13:55:13,426][flwr][INFO] - configure_evaluate: strategy sampled 2 clients (out of 50)
[2024-09-10 13:55:13,637][flwr][INFO] - aggregate_evaluate: received 2 results and 0 failures
[2024-09-10 13:55:13,637][flwr][INFO] - 
[2024-09-10 13:55:13,637][flwr][INFO] - [ROUND 2]
[2024-09-10 13:55:13,637][flwr][INFO] - configure_fit: strategy sampled 5 clients (out of 50)
[2024-09-10 13:55:13,827][flwr][ERROR] - Traceback (most recent call last):
  File "/home/abdenour/miniconda3/envs/fl_with_flower/lib/python3.11/site-packages/flwr/simulation/ray_transport/ray_client_proxy.py", line 94, in _submit_job
    out_mssg, updated_context = self.actor_pool.get_client_result(
                                ^^^^^^^^^^^^^^^^^^^^^^^^^^^^^^^^^^
  File "/home/abdenour/miniconda3/envs/fl_with_flower/lib/python3.11/site-packages/flwr/simulation/ray_transport/ray_actor.py", line 398, in get_client_result
    return self._fetch_future_result(cid)
           ^^^^^^^^^^^^^^^^^^^^^^^^^^^^^^
  File "/home/abdenour/miniconda3/envs/fl_with_flower/lib/python3.11/site-packages/flwr/simulation/ray_transport/ray_actor.py", line 279, in _fetch_future_result
    res_cid, out_mssg, updated_context = ray.get(
                                         ^^^^^^^^
  File "/home/abdenour/miniconda3/envs/fl_with_flower/lib/python3.11/site-packages/ray/_private/auto_init_hook.py", line 21, in auto_init_wrapper
    return fn(*args, **kwargs)
           ^^^^^^^^^^^^^^^^^^^
  File "/home/abdenour/miniconda3/envs/fl_with_flower/lib/python3.11/site-packages/ray/_private/client_mode_hook.py", line 103, in wrapper
    return func(*args, **kwargs)
           ^^^^^^^^^^^^^^^^^^^^^
  File "/home/abdenour/miniconda3/envs/fl_with_flower/lib/python3.11/site-packages/ray/_private/worker.py", line 2667, in get
    values, debugger_breakpoint = worker.get_objects(object_refs, timeout=timeout)
                                  ^^^^^^^^^^^^^^^^^^^^^^^^^^^^^^^^^^^^^^^^^^^^^^^^
  File "/home/abdenour/miniconda3/envs/fl_with_flower/lib/python3.11/site-packages/ray/_private/worker.py", line 864, in get_objects
    raise value.as_instanceof_cause()
ray.exceptions.RayTaskError(ClientAppException): [36mray::ClientAppActor.run()[39m (pid=10227, ip=115.145.171.128, actor_id=4130a17356adc963491580af01000000, repr=<flwr.simulation.ray_transport.ray_actor.ClientAppActor object at 0x78fb9c17b350>)
                  ^^^^^^^^^^^^^^^^^^^^^^^^^^^^^^^^^^^^^
  File "/home/abdenour/miniconda3/envs/fl_with_flower/lib/python3.11/site-packages/flwr/client/client_app.py", line 143, in __call__
    return self._call(message, context)
           ^^^^^^^^^^^^^^^^^^^^^^^^^^^^
  File "/home/abdenour/miniconda3/envs/fl_with_flower/lib/python3.11/site-packages/flwr/client/client_app.py", line 126, in ffn
    out_message = handle_legacy_message_from_msgtype(
                  ^^^^^^^^^^^^^^^^^^^^^^^^^^^^^^^^^^^
  File "/home/abdenour/miniconda3/envs/fl_with_flower/lib/python3.11/site-packages/flwr/client/message_handler/message_handler.py", line 129, in handle_legacy_message_from_msgtype
    fit_res = maybe_call_fit(
              ^^^^^^^^^^^^^^^
  File "/home/abdenour/miniconda3/envs/fl_with_flower/lib/python3.11/site-packages/flwr/client/client.py", line 234, in maybe_call_fit
    return client.fit(fit_ins)
           ^^^^^^^^^^^^^^^^^^^
  File "/home/abdenour/miniconda3/envs/fl_with_flower/lib/python3.11/site-packages/flwr/client/numpy_client.py", line 238, in _fit
    results = self.numpy_client.fit(parameters, ins.config)  # type: ignore
              ^^^^^^^^^^^^^^^^^^^^^^^^^^^^^^^^^^^^^^^^^^^^^
  File "/home/abdenour/PycharmProjects/fl_with_flower/fedavg_mobilnet_poisoned/fedavg_mobilnet/client.py", line 46, in fit
    train(self.model, trainloader, optimizer, epochs=epochs, device=self.device)
  File "/home/abdenour/PycharmProjects/fl_with_flower/fedavg_mobilnet_poisoned/fedavg_mobilnet/utils.py", line 41, in train
    loss.backward()
  File "/home/abdenour/miniconda3/envs/fl_with_flower/lib/python3.11/site-packages/torch/_tensor.py", line 492, in backward
    torch.autograd.backward(
  File "/home/abdenour/miniconda3/envs/fl_with_flower/lib/python3.11/site-packages/torch/autograd/__init__.py", line 251, in backward
    Variable._execution_engine.run_backward(  # Calls into the C++ engine to run the backward pass
RuntimeError: cuDNN error: CUDNN_STATUS_INTERNAL_ERROR

The above exception was the direct cause of the following exception:

[36mray::ClientAppActor.run()[39m (pid=10227, ip=115.145.171.128, actor_id=4130a17356adc963491580af01000000, repr=<flwr.simulation.ray_transport.ray_actor.ClientAppActor object at 0x78fb9c17b350>)
           ^^^^^^^^^^^^^^^^^^^^^^^^^^^^^^^^^^^^
           ^^^^^^^^^^^^^^^^^^^^^^^^^^^^^^^
  File "/home/abdenour/miniconda3/envs/fl_with_flower/lib/python3.11/site-packages/flwr/simulation/ray_transport/ray_actor.py", line 63, in run
    raise ClientAppException(str(ex)) from ex
flwr.client.client_app.ClientAppException: 
Exception ClientAppException occurred. Message: cuDNN error: CUDNN_STATUS_INTERNAL_ERROR

[2024-09-10 13:55:13,827][flwr][ERROR] - [36mray::ClientAppActor.run()[39m (pid=10227, ip=115.145.171.128, actor_id=4130a17356adc963491580af01000000, repr=<flwr.simulation.ray_transport.ray_actor.ClientAppActor object at 0x78fb9c17b350>)
                  ^^^^^^^^^^^^^^^^^^^^^^^^^^^^^^^^^^^^^
  File "/home/abdenour/miniconda3/envs/fl_with_flower/lib/python3.11/site-packages/flwr/client/client_app.py", line 143, in __call__
    return self._call(message, context)
           ^^^^^^^^^^^^^^^^^^^^^^^^^^^^
  File "/home/abdenour/miniconda3/envs/fl_with_flower/lib/python3.11/site-packages/flwr/client/client_app.py", line 126, in ffn
    out_message = handle_legacy_message_from_msgtype(
                  ^^^^^^^^^^^^^^^^^^^^^^^^^^^^^^^^^^^
  File "/home/abdenour/miniconda3/envs/fl_with_flower/lib/python3.11/site-packages/flwr/client/message_handler/message_handler.py", line 129, in handle_legacy_message_from_msgtype
    fit_res = maybe_call_fit(
              ^^^^^^^^^^^^^^^
  File "/home/abdenour/miniconda3/envs/fl_with_flower/lib/python3.11/site-packages/flwr/client/client.py", line 234, in maybe_call_fit
    return client.fit(fit_ins)
           ^^^^^^^^^^^^^^^^^^^
  File "/home/abdenour/miniconda3/envs/fl_with_flower/lib/python3.11/site-packages/flwr/client/numpy_client.py", line 238, in _fit
    results = self.numpy_client.fit(parameters, ins.config)  # type: ignore
              ^^^^^^^^^^^^^^^^^^^^^^^^^^^^^^^^^^^^^^^^^^^^^
  File "/home/abdenour/PycharmProjects/fl_with_flower/fedavg_mobilnet_poisoned/fedavg_mobilnet/client.py", line 46, in fit
    train(self.model, trainloader, optimizer, epochs=epochs, device=self.device)
  File "/home/abdenour/PycharmProjects/fl_with_flower/fedavg_mobilnet_poisoned/fedavg_mobilnet/utils.py", line 41, in train
    loss.backward()
  File "/home/abdenour/miniconda3/envs/fl_with_flower/lib/python3.11/site-packages/torch/_tensor.py", line 492, in backward
    torch.autograd.backward(
  File "/home/abdenour/miniconda3/envs/fl_with_flower/lib/python3.11/site-packages/torch/autograd/__init__.py", line 251, in backward
    Variable._execution_engine.run_backward(  # Calls into the C++ engine to run the backward pass
RuntimeError: cuDNN error: CUDNN_STATUS_INTERNAL_ERROR

The above exception was the direct cause of the following exception:

[36mray::ClientAppActor.run()[39m (pid=10227, ip=115.145.171.128, actor_id=4130a17356adc963491580af01000000, repr=<flwr.simulation.ray_transport.ray_actor.ClientAppActor object at 0x78fb9c17b350>)
           ^^^^^^^^^^^^^^^^^^^^^^^^^^^^^^^^^^^^
           ^^^^^^^^^^^^^^^^^^^^^^^^^^^^^^^
  File "/home/abdenour/miniconda3/envs/fl_with_flower/lib/python3.11/site-packages/flwr/simulation/ray_transport/ray_actor.py", line 63, in run
    raise ClientAppException(str(ex)) from ex
flwr.client.client_app.ClientAppException: 
Exception ClientAppException occurred. Message: cuDNN error: CUDNN_STATUS_INTERNAL_ERROR
[2024-09-10 13:55:14,127][flwr][ERROR] - Traceback (most recent call last):
  File "/home/abdenour/miniconda3/envs/fl_with_flower/lib/python3.11/site-packages/flwr/simulation/ray_transport/ray_client_proxy.py", line 94, in _submit_job
    out_mssg, updated_context = self.actor_pool.get_client_result(
                                ^^^^^^^^^^^^^^^^^^^^^^^^^^^^^^^^^^
  File "/home/abdenour/miniconda3/envs/fl_with_flower/lib/python3.11/site-packages/flwr/simulation/ray_transport/ray_actor.py", line 398, in get_client_result
    return self._fetch_future_result(cid)
           ^^^^^^^^^^^^^^^^^^^^^^^^^^^^^^
  File "/home/abdenour/miniconda3/envs/fl_with_flower/lib/python3.11/site-packages/flwr/simulation/ray_transport/ray_actor.py", line 279, in _fetch_future_result
    res_cid, out_mssg, updated_context = ray.get(
                                         ^^^^^^^^
  File "/home/abdenour/miniconda3/envs/fl_with_flower/lib/python3.11/site-packages/ray/_private/auto_init_hook.py", line 21, in auto_init_wrapper
    return fn(*args, **kwargs)
           ^^^^^^^^^^^^^^^^^^^
  File "/home/abdenour/miniconda3/envs/fl_with_flower/lib/python3.11/site-packages/ray/_private/client_mode_hook.py", line 103, in wrapper
    return func(*args, **kwargs)
           ^^^^^^^^^^^^^^^^^^^^^
  File "/home/abdenour/miniconda3/envs/fl_with_flower/lib/python3.11/site-packages/ray/_private/worker.py", line 2667, in get
    values, debugger_breakpoint = worker.get_objects(object_refs, timeout=timeout)
                                  ^^^^^^^^^^^^^^^^^^^^^^^^^^^^^^^^^^^^^^^^^^^^^^^^
  File "/home/abdenour/miniconda3/envs/fl_with_flower/lib/python3.11/site-packages/ray/_private/worker.py", line 864, in get_objects
    raise value.as_instanceof_cause()
ray.exceptions.RayTaskError(ClientAppException): [36mray::ClientAppActor.run()[39m (pid=10227, ip=115.145.171.128, actor_id=4130a17356adc963491580af01000000, repr=<flwr.simulation.ray_transport.ray_actor.ClientAppActor object at 0x78fb9c17b350>)
                  ^^^^^^^^^^^^^^^^^^^^^^^^^^^^^^^^^^^^^
  File "/home/abdenour/miniconda3/envs/fl_with_flower/lib/python3.11/site-packages/flwr/client/client_app.py", line 143, in __call__
    return self._call(message, context)
           ^^^^^^^^^^^^^^^^^^^^^^^^^^^^
  File "/home/abdenour/miniconda3/envs/fl_with_flower/lib/python3.11/site-packages/flwr/client/client_app.py", line 126, in ffn
    out_message = handle_legacy_message_from_msgtype(
                  ^^^^^^^^^^^^^^^^^^^^^^^^^^^^^^^^^^^
  File "/home/abdenour/miniconda3/envs/fl_with_flower/lib/python3.11/site-packages/flwr/client/message_handler/message_handler.py", line 129, in handle_legacy_message_from_msgtype
    fit_res = maybe_call_fit(
              ^^^^^^^^^^^^^^^
  File "/home/abdenour/miniconda3/envs/fl_with_flower/lib/python3.11/site-packages/flwr/client/client.py", line 234, in maybe_call_fit
    return client.fit(fit_ins)
           ^^^^^^^^^^^^^^^^^^^
  File "/home/abdenour/miniconda3/envs/fl_with_flower/lib/python3.11/site-packages/flwr/client/numpy_client.py", line 238, in _fit
    results = self.numpy_client.fit(parameters, ins.config)  # type: ignore
              ^^^^^^^^^^^^^^^^^^^^^^^^^^^^^^^^^^^^^^^^^^^^^
  File "/home/abdenour/PycharmProjects/fl_with_flower/fedavg_mobilnet_poisoned/fedavg_mobilnet/client.py", line 46, in fit
    train(self.model, trainloader, optimizer, epochs=epochs, device=self.device)
  File "/home/abdenour/PycharmProjects/fl_with_flower/fedavg_mobilnet_poisoned/fedavg_mobilnet/utils.py", line 41, in train
    loss.backward()
  File "/home/abdenour/miniconda3/envs/fl_with_flower/lib/python3.11/site-packages/torch/_tensor.py", line 492, in backward
    torch.autograd.backward(
  File "/home/abdenour/miniconda3/envs/fl_with_flower/lib/python3.11/site-packages/torch/autograd/__init__.py", line 251, in backward
    Variable._execution_engine.run_backward(  # Calls into the C++ engine to run the backward pass
RuntimeError: cuDNN error: CUDNN_STATUS_INTERNAL_ERROR

The above exception was the direct cause of the following exception:

[36mray::ClientAppActor.run()[39m (pid=10227, ip=115.145.171.128, actor_id=4130a17356adc963491580af01000000, repr=<flwr.simulation.ray_transport.ray_actor.ClientAppActor object at 0x78fb9c17b350>)
           ^^^^^^^^^^^^^^^^^^^^^^^^^^^^^^^^^^^^
           ^^^^^^^^^^^^^^^^^^^^^^^^^^^^^^^
  File "/home/abdenour/miniconda3/envs/fl_with_flower/lib/python3.11/site-packages/flwr/simulation/ray_transport/ray_actor.py", line 63, in run
    raise ClientAppException(str(ex)) from ex
flwr.client.client_app.ClientAppException: 
Exception ClientAppException occurred. Message: cuDNN error: CUDNN_STATUS_INTERNAL_ERROR

[2024-09-10 13:55:14,127][flwr][ERROR] - [36mray::ClientAppActor.run()[39m (pid=10227, ip=115.145.171.128, actor_id=4130a17356adc963491580af01000000, repr=<flwr.simulation.ray_transport.ray_actor.ClientAppActor object at 0x78fb9c17b350>)
                  ^^^^^^^^^^^^^^^^^^^^^^^^^^^^^^^^^^^^^
  File "/home/abdenour/miniconda3/envs/fl_with_flower/lib/python3.11/site-packages/flwr/client/client_app.py", line 143, in __call__
    return self._call(message, context)
           ^^^^^^^^^^^^^^^^^^^^^^^^^^^^
  File "/home/abdenour/miniconda3/envs/fl_with_flower/lib/python3.11/site-packages/flwr/client/client_app.py", line 126, in ffn
    out_message = handle_legacy_message_from_msgtype(
                  ^^^^^^^^^^^^^^^^^^^^^^^^^^^^^^^^^^^
  File "/home/abdenour/miniconda3/envs/fl_with_flower/lib/python3.11/site-packages/flwr/client/message_handler/message_handler.py", line 129, in handle_legacy_message_from_msgtype
    fit_res = maybe_call_fit(
              ^^^^^^^^^^^^^^^
  File "/home/abdenour/miniconda3/envs/fl_with_flower/lib/python3.11/site-packages/flwr/client/client.py", line 234, in maybe_call_fit
    return client.fit(fit_ins)
           ^^^^^^^^^^^^^^^^^^^
  File "/home/abdenour/miniconda3/envs/fl_with_flower/lib/python3.11/site-packages/flwr/client/numpy_client.py", line 238, in _fit
    results = self.numpy_client.fit(parameters, ins.config)  # type: ignore
              ^^^^^^^^^^^^^^^^^^^^^^^^^^^^^^^^^^^^^^^^^^^^^
  File "/home/abdenour/PycharmProjects/fl_with_flower/fedavg_mobilnet_poisoned/fedavg_mobilnet/client.py", line 46, in fit
    train(self.model, trainloader, optimizer, epochs=epochs, device=self.device)
  File "/home/abdenour/PycharmProjects/fl_with_flower/fedavg_mobilnet_poisoned/fedavg_mobilnet/utils.py", line 41, in train
    loss.backward()
  File "/home/abdenour/miniconda3/envs/fl_with_flower/lib/python3.11/site-packages/torch/_tensor.py", line 492, in backward
    torch.autograd.backward(
  File "/home/abdenour/miniconda3/envs/fl_with_flower/lib/python3.11/site-packages/torch/autograd/__init__.py", line 251, in backward
    Variable._execution_engine.run_backward(  # Calls into the C++ engine to run the backward pass
RuntimeError: cuDNN error: CUDNN_STATUS_INTERNAL_ERROR

The above exception was the direct cause of the following exception:

[36mray::ClientAppActor.run()[39m (pid=10227, ip=115.145.171.128, actor_id=4130a17356adc963491580af01000000, repr=<flwr.simulation.ray_transport.ray_actor.ClientAppActor object at 0x78fb9c17b350>)
           ^^^^^^^^^^^^^^^^^^^^^^^^^^^^^^^^^^^^
           ^^^^^^^^^^^^^^^^^^^^^^^^^^^^^^^
  File "/home/abdenour/miniconda3/envs/fl_with_flower/lib/python3.11/site-packages/flwr/simulation/ray_transport/ray_actor.py", line 63, in run
    raise ClientAppException(str(ex)) from ex
flwr.client.client_app.ClientAppException: 
Exception ClientAppException occurred. Message: cuDNN error: CUDNN_STATUS_INTERNAL_ERROR
[2024-09-10 13:55:14,410][flwr][ERROR] - Traceback (most recent call last):
  File "/home/abdenour/miniconda3/envs/fl_with_flower/lib/python3.11/site-packages/flwr/simulation/ray_transport/ray_client_proxy.py", line 94, in _submit_job
    out_mssg, updated_context = self.actor_pool.get_client_result(
                                ^^^^^^^^^^^^^^^^^^^^^^^^^^^^^^^^^^
  File "/home/abdenour/miniconda3/envs/fl_with_flower/lib/python3.11/site-packages/flwr/simulation/ray_transport/ray_actor.py", line 398, in get_client_result
    return self._fetch_future_result(cid)
           ^^^^^^^^^^^^^^^^^^^^^^^^^^^^^^
  File "/home/abdenour/miniconda3/envs/fl_with_flower/lib/python3.11/site-packages/flwr/simulation/ray_transport/ray_actor.py", line 279, in _fetch_future_result
    res_cid, out_mssg, updated_context = ray.get(
                                         ^^^^^^^^
  File "/home/abdenour/miniconda3/envs/fl_with_flower/lib/python3.11/site-packages/ray/_private/auto_init_hook.py", line 21, in auto_init_wrapper
    return fn(*args, **kwargs)
           ^^^^^^^^^^^^^^^^^^^
  File "/home/abdenour/miniconda3/envs/fl_with_flower/lib/python3.11/site-packages/ray/_private/client_mode_hook.py", line 103, in wrapper
    return func(*args, **kwargs)
           ^^^^^^^^^^^^^^^^^^^^^
  File "/home/abdenour/miniconda3/envs/fl_with_flower/lib/python3.11/site-packages/ray/_private/worker.py", line 2667, in get
    values, debugger_breakpoint = worker.get_objects(object_refs, timeout=timeout)
                                  ^^^^^^^^^^^^^^^^^^^^^^^^^^^^^^^^^^^^^^^^^^^^^^^^
  File "/home/abdenour/miniconda3/envs/fl_with_flower/lib/python3.11/site-packages/ray/_private/worker.py", line 864, in get_objects
    raise value.as_instanceof_cause()
ray.exceptions.RayTaskError(ClientAppException): [36mray::ClientAppActor.run()[39m (pid=10227, ip=115.145.171.128, actor_id=4130a17356adc963491580af01000000, repr=<flwr.simulation.ray_transport.ray_actor.ClientAppActor object at 0x78fb9c17b350>)
                  ^^^^^^^^^^^^^^^^^^^^^^^^^^^^^^^^^^^^^
  File "/home/abdenour/miniconda3/envs/fl_with_flower/lib/python3.11/site-packages/flwr/client/client_app.py", line 143, in __call__
    return self._call(message, context)
           ^^^^^^^^^^^^^^^^^^^^^^^^^^^^
  File "/home/abdenour/miniconda3/envs/fl_with_flower/lib/python3.11/site-packages/flwr/client/client_app.py", line 126, in ffn
    out_message = handle_legacy_message_from_msgtype(
                  ^^^^^^^^^^^^^^^^^^^^^^^^^^^^^^^^^^^
  File "/home/abdenour/miniconda3/envs/fl_with_flower/lib/python3.11/site-packages/flwr/client/message_handler/message_handler.py", line 129, in handle_legacy_message_from_msgtype
    fit_res = maybe_call_fit(
              ^^^^^^^^^^^^^^^
  File "/home/abdenour/miniconda3/envs/fl_with_flower/lib/python3.11/site-packages/flwr/client/client.py", line 234, in maybe_call_fit
    return client.fit(fit_ins)
           ^^^^^^^^^^^^^^^^^^^
  File "/home/abdenour/miniconda3/envs/fl_with_flower/lib/python3.11/site-packages/flwr/client/numpy_client.py", line 238, in _fit
    results = self.numpy_client.fit(parameters, ins.config)  # type: ignore
              ^^^^^^^^^^^^^^^^^^^^^^^^^^^^^^^^^^^^^^^^^^^^^
  File "/home/abdenour/PycharmProjects/fl_with_flower/fedavg_mobilnet_poisoned/fedavg_mobilnet/client.py", line 46, in fit
    train(self.model, trainloader, optimizer, epochs=epochs, device=self.device)
  File "/home/abdenour/PycharmProjects/fl_with_flower/fedavg_mobilnet_poisoned/fedavg_mobilnet/utils.py", line 41, in train
    loss.backward()
  File "/home/abdenour/miniconda3/envs/fl_with_flower/lib/python3.11/site-packages/torch/_tensor.py", line 492, in backward
    torch.autograd.backward(
  File "/home/abdenour/miniconda3/envs/fl_with_flower/lib/python3.11/site-packages/torch/autograd/__init__.py", line 251, in backward
    Variable._execution_engine.run_backward(  # Calls into the C++ engine to run the backward pass
RuntimeError: cuDNN error: CUDNN_STATUS_INTERNAL_ERROR

The above exception was the direct cause of the following exception:

[36mray::ClientAppActor.run()[39m (pid=10227, ip=115.145.171.128, actor_id=4130a17356adc963491580af01000000, repr=<flwr.simulation.ray_transport.ray_actor.ClientAppActor object at 0x78fb9c17b350>)
           ^^^^^^^^^^^^^^^^^^^^^^^^^^^^^^^^^^^^
           ^^^^^^^^^^^^^^^^^^^^^^^^^^^^^^^
  File "/home/abdenour/miniconda3/envs/fl_with_flower/lib/python3.11/site-packages/flwr/simulation/ray_transport/ray_actor.py", line 63, in run
    raise ClientAppException(str(ex)) from ex
flwr.client.client_app.ClientAppException: 
Exception ClientAppException occurred. Message: cuDNN error: CUDNN_STATUS_INTERNAL_ERROR

[2024-09-10 13:55:14,410][flwr][ERROR] - [36mray::ClientAppActor.run()[39m (pid=10227, ip=115.145.171.128, actor_id=4130a17356adc963491580af01000000, repr=<flwr.simulation.ray_transport.ray_actor.ClientAppActor object at 0x78fb9c17b350>)
                  ^^^^^^^^^^^^^^^^^^^^^^^^^^^^^^^^^^^^^
  File "/home/abdenour/miniconda3/envs/fl_with_flower/lib/python3.11/site-packages/flwr/client/client_app.py", line 143, in __call__
    return self._call(message, context)
           ^^^^^^^^^^^^^^^^^^^^^^^^^^^^
  File "/home/abdenour/miniconda3/envs/fl_with_flower/lib/python3.11/site-packages/flwr/client/client_app.py", line 126, in ffn
    out_message = handle_legacy_message_from_msgtype(
                  ^^^^^^^^^^^^^^^^^^^^^^^^^^^^^^^^^^^
  File "/home/abdenour/miniconda3/envs/fl_with_flower/lib/python3.11/site-packages/flwr/client/message_handler/message_handler.py", line 129, in handle_legacy_message_from_msgtype
    fit_res = maybe_call_fit(
              ^^^^^^^^^^^^^^^
  File "/home/abdenour/miniconda3/envs/fl_with_flower/lib/python3.11/site-packages/flwr/client/client.py", line 234, in maybe_call_fit
    return client.fit(fit_ins)
           ^^^^^^^^^^^^^^^^^^^
  File "/home/abdenour/miniconda3/envs/fl_with_flower/lib/python3.11/site-packages/flwr/client/numpy_client.py", line 238, in _fit
    results = self.numpy_client.fit(parameters, ins.config)  # type: ignore
              ^^^^^^^^^^^^^^^^^^^^^^^^^^^^^^^^^^^^^^^^^^^^^
  File "/home/abdenour/PycharmProjects/fl_with_flower/fedavg_mobilnet_poisoned/fedavg_mobilnet/client.py", line 46, in fit
    train(self.model, trainloader, optimizer, epochs=epochs, device=self.device)
  File "/home/abdenour/PycharmProjects/fl_with_flower/fedavg_mobilnet_poisoned/fedavg_mobilnet/utils.py", line 41, in train
    loss.backward()
  File "/home/abdenour/miniconda3/envs/fl_with_flower/lib/python3.11/site-packages/torch/_tensor.py", line 492, in backward
    torch.autograd.backward(
  File "/home/abdenour/miniconda3/envs/fl_with_flower/lib/python3.11/site-packages/torch/autograd/__init__.py", line 251, in backward
    Variable._execution_engine.run_backward(  # Calls into the C++ engine to run the backward pass
RuntimeError: cuDNN error: CUDNN_STATUS_INTERNAL_ERROR

The above exception was the direct cause of the following exception:

[36mray::ClientAppActor.run()[39m (pid=10227, ip=115.145.171.128, actor_id=4130a17356adc963491580af01000000, repr=<flwr.simulation.ray_transport.ray_actor.ClientAppActor object at 0x78fb9c17b350>)
           ^^^^^^^^^^^^^^^^^^^^^^^^^^^^^^^^^^^^
           ^^^^^^^^^^^^^^^^^^^^^^^^^^^^^^^
  File "/home/abdenour/miniconda3/envs/fl_with_flower/lib/python3.11/site-packages/flwr/simulation/ray_transport/ray_actor.py", line 63, in run
    raise ClientAppException(str(ex)) from ex
flwr.client.client_app.ClientAppException: 
Exception ClientAppException occurred. Message: cuDNN error: CUDNN_STATUS_INTERNAL_ERROR
[2024-09-10 13:55:14,796][flwr][ERROR] - Traceback (most recent call last):
  File "/home/abdenour/miniconda3/envs/fl_with_flower/lib/python3.11/site-packages/flwr/simulation/ray_transport/ray_client_proxy.py", line 94, in _submit_job
    out_mssg, updated_context = self.actor_pool.get_client_result(
                                ^^^^^^^^^^^^^^^^^^^^^^^^^^^^^^^^^^
  File "/home/abdenour/miniconda3/envs/fl_with_flower/lib/python3.11/site-packages/flwr/simulation/ray_transport/ray_actor.py", line 398, in get_client_result
    return self._fetch_future_result(cid)
           ^^^^^^^^^^^^^^^^^^^^^^^^^^^^^^
  File "/home/abdenour/miniconda3/envs/fl_with_flower/lib/python3.11/site-packages/flwr/simulation/ray_transport/ray_actor.py", line 279, in _fetch_future_result
    res_cid, out_mssg, updated_context = ray.get(
                                         ^^^^^^^^
  File "/home/abdenour/miniconda3/envs/fl_with_flower/lib/python3.11/site-packages/ray/_private/auto_init_hook.py", line 21, in auto_init_wrapper
    return fn(*args, **kwargs)
           ^^^^^^^^^^^^^^^^^^^
  File "/home/abdenour/miniconda3/envs/fl_with_flower/lib/python3.11/site-packages/ray/_private/client_mode_hook.py", line 103, in wrapper
    return func(*args, **kwargs)
           ^^^^^^^^^^^^^^^^^^^^^
  File "/home/abdenour/miniconda3/envs/fl_with_flower/lib/python3.11/site-packages/ray/_private/worker.py", line 2667, in get
    values, debugger_breakpoint = worker.get_objects(object_refs, timeout=timeout)
                                  ^^^^^^^^^^^^^^^^^^^^^^^^^^^^^^^^^^^^^^^^^^^^^^^^
  File "/home/abdenour/miniconda3/envs/fl_with_flower/lib/python3.11/site-packages/ray/_private/worker.py", line 864, in get_objects
    raise value.as_instanceof_cause()
ray.exceptions.RayTaskError(ClientAppException): [36mray::ClientAppActor.run()[39m (pid=10227, ip=115.145.171.128, actor_id=4130a17356adc963491580af01000000, repr=<flwr.simulation.ray_transport.ray_actor.ClientAppActor object at 0x78fb9c17b350>)
                  ^^^^^^^^^^^^^^^^^^^^^^^^^^^^^^^^^^^^^
  File "/home/abdenour/miniconda3/envs/fl_with_flower/lib/python3.11/site-packages/flwr/client/client_app.py", line 143, in __call__
    return self._call(message, context)
           ^^^^^^^^^^^^^^^^^^^^^^^^^^^^
  File "/home/abdenour/miniconda3/envs/fl_with_flower/lib/python3.11/site-packages/flwr/client/client_app.py", line 126, in ffn
    out_message = handle_legacy_message_from_msgtype(
                  ^^^^^^^^^^^^^^^^^^^^^^^^^^^^^^^^^^^
  File "/home/abdenour/miniconda3/envs/fl_with_flower/lib/python3.11/site-packages/flwr/client/message_handler/message_handler.py", line 129, in handle_legacy_message_from_msgtype
    fit_res = maybe_call_fit(
              ^^^^^^^^^^^^^^^
  File "/home/abdenour/miniconda3/envs/fl_with_flower/lib/python3.11/site-packages/flwr/client/client.py", line 234, in maybe_call_fit
    return client.fit(fit_ins)
           ^^^^^^^^^^^^^^^^^^^
  File "/home/abdenour/miniconda3/envs/fl_with_flower/lib/python3.11/site-packages/flwr/client/numpy_client.py", line 238, in _fit
    results = self.numpy_client.fit(parameters, ins.config)  # type: ignore
              ^^^^^^^^^^^^^^^^^^^^^^^^^^^^^^^^^^^^^^^^^^^^^
  File "/home/abdenour/PycharmProjects/fl_with_flower/fedavg_mobilnet_poisoned/fedavg_mobilnet/client.py", line 46, in fit
    train(self.model, trainloader, optimizer, epochs=epochs, device=self.device)
  File "/home/abdenour/PycharmProjects/fl_with_flower/fedavg_mobilnet_poisoned/fedavg_mobilnet/utils.py", line 41, in train
    loss.backward()
  File "/home/abdenour/miniconda3/envs/fl_with_flower/lib/python3.11/site-packages/torch/_tensor.py", line 492, in backward
    torch.autograd.backward(
  File "/home/abdenour/miniconda3/envs/fl_with_flower/lib/python3.11/site-packages/torch/autograd/__init__.py", line 251, in backward
    Variable._execution_engine.run_backward(  # Calls into the C++ engine to run the backward pass
RuntimeError: cuDNN error: CUDNN_STATUS_INTERNAL_ERROR

The above exception was the direct cause of the following exception:

[36mray::ClientAppActor.run()[39m (pid=10227, ip=115.145.171.128, actor_id=4130a17356adc963491580af01000000, repr=<flwr.simulation.ray_transport.ray_actor.ClientAppActor object at 0x78fb9c17b350>)
           ^^^^^^^^^^^^^^^^^^^^^^^^^^^^^^^^^^^^
           ^^^^^^^^^^^^^^^^^^^^^^^^^^^^^^^
  File "/home/abdenour/miniconda3/envs/fl_with_flower/lib/python3.11/site-packages/flwr/simulation/ray_transport/ray_actor.py", line 63, in run
    raise ClientAppException(str(ex)) from ex
flwr.client.client_app.ClientAppException: 
Exception ClientAppException occurred. Message: cuDNN error: CUDNN_STATUS_INTERNAL_ERROR

[2024-09-10 13:55:14,796][flwr][ERROR] - [36mray::ClientAppActor.run()[39m (pid=10227, ip=115.145.171.128, actor_id=4130a17356adc963491580af01000000, repr=<flwr.simulation.ray_transport.ray_actor.ClientAppActor object at 0x78fb9c17b350>)
                  ^^^^^^^^^^^^^^^^^^^^^^^^^^^^^^^^^^^^^
  File "/home/abdenour/miniconda3/envs/fl_with_flower/lib/python3.11/site-packages/flwr/client/client_app.py", line 143, in __call__
    return self._call(message, context)
           ^^^^^^^^^^^^^^^^^^^^^^^^^^^^
  File "/home/abdenour/miniconda3/envs/fl_with_flower/lib/python3.11/site-packages/flwr/client/client_app.py", line 126, in ffn
    out_message = handle_legacy_message_from_msgtype(
                  ^^^^^^^^^^^^^^^^^^^^^^^^^^^^^^^^^^^
  File "/home/abdenour/miniconda3/envs/fl_with_flower/lib/python3.11/site-packages/flwr/client/message_handler/message_handler.py", line 129, in handle_legacy_message_from_msgtype
    fit_res = maybe_call_fit(
              ^^^^^^^^^^^^^^^
  File "/home/abdenour/miniconda3/envs/fl_with_flower/lib/python3.11/site-packages/flwr/client/client.py", line 234, in maybe_call_fit
    return client.fit(fit_ins)
           ^^^^^^^^^^^^^^^^^^^
  File "/home/abdenour/miniconda3/envs/fl_with_flower/lib/python3.11/site-packages/flwr/client/numpy_client.py", line 238, in _fit
    results = self.numpy_client.fit(parameters, ins.config)  # type: ignore
              ^^^^^^^^^^^^^^^^^^^^^^^^^^^^^^^^^^^^^^^^^^^^^
  File "/home/abdenour/PycharmProjects/fl_with_flower/fedavg_mobilnet_poisoned/fedavg_mobilnet/client.py", line 46, in fit
    train(self.model, trainloader, optimizer, epochs=epochs, device=self.device)
  File "/home/abdenour/PycharmProjects/fl_with_flower/fedavg_mobilnet_poisoned/fedavg_mobilnet/utils.py", line 41, in train
    loss.backward()
  File "/home/abdenour/miniconda3/envs/fl_with_flower/lib/python3.11/site-packages/torch/_tensor.py", line 492, in backward
    torch.autograd.backward(
  File "/home/abdenour/miniconda3/envs/fl_with_flower/lib/python3.11/site-packages/torch/autograd/__init__.py", line 251, in backward
    Variable._execution_engine.run_backward(  # Calls into the C++ engine to run the backward pass
RuntimeError: cuDNN error: CUDNN_STATUS_INTERNAL_ERROR

The above exception was the direct cause of the following exception:

[36mray::ClientAppActor.run()[39m (pid=10227, ip=115.145.171.128, actor_id=4130a17356adc963491580af01000000, repr=<flwr.simulation.ray_transport.ray_actor.ClientAppActor object at 0x78fb9c17b350>)
           ^^^^^^^^^^^^^^^^^^^^^^^^^^^^^^^^^^^^
           ^^^^^^^^^^^^^^^^^^^^^^^^^^^^^^^
  File "/home/abdenour/miniconda3/envs/fl_with_flower/lib/python3.11/site-packages/flwr/simulation/ray_transport/ray_actor.py", line 63, in run
    raise ClientAppException(str(ex)) from ex
flwr.client.client_app.ClientAppException: 
Exception ClientAppException occurred. Message: cuDNN error: CUDNN_STATUS_INTERNAL_ERROR
[2024-09-10 13:55:14,797][flwr][INFO] - aggregate_fit: received 1 results and 4 failures
