[2024-09-19 01:27:10,303][flwr][INFO] - Starting Flower simulation, config: num_rounds=100, no round_timeout
[2024-09-19 01:27:13,657][flwr][INFO] - Flower VCE: Ray initialized with resources: {'GPU': 1.0, 'accelerator_type:G': 1.0, 'node:__internal_head__': 1.0, 'memory': 147276611789.0, 'CPU': 256.0, 'node:115.145.172.224': 1.0, 'object_store_memory': 67404262195.0}
[2024-09-19 01:27:13,657][flwr][INFO] - Optimize your simulation with Flower VCE: https://flower.ai/docs/framework/how-to-run-simulations.html
[2024-09-19 01:27:13,657][flwr][INFO] - Flower VCE: Resources for each Virtual Client: {'num_cpus': 64, 'num_gpus': 0.1}
[2024-09-19 01:27:13,669][flwr][INFO] - Flower VCE: Creating VirtualClientEngineActorPool with 4 actors
[2024-09-19 01:27:13,670][flwr][INFO] - [INIT]
[2024-09-19 01:27:13,670][flwr][INFO] - Requesting initial parameters from one random client
[2024-09-19 01:27:21,262][flwr][INFO] - Received initial parameters from one random client
[2024-09-19 01:27:21,262][flwr][INFO] - Evaluating initial global parameters
[2024-09-19 01:27:35,083][flwr][INFO] - initial parameters (loss, other metrics): 223.07366704940796, {'accuracy': 0.08973984215141771}
[2024-09-19 01:27:35,085][flwr][INFO] - 
[2024-09-19 01:27:35,085][flwr][INFO] - [ROUND 1]
[2024-09-19 01:27:35,086][flwr][INFO] - configure_fit: strategy sampled 5 clients (out of 50)
[2024-09-19 01:27:44,951][flwr][ERROR] - Traceback (most recent call last):
  File "/home/abdenour/.local/lib/python3.10/site-packages/flwr/simulation/ray_transport/ray_client_proxy.py", line 94, in _submit_job
    out_mssg, updated_context = self.actor_pool.get_client_result(
  File "/home/abdenour/.local/lib/python3.10/site-packages/flwr/simulation/ray_transport/ray_actor.py", line 398, in get_client_result
    return self._fetch_future_result(cid)
  File "/home/abdenour/.local/lib/python3.10/site-packages/flwr/simulation/ray_transport/ray_actor.py", line 279, in _fetch_future_result
    res_cid, out_mssg, updated_context = ray.get(
  File "/home/abdenour/.local/lib/python3.10/site-packages/ray/_private/auto_init_hook.py", line 21, in auto_init_wrapper
    return fn(*args, **kwargs)
  File "/home/abdenour/.local/lib/python3.10/site-packages/ray/_private/client_mode_hook.py", line 103, in wrapper
    return func(*args, **kwargs)
  File "/home/abdenour/.local/lib/python3.10/site-packages/ray/_private/worker.py", line 2667, in get
    values, debugger_breakpoint = worker.get_objects(object_refs, timeout=timeout)
  File "/home/abdenour/.local/lib/python3.10/site-packages/ray/_private/worker.py", line 864, in get_objects
    raise value.as_instanceof_cause()
ray.exceptions.RayTaskError(ClientAppException): [36mray::ClientAppActor.run()[39m (pid=2362922, ip=115.145.172.224, actor_id=b553081c8efb20e91541068301000000, repr=<flwr.simulation.ray_transport.ray_actor.ClientAppActor object at 0x7f8ea0279750>)
  File "/home/abdenour/.local/lib/python3.10/site-packages/flwr/client/client_app.py", line 143, in __call__
    return self._call(message, context)
  File "/home/abdenour/.local/lib/python3.10/site-packages/flwr/client/client_app.py", line 126, in ffn
    out_message = handle_legacy_message_from_msgtype(
  File "/home/abdenour/.local/lib/python3.10/site-packages/flwr/client/message_handler/message_handler.py", line 95, in handle_legacy_message_from_msgtype
    client = client_fn(context)
  File "/home/abdenour/fl_with_flower/fednova_vgg16/fednova_vgg16/client.py", line 129, in client_fn
    return FlowerClient(trainset, valset, num_classes, config_fit, client_dataset_ratio, context.node_config).to_client()
  File "/home/abdenour/fl_with_flower/fednova_vgg16/fednova_vgg16/client.py", line 36, in __init__
    self.model = self.model.to(self.device)
  File "/home/abdenour/anaconda3/envs/fl/lib/python3.10/site-packages/torch/nn/modules/module.py", line 1174, in to
    return self._apply(convert)
  File "/home/abdenour/anaconda3/envs/fl/lib/python3.10/site-packages/torch/nn/modules/module.py", line 780, in _apply
    module._apply(fn)
  File "/home/abdenour/anaconda3/envs/fl/lib/python3.10/site-packages/torch/nn/modules/module.py", line 780, in _apply
    module._apply(fn)
  File "/home/abdenour/anaconda3/envs/fl/lib/python3.10/site-packages/torch/nn/modules/module.py", line 805, in _apply
    param_applied = fn(param)
  File "/home/abdenour/anaconda3/envs/fl/lib/python3.10/site-packages/torch/nn/modules/module.py", line 1160, in convert
    return t.to(
torch.OutOfMemoryError: CUDA out of memory. Tried to allocate 392.00 MiB. GPU 0 has a total capacity of 47.33 GiB of which 44.81 MiB is free. Process 2279413 has 11.11 GiB memory in use. Process 2265701 has 2.37 GiB memory in use. Process 2279412 has 11.11 GiB memory in use. Process 2362925 has 11.11 GiB memory in use. Process 2349203 has 2.37 GiB memory in use. Process 2362924 has 8.04 GiB memory in use. Process 2362923 has 816.00 MiB memory in use. Including non-PyTorch memory, this process has 322.00 MiB memory in use. Of the allocated memory 57.01 MiB is allocated by PyTorch, and 4.99 MiB is reserved by PyTorch but unallocated. If reserved but unallocated memory is large try setting PYTORCH_CUDA_ALLOC_CONF=expandable_segments:True to avoid fragmentation.  See documentation for Memory Management  (https://pytorch.org/docs/stable/notes/cuda.html#environment-variables)

The above exception was the direct cause of the following exception:

[36mray::ClientAppActor.run()[39m (pid=2362922, ip=115.145.172.224, actor_id=b553081c8efb20e91541068301000000, repr=<flwr.simulation.ray_transport.ray_actor.ClientAppActor object at 0x7f8ea0279750>)
  File "/home/abdenour/.local/lib/python3.10/site-packages/flwr/simulation/ray_transport/ray_actor.py", line 63, in run
    raise ClientAppException(str(ex)) from ex
flwr.client.client_app.ClientAppException: 
Exception ClientAppException occurred. Message: CUDA out of memory. Tried to allocate 392.00 MiB. GPU 0 has a total capacity of 47.33 GiB of which 44.81 MiB is free. Process 2279413 has 11.11 GiB memory in use. Process 2265701 has 2.37 GiB memory in use. Process 2279412 has 11.11 GiB memory in use. Process 2362925 has 11.11 GiB memory in use. Process 2349203 has 2.37 GiB memory in use. Process 2362924 has 8.04 GiB memory in use. Process 2362923 has 816.00 MiB memory in use. Including non-PyTorch memory, this process has 322.00 MiB memory in use. Of the allocated memory 57.01 MiB is allocated by PyTorch, and 4.99 MiB is reserved by PyTorch but unallocated. If reserved but unallocated memory is large try setting PYTORCH_CUDA_ALLOC_CONF=expandable_segments:True to avoid fragmentation.  See documentation for Memory Management  (https://pytorch.org/docs/stable/notes/cuda.html#environment-variables)

[2024-09-19 01:27:44,952][flwr][ERROR] - Traceback (most recent call last):
  File "/home/abdenour/.local/lib/python3.10/site-packages/flwr/simulation/ray_transport/ray_client_proxy.py", line 94, in _submit_job
    out_mssg, updated_context = self.actor_pool.get_client_result(
  File "/home/abdenour/.local/lib/python3.10/site-packages/flwr/simulation/ray_transport/ray_actor.py", line 398, in get_client_result
    return self._fetch_future_result(cid)
  File "/home/abdenour/.local/lib/python3.10/site-packages/flwr/simulation/ray_transport/ray_actor.py", line 279, in _fetch_future_result
    res_cid, out_mssg, updated_context = ray.get(
  File "/home/abdenour/.local/lib/python3.10/site-packages/ray/_private/auto_init_hook.py", line 21, in auto_init_wrapper
    return fn(*args, **kwargs)
  File "/home/abdenour/.local/lib/python3.10/site-packages/ray/_private/client_mode_hook.py", line 103, in wrapper
    return func(*args, **kwargs)
  File "/home/abdenour/.local/lib/python3.10/site-packages/ray/_private/worker.py", line 2667, in get
    values, debugger_breakpoint = worker.get_objects(object_refs, timeout=timeout)
  File "/home/abdenour/.local/lib/python3.10/site-packages/ray/_private/worker.py", line 864, in get_objects
    raise value.as_instanceof_cause()
ray.exceptions.RayTaskError(ClientAppException): [36mray::ClientAppActor.run()[39m (pid=2362923, ip=115.145.172.224, actor_id=191f38ecb8e72eee5122ddd001000000, repr=<flwr.simulation.ray_transport.ray_actor.ClientAppActor object at 0x7f2c5008d720>)
  File "/home/abdenour/.local/lib/python3.10/site-packages/flwr/client/client_app.py", line 143, in __call__
    return self._call(message, context)
  File "/home/abdenour/.local/lib/python3.10/site-packages/flwr/client/client_app.py", line 126, in ffn
    out_message = handle_legacy_message_from_msgtype(
  File "/home/abdenour/.local/lib/python3.10/site-packages/flwr/client/message_handler/message_handler.py", line 129, in handle_legacy_message_from_msgtype
    fit_res = maybe_call_fit(
  File "/home/abdenour/.local/lib/python3.10/site-packages/flwr/client/client.py", line 234, in maybe_call_fit
    return client.fit(fit_ins)
  File "/home/abdenour/.local/lib/python3.10/site-packages/flwr/client/numpy_client.py", line 238, in _fit
    results = self.numpy_client.fit(parameters, ins.config)  # type: ignore
  File "/home/abdenour/fl_with_flower/fednova_vgg16/fednova_vgg16/client.py", line 69, in fit
    train(self.model, trainloader, self.optimizer, epochs=num_epochs, device=self.device)
  File "/home/abdenour/fl_with_flower/fednova_vgg16/fednova_vgg16/utils.py", line 57, in train
    loss = criterion(net(images), labels)
  File "/home/abdenour/anaconda3/envs/fl/lib/python3.10/site-packages/torch/nn/modules/module.py", line 1553, in _wrapped_call_impl
    return self._call_impl(*args, **kwargs)
  File "/home/abdenour/anaconda3/envs/fl/lib/python3.10/site-packages/torch/nn/modules/module.py", line 1562, in _call_impl
    return forward_call(*args, **kwargs)
  File "/home/abdenour/anaconda3/envs/fl/lib/python3.10/site-packages/torchvision/models/vgg.py", line 66, in forward
    x = self.features(x)
  File "/home/abdenour/anaconda3/envs/fl/lib/python3.10/site-packages/torch/nn/modules/module.py", line 1553, in _wrapped_call_impl
    return self._call_impl(*args, **kwargs)
  File "/home/abdenour/anaconda3/envs/fl/lib/python3.10/site-packages/torch/nn/modules/module.py", line 1562, in _call_impl
    return forward_call(*args, **kwargs)
  File "/home/abdenour/anaconda3/envs/fl/lib/python3.10/site-packages/torch/nn/modules/container.py", line 219, in forward
    input = module(input)
  File "/home/abdenour/anaconda3/envs/fl/lib/python3.10/site-packages/torch/nn/modules/module.py", line 1553, in _wrapped_call_impl
    return self._call_impl(*args, **kwargs)
  File "/home/abdenour/anaconda3/envs/fl/lib/python3.10/site-packages/torch/nn/modules/module.py", line 1562, in _call_impl
    return forward_call(*args, **kwargs)
  File "/home/abdenour/anaconda3/envs/fl/lib/python3.10/site-packages/torch/nn/modules/conv.py", line 458, in forward
    return self._conv_forward(input, self.weight, self.bias)
  File "/home/abdenour/anaconda3/envs/fl/lib/python3.10/site-packages/torch/nn/modules/conv.py", line 454, in _conv_forward
    return F.conv2d(input, weight, bias, self.stride,
torch.OutOfMemoryError: CUDA out of memory. Tried to allocate 784.00 MiB. GPU 0 has a total capacity of 47.33 GiB of which 44.81 MiB is free. Process 2279413 has 11.11 GiB memory in use. Process 2265701 has 2.37 GiB memory in use. Process 2279412 has 11.11 GiB memory in use. Process 2362925 has 11.11 GiB memory in use. Process 2349203 has 2.37 GiB memory in use. Process 2362924 has 8.04 GiB memory in use. Including non-PyTorch memory, this process has 816.00 MiB memory in use. Process 2362922 has 322.00 MiB memory in use. Of the allocated memory 549.92 MiB is allocated by PyTorch, and 6.08 MiB is reserved by PyTorch but unallocated. If reserved but unallocated memory is large try setting PYTORCH_CUDA_ALLOC_CONF=expandable_segments:True to avoid fragmentation.  See documentation for Memory Management  (https://pytorch.org/docs/stable/notes/cuda.html#environment-variables)

The above exception was the direct cause of the following exception:

[36mray::ClientAppActor.run()[39m (pid=2362923, ip=115.145.172.224, actor_id=191f38ecb8e72eee5122ddd001000000, repr=<flwr.simulation.ray_transport.ray_actor.ClientAppActor object at 0x7f2c5008d720>)
  File "/home/abdenour/.local/lib/python3.10/site-packages/flwr/simulation/ray_transport/ray_actor.py", line 63, in run
    raise ClientAppException(str(ex)) from ex
flwr.client.client_app.ClientAppException: 
Exception ClientAppException occurred. Message: CUDA out of memory. Tried to allocate 784.00 MiB. GPU 0 has a total capacity of 47.33 GiB of which 44.81 MiB is free. Process 2279413 has 11.11 GiB memory in use. Process 2265701 has 2.37 GiB memory in use. Process 2279412 has 11.11 GiB memory in use. Process 2362925 has 11.11 GiB memory in use. Process 2349203 has 2.37 GiB memory in use. Process 2362924 has 8.04 GiB memory in use. Including non-PyTorch memory, this process has 816.00 MiB memory in use. Process 2362922 has 322.00 MiB memory in use. Of the allocated memory 549.92 MiB is allocated by PyTorch, and 6.08 MiB is reserved by PyTorch but unallocated. If reserved but unallocated memory is large try setting PYTORCH_CUDA_ALLOC_CONF=expandable_segments:True to avoid fragmentation.  See documentation for Memory Management  (https://pytorch.org/docs/stable/notes/cuda.html#environment-variables)

[2024-09-19 01:27:44,952][flwr][ERROR] - [36mray::ClientAppActor.run()[39m (pid=2362922, ip=115.145.172.224, actor_id=b553081c8efb20e91541068301000000, repr=<flwr.simulation.ray_transport.ray_actor.ClientAppActor object at 0x7f8ea0279750>)
  File "/home/abdenour/.local/lib/python3.10/site-packages/flwr/client/client_app.py", line 143, in __call__
    return self._call(message, context)
  File "/home/abdenour/.local/lib/python3.10/site-packages/flwr/client/client_app.py", line 126, in ffn
    out_message = handle_legacy_message_from_msgtype(
  File "/home/abdenour/.local/lib/python3.10/site-packages/flwr/client/message_handler/message_handler.py", line 95, in handle_legacy_message_from_msgtype
    client = client_fn(context)
  File "/home/abdenour/fl_with_flower/fednova_vgg16/fednova_vgg16/client.py", line 129, in client_fn
    return FlowerClient(trainset, valset, num_classes, config_fit, client_dataset_ratio, context.node_config).to_client()
  File "/home/abdenour/fl_with_flower/fednova_vgg16/fednova_vgg16/client.py", line 36, in __init__
    self.model = self.model.to(self.device)
  File "/home/abdenour/anaconda3/envs/fl/lib/python3.10/site-packages/torch/nn/modules/module.py", line 1174, in to
    return self._apply(convert)
  File "/home/abdenour/anaconda3/envs/fl/lib/python3.10/site-packages/torch/nn/modules/module.py", line 780, in _apply
    module._apply(fn)
  File "/home/abdenour/anaconda3/envs/fl/lib/python3.10/site-packages/torch/nn/modules/module.py", line 780, in _apply
    module._apply(fn)
  File "/home/abdenour/anaconda3/envs/fl/lib/python3.10/site-packages/torch/nn/modules/module.py", line 805, in _apply
    param_applied = fn(param)
  File "/home/abdenour/anaconda3/envs/fl/lib/python3.10/site-packages/torch/nn/modules/module.py", line 1160, in convert
    return t.to(
torch.OutOfMemoryError: CUDA out of memory. Tried to allocate 392.00 MiB. GPU 0 has a total capacity of 47.33 GiB of which 44.81 MiB is free. Process 2279413 has 11.11 GiB memory in use. Process 2265701 has 2.37 GiB memory in use. Process 2279412 has 11.11 GiB memory in use. Process 2362925 has 11.11 GiB memory in use. Process 2349203 has 2.37 GiB memory in use. Process 2362924 has 8.04 GiB memory in use. Process 2362923 has 816.00 MiB memory in use. Including non-PyTorch memory, this process has 322.00 MiB memory in use. Of the allocated memory 57.01 MiB is allocated by PyTorch, and 4.99 MiB is reserved by PyTorch but unallocated. If reserved but unallocated memory is large try setting PYTORCH_CUDA_ALLOC_CONF=expandable_segments:True to avoid fragmentation.  See documentation for Memory Management  (https://pytorch.org/docs/stable/notes/cuda.html#environment-variables)

The above exception was the direct cause of the following exception:

[36mray::ClientAppActor.run()[39m (pid=2362922, ip=115.145.172.224, actor_id=b553081c8efb20e91541068301000000, repr=<flwr.simulation.ray_transport.ray_actor.ClientAppActor object at 0x7f8ea0279750>)
  File "/home/abdenour/.local/lib/python3.10/site-packages/flwr/simulation/ray_transport/ray_actor.py", line 63, in run
    raise ClientAppException(str(ex)) from ex
flwr.client.client_app.ClientAppException: 
Exception ClientAppException occurred. Message: CUDA out of memory. Tried to allocate 392.00 MiB. GPU 0 has a total capacity of 47.33 GiB of which 44.81 MiB is free. Process 2279413 has 11.11 GiB memory in use. Process 2265701 has 2.37 GiB memory in use. Process 2279412 has 11.11 GiB memory in use. Process 2362925 has 11.11 GiB memory in use. Process 2349203 has 2.37 GiB memory in use. Process 2362924 has 8.04 GiB memory in use. Process 2362923 has 816.00 MiB memory in use. Including non-PyTorch memory, this process has 322.00 MiB memory in use. Of the allocated memory 57.01 MiB is allocated by PyTorch, and 4.99 MiB is reserved by PyTorch but unallocated. If reserved but unallocated memory is large try setting PYTORCH_CUDA_ALLOC_CONF=expandable_segments:True to avoid fragmentation.  See documentation for Memory Management  (https://pytorch.org/docs/stable/notes/cuda.html#environment-variables)
[2024-09-19 01:27:44,952][flwr][ERROR] - [36mray::ClientAppActor.run()[39m (pid=2362923, ip=115.145.172.224, actor_id=191f38ecb8e72eee5122ddd001000000, repr=<flwr.simulation.ray_transport.ray_actor.ClientAppActor object at 0x7f2c5008d720>)
  File "/home/abdenour/.local/lib/python3.10/site-packages/flwr/client/client_app.py", line 143, in __call__
    return self._call(message, context)
  File "/home/abdenour/.local/lib/python3.10/site-packages/flwr/client/client_app.py", line 126, in ffn
    out_message = handle_legacy_message_from_msgtype(
  File "/home/abdenour/.local/lib/python3.10/site-packages/flwr/client/message_handler/message_handler.py", line 129, in handle_legacy_message_from_msgtype
    fit_res = maybe_call_fit(
  File "/home/abdenour/.local/lib/python3.10/site-packages/flwr/client/client.py", line 234, in maybe_call_fit
    return client.fit(fit_ins)
  File "/home/abdenour/.local/lib/python3.10/site-packages/flwr/client/numpy_client.py", line 238, in _fit
    results = self.numpy_client.fit(parameters, ins.config)  # type: ignore
  File "/home/abdenour/fl_with_flower/fednova_vgg16/fednova_vgg16/client.py", line 69, in fit
    train(self.model, trainloader, self.optimizer, epochs=num_epochs, device=self.device)
  File "/home/abdenour/fl_with_flower/fednova_vgg16/fednova_vgg16/utils.py", line 57, in train
    loss = criterion(net(images), labels)
  File "/home/abdenour/anaconda3/envs/fl/lib/python3.10/site-packages/torch/nn/modules/module.py", line 1553, in _wrapped_call_impl
    return self._call_impl(*args, **kwargs)
  File "/home/abdenour/anaconda3/envs/fl/lib/python3.10/site-packages/torch/nn/modules/module.py", line 1562, in _call_impl
    return forward_call(*args, **kwargs)
  File "/home/abdenour/anaconda3/envs/fl/lib/python3.10/site-packages/torchvision/models/vgg.py", line 66, in forward
    x = self.features(x)
  File "/home/abdenour/anaconda3/envs/fl/lib/python3.10/site-packages/torch/nn/modules/module.py", line 1553, in _wrapped_call_impl
    return self._call_impl(*args, **kwargs)
  File "/home/abdenour/anaconda3/envs/fl/lib/python3.10/site-packages/torch/nn/modules/module.py", line 1562, in _call_impl
    return forward_call(*args, **kwargs)
  File "/home/abdenour/anaconda3/envs/fl/lib/python3.10/site-packages/torch/nn/modules/container.py", line 219, in forward
    input = module(input)
  File "/home/abdenour/anaconda3/envs/fl/lib/python3.10/site-packages/torch/nn/modules/module.py", line 1553, in _wrapped_call_impl
    return self._call_impl(*args, **kwargs)
  File "/home/abdenour/anaconda3/envs/fl/lib/python3.10/site-packages/torch/nn/modules/module.py", line 1562, in _call_impl
    return forward_call(*args, **kwargs)
  File "/home/abdenour/anaconda3/envs/fl/lib/python3.10/site-packages/torch/nn/modules/conv.py", line 458, in forward
    return self._conv_forward(input, self.weight, self.bias)
  File "/home/abdenour/anaconda3/envs/fl/lib/python3.10/site-packages/torch/nn/modules/conv.py", line 454, in _conv_forward
    return F.conv2d(input, weight, bias, self.stride,
torch.OutOfMemoryError: CUDA out of memory. Tried to allocate 784.00 MiB. GPU 0 has a total capacity of 47.33 GiB of which 44.81 MiB is free. Process 2279413 has 11.11 GiB memory in use. Process 2265701 has 2.37 GiB memory in use. Process 2279412 has 11.11 GiB memory in use. Process 2362925 has 11.11 GiB memory in use. Process 2349203 has 2.37 GiB memory in use. Process 2362924 has 8.04 GiB memory in use. Including non-PyTorch memory, this process has 816.00 MiB memory in use. Process 2362922 has 322.00 MiB memory in use. Of the allocated memory 549.92 MiB is allocated by PyTorch, and 6.08 MiB is reserved by PyTorch but unallocated. If reserved but unallocated memory is large try setting PYTORCH_CUDA_ALLOC_CONF=expandable_segments:True to avoid fragmentation.  See documentation for Memory Management  (https://pytorch.org/docs/stable/notes/cuda.html#environment-variables)

The above exception was the direct cause of the following exception:

[36mray::ClientAppActor.run()[39m (pid=2362923, ip=115.145.172.224, actor_id=191f38ecb8e72eee5122ddd001000000, repr=<flwr.simulation.ray_transport.ray_actor.ClientAppActor object at 0x7f2c5008d720>)
  File "/home/abdenour/.local/lib/python3.10/site-packages/flwr/simulation/ray_transport/ray_actor.py", line 63, in run
    raise ClientAppException(str(ex)) from ex
flwr.client.client_app.ClientAppException: 
Exception ClientAppException occurred. Message: CUDA out of memory. Tried to allocate 784.00 MiB. GPU 0 has a total capacity of 47.33 GiB of which 44.81 MiB is free. Process 2279413 has 11.11 GiB memory in use. Process 2265701 has 2.37 GiB memory in use. Process 2279412 has 11.11 GiB memory in use. Process 2362925 has 11.11 GiB memory in use. Process 2349203 has 2.37 GiB memory in use. Process 2362924 has 8.04 GiB memory in use. Including non-PyTorch memory, this process has 816.00 MiB memory in use. Process 2362922 has 322.00 MiB memory in use. Of the allocated memory 549.92 MiB is allocated by PyTorch, and 6.08 MiB is reserved by PyTorch but unallocated. If reserved but unallocated memory is large try setting PYTORCH_CUDA_ALLOC_CONF=expandable_segments:True to avoid fragmentation.  See documentation for Memory Management  (https://pytorch.org/docs/stable/notes/cuda.html#environment-variables)
[2024-09-19 01:27:51,376][flwr][INFO] - aggregate_fit: received 3 results and 2 failures
[2024-09-19 01:27:52,318][flwr][WARNING] - No fit_metrics_aggregation_fn provided
[2024-09-19 01:28:02,544][flwr][INFO] - fit progress: (1, 228.73988962173462, {'accuracy': 0.16895644548377667}, 27.458578503225)
[2024-09-19 01:28:02,544][flwr][INFO] - configure_evaluate: strategy sampled 2 clients (out of 50)
[2024-09-19 01:28:06,205][flwr][INFO] - aggregate_evaluate: received 2 results and 0 failures
[2024-09-19 01:28:06,206][flwr][INFO] - 
[2024-09-19 01:28:06,206][flwr][INFO] - [ROUND 2]
[2024-09-19 01:28:06,206][flwr][INFO] - configure_fit: strategy sampled 5 clients (out of 50)
[2024-09-19 01:28:12,671][flwr][ERROR] - Traceback (most recent call last):
  File "/home/abdenour/.local/lib/python3.10/site-packages/flwr/simulation/ray_transport/ray_client_proxy.py", line 94, in _submit_job
    out_mssg, updated_context = self.actor_pool.get_client_result(
  File "/home/abdenour/.local/lib/python3.10/site-packages/flwr/simulation/ray_transport/ray_actor.py", line 398, in get_client_result
    return self._fetch_future_result(cid)
  File "/home/abdenour/.local/lib/python3.10/site-packages/flwr/simulation/ray_transport/ray_actor.py", line 279, in _fetch_future_result
    res_cid, out_mssg, updated_context = ray.get(
  File "/home/abdenour/.local/lib/python3.10/site-packages/ray/_private/auto_init_hook.py", line 21, in auto_init_wrapper
    return fn(*args, **kwargs)
  File "/home/abdenour/.local/lib/python3.10/site-packages/ray/_private/client_mode_hook.py", line 103, in wrapper
    return func(*args, **kwargs)
  File "/home/abdenour/.local/lib/python3.10/site-packages/ray/_private/worker.py", line 2667, in get
    values, debugger_breakpoint = worker.get_objects(object_refs, timeout=timeout)
  File "/home/abdenour/.local/lib/python3.10/site-packages/ray/_private/worker.py", line 864, in get_objects
    raise value.as_instanceof_cause()
ray.exceptions.RayTaskError(ClientAppException): [36mray::ClientAppActor.run()[39m (pid=2362922, ip=115.145.172.224, actor_id=b553081c8efb20e91541068301000000, repr=<flwr.simulation.ray_transport.ray_actor.ClientAppActor object at 0x7f8ea0279750>)
  File "/home/abdenour/.local/lib/python3.10/site-packages/flwr/client/client_app.py", line 143, in __call__
    return self._call(message, context)
  File "/home/abdenour/.local/lib/python3.10/site-packages/flwr/client/client_app.py", line 126, in ffn
    out_message = handle_legacy_message_from_msgtype(
  File "/home/abdenour/.local/lib/python3.10/site-packages/flwr/client/message_handler/message_handler.py", line 95, in handle_legacy_message_from_msgtype
    client = client_fn(context)
  File "/home/abdenour/fl_with_flower/fednova_vgg16/fednova_vgg16/client.py", line 129, in client_fn
    return FlowerClient(trainset, valset, num_classes, config_fit, client_dataset_ratio, context.node_config).to_client()
  File "/home/abdenour/fl_with_flower/fednova_vgg16/fednova_vgg16/client.py", line 36, in __init__
    self.model = self.model.to(self.device)
  File "/home/abdenour/anaconda3/envs/fl/lib/python3.10/site-packages/torch/nn/modules/module.py", line 1174, in to
    return self._apply(convert)
  File "/home/abdenour/anaconda3/envs/fl/lib/python3.10/site-packages/torch/nn/modules/module.py", line 780, in _apply
    module._apply(fn)
  File "/home/abdenour/anaconda3/envs/fl/lib/python3.10/site-packages/torch/nn/modules/module.py", line 780, in _apply
    module._apply(fn)
  File "/home/abdenour/anaconda3/envs/fl/lib/python3.10/site-packages/torch/nn/modules/module.py", line 805, in _apply
    param_applied = fn(param)
  File "/home/abdenour/anaconda3/envs/fl/lib/python3.10/site-packages/torch/nn/modules/module.py", line 1160, in convert
    return t.to(
torch.OutOfMemoryError: CUDA out of memory. Tried to allocate 392.00 MiB. GPU 0 has a total capacity of 47.33 GiB of which 50.81 MiB is free. Process 2279413 has 11.11 GiB memory in use. Process 2265701 has 2.37 GiB memory in use. Process 2279412 has 11.11 GiB memory in use. Process 2362925 has 11.11 GiB memory in use. Process 2349203 has 2.37 GiB memory in use. Process 2362924 has 8.04 GiB memory in use. Process 2362923 has 816.00 MiB memory in use. Including non-PyTorch memory, this process has 322.00 MiB memory in use. Of the allocated memory 57.01 MiB is allocated by PyTorch, and 4.99 MiB is reserved by PyTorch but unallocated. If reserved but unallocated memory is large try setting PYTORCH_CUDA_ALLOC_CONF=expandable_segments:True to avoid fragmentation.  See documentation for Memory Management  (https://pytorch.org/docs/stable/notes/cuda.html#environment-variables)

The above exception was the direct cause of the following exception:

[36mray::ClientAppActor.run()[39m (pid=2362922, ip=115.145.172.224, actor_id=b553081c8efb20e91541068301000000, repr=<flwr.simulation.ray_transport.ray_actor.ClientAppActor object at 0x7f8ea0279750>)
  File "/home/abdenour/.local/lib/python3.10/site-packages/flwr/simulation/ray_transport/ray_actor.py", line 63, in run
    raise ClientAppException(str(ex)) from ex
flwr.client.client_app.ClientAppException: 
Exception ClientAppException occurred. Message: CUDA out of memory. Tried to allocate 392.00 MiB. GPU 0 has a total capacity of 47.33 GiB of which 50.81 MiB is free. Process 2279413 has 11.11 GiB memory in use. Process 2265701 has 2.37 GiB memory in use. Process 2279412 has 11.11 GiB memory in use. Process 2362925 has 11.11 GiB memory in use. Process 2349203 has 2.37 GiB memory in use. Process 2362924 has 8.04 GiB memory in use. Process 2362923 has 816.00 MiB memory in use. Including non-PyTorch memory, this process has 322.00 MiB memory in use. Of the allocated memory 57.01 MiB is allocated by PyTorch, and 4.99 MiB is reserved by PyTorch but unallocated. If reserved but unallocated memory is large try setting PYTORCH_CUDA_ALLOC_CONF=expandable_segments:True to avoid fragmentation.  See documentation for Memory Management  (https://pytorch.org/docs/stable/notes/cuda.html#environment-variables)

[2024-09-19 01:28:12,671][flwr][ERROR] - Traceback (most recent call last):
  File "/home/abdenour/.local/lib/python3.10/site-packages/flwr/simulation/ray_transport/ray_client_proxy.py", line 94, in _submit_job
    out_mssg, updated_context = self.actor_pool.get_client_result(
  File "/home/abdenour/.local/lib/python3.10/site-packages/flwr/simulation/ray_transport/ray_actor.py", line 398, in get_client_result
    return self._fetch_future_result(cid)
  File "/home/abdenour/.local/lib/python3.10/site-packages/flwr/simulation/ray_transport/ray_actor.py", line 279, in _fetch_future_result
    res_cid, out_mssg, updated_context = ray.get(
  File "/home/abdenour/.local/lib/python3.10/site-packages/ray/_private/auto_init_hook.py", line 21, in auto_init_wrapper
    return fn(*args, **kwargs)
  File "/home/abdenour/.local/lib/python3.10/site-packages/ray/_private/client_mode_hook.py", line 103, in wrapper
    return func(*args, **kwargs)
  File "/home/abdenour/.local/lib/python3.10/site-packages/ray/_private/worker.py", line 2667, in get
    values, debugger_breakpoint = worker.get_objects(object_refs, timeout=timeout)
  File "/home/abdenour/.local/lib/python3.10/site-packages/ray/_private/worker.py", line 864, in get_objects
    raise value.as_instanceof_cause()
ray.exceptions.RayTaskError(ClientAppException): [36mray::ClientAppActor.run()[39m (pid=2362923, ip=115.145.172.224, actor_id=191f38ecb8e72eee5122ddd001000000, repr=<flwr.simulation.ray_transport.ray_actor.ClientAppActor object at 0x7f2c5008d720>)
  File "/home/abdenour/.local/lib/python3.10/site-packages/flwr/client/client_app.py", line 143, in __call__
    return self._call(message, context)
  File "/home/abdenour/.local/lib/python3.10/site-packages/flwr/client/client_app.py", line 126, in ffn
    out_message = handle_legacy_message_from_msgtype(
  File "/home/abdenour/.local/lib/python3.10/site-packages/flwr/client/message_handler/message_handler.py", line 129, in handle_legacy_message_from_msgtype
    fit_res = maybe_call_fit(
  File "/home/abdenour/.local/lib/python3.10/site-packages/flwr/client/client.py", line 234, in maybe_call_fit
    return client.fit(fit_ins)
  File "/home/abdenour/.local/lib/python3.10/site-packages/flwr/client/numpy_client.py", line 238, in _fit
    results = self.numpy_client.fit(parameters, ins.config)  # type: ignore
  File "/home/abdenour/fl_with_flower/fednova_vgg16/fednova_vgg16/client.py", line 69, in fit
    train(self.model, trainloader, self.optimizer, epochs=num_epochs, device=self.device)
  File "/home/abdenour/fl_with_flower/fednova_vgg16/fednova_vgg16/utils.py", line 57, in train
    loss = criterion(net(images), labels)
  File "/home/abdenour/anaconda3/envs/fl/lib/python3.10/site-packages/torch/nn/modules/module.py", line 1553, in _wrapped_call_impl
    return self._call_impl(*args, **kwargs)
  File "/home/abdenour/anaconda3/envs/fl/lib/python3.10/site-packages/torch/nn/modules/module.py", line 1562, in _call_impl
    return forward_call(*args, **kwargs)
  File "/home/abdenour/anaconda3/envs/fl/lib/python3.10/site-packages/torchvision/models/vgg.py", line 66, in forward
    x = self.features(x)
  File "/home/abdenour/anaconda3/envs/fl/lib/python3.10/site-packages/torch/nn/modules/module.py", line 1553, in _wrapped_call_impl
    return self._call_impl(*args, **kwargs)
  File "/home/abdenour/anaconda3/envs/fl/lib/python3.10/site-packages/torch/nn/modules/module.py", line 1562, in _call_impl
    return forward_call(*args, **kwargs)
  File "/home/abdenour/anaconda3/envs/fl/lib/python3.10/site-packages/torch/nn/modules/container.py", line 219, in forward
    input = module(input)
  File "/home/abdenour/anaconda3/envs/fl/lib/python3.10/site-packages/torch/nn/modules/module.py", line 1553, in _wrapped_call_impl
    return self._call_impl(*args, **kwargs)
  File "/home/abdenour/anaconda3/envs/fl/lib/python3.10/site-packages/torch/nn/modules/module.py", line 1562, in _call_impl
    return forward_call(*args, **kwargs)
  File "/home/abdenour/anaconda3/envs/fl/lib/python3.10/site-packages/torch/nn/modules/conv.py", line 458, in forward
    return self._conv_forward(input, self.weight, self.bias)
  File "/home/abdenour/anaconda3/envs/fl/lib/python3.10/site-packages/torch/nn/modules/conv.py", line 454, in _conv_forward
    return F.conv2d(input, weight, bias, self.stride,
torch.OutOfMemoryError: CUDA out of memory. Tried to allocate 784.00 MiB. GPU 0 has a total capacity of 47.33 GiB of which 50.81 MiB is free. Process 2279413 has 11.11 GiB memory in use. Process 2265701 has 2.37 GiB memory in use. Process 2279412 has 11.11 GiB memory in use. Process 2362925 has 11.11 GiB memory in use. Process 2349203 has 2.37 GiB memory in use. Process 2362924 has 8.04 GiB memory in use. Including non-PyTorch memory, this process has 816.00 MiB memory in use. Process 2362922 has 322.00 MiB memory in use. Of the allocated memory 549.92 MiB is allocated by PyTorch, and 6.08 MiB is reserved by PyTorch but unallocated. If reserved but unallocated memory is large try setting PYTORCH_CUDA_ALLOC_CONF=expandable_segments:True to avoid fragmentation.  See documentation for Memory Management  (https://pytorch.org/docs/stable/notes/cuda.html#environment-variables)

The above exception was the direct cause of the following exception:

[36mray::ClientAppActor.run()[39m (pid=2362923, ip=115.145.172.224, actor_id=191f38ecb8e72eee5122ddd001000000, repr=<flwr.simulation.ray_transport.ray_actor.ClientAppActor object at 0x7f2c5008d720>)
  File "/home/abdenour/.local/lib/python3.10/site-packages/flwr/simulation/ray_transport/ray_actor.py", line 63, in run
    raise ClientAppException(str(ex)) from ex
flwr.client.client_app.ClientAppException: 
Exception ClientAppException occurred. Message: CUDA out of memory. Tried to allocate 784.00 MiB. GPU 0 has a total capacity of 47.33 GiB of which 50.81 MiB is free. Process 2279413 has 11.11 GiB memory in use. Process 2265701 has 2.37 GiB memory in use. Process 2279412 has 11.11 GiB memory in use. Process 2362925 has 11.11 GiB memory in use. Process 2349203 has 2.37 GiB memory in use. Process 2362924 has 8.04 GiB memory in use. Including non-PyTorch memory, this process has 816.00 MiB memory in use. Process 2362922 has 322.00 MiB memory in use. Of the allocated memory 549.92 MiB is allocated by PyTorch, and 6.08 MiB is reserved by PyTorch but unallocated. If reserved but unallocated memory is large try setting PYTORCH_CUDA_ALLOC_CONF=expandable_segments:True to avoid fragmentation.  See documentation for Memory Management  (https://pytorch.org/docs/stable/notes/cuda.html#environment-variables)

[2024-09-19 01:28:12,672][flwr][ERROR] - [36mray::ClientAppActor.run()[39m (pid=2362922, ip=115.145.172.224, actor_id=b553081c8efb20e91541068301000000, repr=<flwr.simulation.ray_transport.ray_actor.ClientAppActor object at 0x7f8ea0279750>)
  File "/home/abdenour/.local/lib/python3.10/site-packages/flwr/client/client_app.py", line 143, in __call__
    return self._call(message, context)
  File "/home/abdenour/.local/lib/python3.10/site-packages/flwr/client/client_app.py", line 126, in ffn
    out_message = handle_legacy_message_from_msgtype(
  File "/home/abdenour/.local/lib/python3.10/site-packages/flwr/client/message_handler/message_handler.py", line 95, in handle_legacy_message_from_msgtype
    client = client_fn(context)
  File "/home/abdenour/fl_with_flower/fednova_vgg16/fednova_vgg16/client.py", line 129, in client_fn
    return FlowerClient(trainset, valset, num_classes, config_fit, client_dataset_ratio, context.node_config).to_client()
  File "/home/abdenour/fl_with_flower/fednova_vgg16/fednova_vgg16/client.py", line 36, in __init__
    self.model = self.model.to(self.device)
  File "/home/abdenour/anaconda3/envs/fl/lib/python3.10/site-packages/torch/nn/modules/module.py", line 1174, in to
    return self._apply(convert)
  File "/home/abdenour/anaconda3/envs/fl/lib/python3.10/site-packages/torch/nn/modules/module.py", line 780, in _apply
    module._apply(fn)
  File "/home/abdenour/anaconda3/envs/fl/lib/python3.10/site-packages/torch/nn/modules/module.py", line 780, in _apply
    module._apply(fn)
  File "/home/abdenour/anaconda3/envs/fl/lib/python3.10/site-packages/torch/nn/modules/module.py", line 805, in _apply
    param_applied = fn(param)
  File "/home/abdenour/anaconda3/envs/fl/lib/python3.10/site-packages/torch/nn/modules/module.py", line 1160, in convert
    return t.to(
torch.OutOfMemoryError: CUDA out of memory. Tried to allocate 392.00 MiB. GPU 0 has a total capacity of 47.33 GiB of which 50.81 MiB is free. Process 2279413 has 11.11 GiB memory in use. Process 2265701 has 2.37 GiB memory in use. Process 2279412 has 11.11 GiB memory in use. Process 2362925 has 11.11 GiB memory in use. Process 2349203 has 2.37 GiB memory in use. Process 2362924 has 8.04 GiB memory in use. Process 2362923 has 816.00 MiB memory in use. Including non-PyTorch memory, this process has 322.00 MiB memory in use. Of the allocated memory 57.01 MiB is allocated by PyTorch, and 4.99 MiB is reserved by PyTorch but unallocated. If reserved but unallocated memory is large try setting PYTORCH_CUDA_ALLOC_CONF=expandable_segments:True to avoid fragmentation.  See documentation for Memory Management  (https://pytorch.org/docs/stable/notes/cuda.html#environment-variables)

The above exception was the direct cause of the following exception:

[36mray::ClientAppActor.run()[39m (pid=2362922, ip=115.145.172.224, actor_id=b553081c8efb20e91541068301000000, repr=<flwr.simulation.ray_transport.ray_actor.ClientAppActor object at 0x7f8ea0279750>)
  File "/home/abdenour/.local/lib/python3.10/site-packages/flwr/simulation/ray_transport/ray_actor.py", line 63, in run
    raise ClientAppException(str(ex)) from ex
flwr.client.client_app.ClientAppException: 
Exception ClientAppException occurred. Message: CUDA out of memory. Tried to allocate 392.00 MiB. GPU 0 has a total capacity of 47.33 GiB of which 50.81 MiB is free. Process 2279413 has 11.11 GiB memory in use. Process 2265701 has 2.37 GiB memory in use. Process 2279412 has 11.11 GiB memory in use. Process 2362925 has 11.11 GiB memory in use. Process 2349203 has 2.37 GiB memory in use. Process 2362924 has 8.04 GiB memory in use. Process 2362923 has 816.00 MiB memory in use. Including non-PyTorch memory, this process has 322.00 MiB memory in use. Of the allocated memory 57.01 MiB is allocated by PyTorch, and 4.99 MiB is reserved by PyTorch but unallocated. If reserved but unallocated memory is large try setting PYTORCH_CUDA_ALLOC_CONF=expandable_segments:True to avoid fragmentation.  See documentation for Memory Management  (https://pytorch.org/docs/stable/notes/cuda.html#environment-variables)
[2024-09-19 01:28:12,672][flwr][ERROR] - [36mray::ClientAppActor.run()[39m (pid=2362923, ip=115.145.172.224, actor_id=191f38ecb8e72eee5122ddd001000000, repr=<flwr.simulation.ray_transport.ray_actor.ClientAppActor object at 0x7f2c5008d720>)
  File "/home/abdenour/.local/lib/python3.10/site-packages/flwr/client/client_app.py", line 143, in __call__
    return self._call(message, context)
  File "/home/abdenour/.local/lib/python3.10/site-packages/flwr/client/client_app.py", line 126, in ffn
    out_message = handle_legacy_message_from_msgtype(
  File "/home/abdenour/.local/lib/python3.10/site-packages/flwr/client/message_handler/message_handler.py", line 129, in handle_legacy_message_from_msgtype
    fit_res = maybe_call_fit(
  File "/home/abdenour/.local/lib/python3.10/site-packages/flwr/client/client.py", line 234, in maybe_call_fit
    return client.fit(fit_ins)
  File "/home/abdenour/.local/lib/python3.10/site-packages/flwr/client/numpy_client.py", line 238, in _fit
    results = self.numpy_client.fit(parameters, ins.config)  # type: ignore
  File "/home/abdenour/fl_with_flower/fednova_vgg16/fednova_vgg16/client.py", line 69, in fit
    train(self.model, trainloader, self.optimizer, epochs=num_epochs, device=self.device)
  File "/home/abdenour/fl_with_flower/fednova_vgg16/fednova_vgg16/utils.py", line 57, in train
    loss = criterion(net(images), labels)
  File "/home/abdenour/anaconda3/envs/fl/lib/python3.10/site-packages/torch/nn/modules/module.py", line 1553, in _wrapped_call_impl
    return self._call_impl(*args, **kwargs)
  File "/home/abdenour/anaconda3/envs/fl/lib/python3.10/site-packages/torch/nn/modules/module.py", line 1562, in _call_impl
    return forward_call(*args, **kwargs)
  File "/home/abdenour/anaconda3/envs/fl/lib/python3.10/site-packages/torchvision/models/vgg.py", line 66, in forward
    x = self.features(x)
  File "/home/abdenour/anaconda3/envs/fl/lib/python3.10/site-packages/torch/nn/modules/module.py", line 1553, in _wrapped_call_impl
    return self._call_impl(*args, **kwargs)
  File "/home/abdenour/anaconda3/envs/fl/lib/python3.10/site-packages/torch/nn/modules/module.py", line 1562, in _call_impl
    return forward_call(*args, **kwargs)
  File "/home/abdenour/anaconda3/envs/fl/lib/python3.10/site-packages/torch/nn/modules/container.py", line 219, in forward
    input = module(input)
  File "/home/abdenour/anaconda3/envs/fl/lib/python3.10/site-packages/torch/nn/modules/module.py", line 1553, in _wrapped_call_impl
    return self._call_impl(*args, **kwargs)
  File "/home/abdenour/anaconda3/envs/fl/lib/python3.10/site-packages/torch/nn/modules/module.py", line 1562, in _call_impl
    return forward_call(*args, **kwargs)
  File "/home/abdenour/anaconda3/envs/fl/lib/python3.10/site-packages/torch/nn/modules/conv.py", line 458, in forward
    return self._conv_forward(input, self.weight, self.bias)
  File "/home/abdenour/anaconda3/envs/fl/lib/python3.10/site-packages/torch/nn/modules/conv.py", line 454, in _conv_forward
    return F.conv2d(input, weight, bias, self.stride,
torch.OutOfMemoryError: CUDA out of memory. Tried to allocate 784.00 MiB. GPU 0 has a total capacity of 47.33 GiB of which 50.81 MiB is free. Process 2279413 has 11.11 GiB memory in use. Process 2265701 has 2.37 GiB memory in use. Process 2279412 has 11.11 GiB memory in use. Process 2362925 has 11.11 GiB memory in use. Process 2349203 has 2.37 GiB memory in use. Process 2362924 has 8.04 GiB memory in use. Including non-PyTorch memory, this process has 816.00 MiB memory in use. Process 2362922 has 322.00 MiB memory in use. Of the allocated memory 549.92 MiB is allocated by PyTorch, and 6.08 MiB is reserved by PyTorch but unallocated. If reserved but unallocated memory is large try setting PYTORCH_CUDA_ALLOC_CONF=expandable_segments:True to avoid fragmentation.  See documentation for Memory Management  (https://pytorch.org/docs/stable/notes/cuda.html#environment-variables)

The above exception was the direct cause of the following exception:

[36mray::ClientAppActor.run()[39m (pid=2362923, ip=115.145.172.224, actor_id=191f38ecb8e72eee5122ddd001000000, repr=<flwr.simulation.ray_transport.ray_actor.ClientAppActor object at 0x7f2c5008d720>)
  File "/home/abdenour/.local/lib/python3.10/site-packages/flwr/simulation/ray_transport/ray_actor.py", line 63, in run
    raise ClientAppException(str(ex)) from ex
flwr.client.client_app.ClientAppException: 
Exception ClientAppException occurred. Message: CUDA out of memory. Tried to allocate 784.00 MiB. GPU 0 has a total capacity of 47.33 GiB of which 50.81 MiB is free. Process 2279413 has 11.11 GiB memory in use. Process 2265701 has 2.37 GiB memory in use. Process 2279412 has 11.11 GiB memory in use. Process 2362925 has 11.11 GiB memory in use. Process 2349203 has 2.37 GiB memory in use. Process 2362924 has 8.04 GiB memory in use. Including non-PyTorch memory, this process has 816.00 MiB memory in use. Process 2362922 has 322.00 MiB memory in use. Of the allocated memory 549.92 MiB is allocated by PyTorch, and 6.08 MiB is reserved by PyTorch but unallocated. If reserved but unallocated memory is large try setting PYTORCH_CUDA_ALLOC_CONF=expandable_segments:True to avoid fragmentation.  See documentation for Memory Management  (https://pytorch.org/docs/stable/notes/cuda.html#environment-variables)
[2024-09-19 01:28:14,309][flwr][ERROR] - Traceback (most recent call last):
  File "/home/abdenour/.local/lib/python3.10/site-packages/flwr/simulation/ray_transport/ray_client_proxy.py", line 94, in _submit_job
    out_mssg, updated_context = self.actor_pool.get_client_result(
  File "/home/abdenour/.local/lib/python3.10/site-packages/flwr/simulation/ray_transport/ray_actor.py", line 398, in get_client_result
    return self._fetch_future_result(cid)
  File "/home/abdenour/.local/lib/python3.10/site-packages/flwr/simulation/ray_transport/ray_actor.py", line 279, in _fetch_future_result
    res_cid, out_mssg, updated_context = ray.get(
  File "/home/abdenour/.local/lib/python3.10/site-packages/ray/_private/auto_init_hook.py", line 21, in auto_init_wrapper
    return fn(*args, **kwargs)
  File "/home/abdenour/.local/lib/python3.10/site-packages/ray/_private/client_mode_hook.py", line 103, in wrapper
    return func(*args, **kwargs)
  File "/home/abdenour/.local/lib/python3.10/site-packages/ray/_private/worker.py", line 2667, in get
    values, debugger_breakpoint = worker.get_objects(object_refs, timeout=timeout)
  File "/home/abdenour/.local/lib/python3.10/site-packages/ray/_private/worker.py", line 864, in get_objects
    raise value.as_instanceof_cause()
ray.exceptions.RayTaskError(ClientAppException): [36mray::ClientAppActor.run()[39m (pid=2362922, ip=115.145.172.224, actor_id=b553081c8efb20e91541068301000000, repr=<flwr.simulation.ray_transport.ray_actor.ClientAppActor object at 0x7f8ea0279750>)
  File "/home/abdenour/.local/lib/python3.10/site-packages/flwr/client/client_app.py", line 143, in __call__
    return self._call(message, context)
  File "/home/abdenour/.local/lib/python3.10/site-packages/flwr/client/client_app.py", line 126, in ffn
    out_message = handle_legacy_message_from_msgtype(
  File "/home/abdenour/.local/lib/python3.10/site-packages/flwr/client/message_handler/message_handler.py", line 95, in handle_legacy_message_from_msgtype
    client = client_fn(context)
  File "/home/abdenour/fl_with_flower/fednova_vgg16/fednova_vgg16/client.py", line 129, in client_fn
    return FlowerClient(trainset, valset, num_classes, config_fit, client_dataset_ratio, context.node_config).to_client()
  File "/home/abdenour/fl_with_flower/fednova_vgg16/fednova_vgg16/client.py", line 36, in __init__
    self.model = self.model.to(self.device)
  File "/home/abdenour/anaconda3/envs/fl/lib/python3.10/site-packages/torch/nn/modules/module.py", line 1174, in to
    return self._apply(convert)
  File "/home/abdenour/anaconda3/envs/fl/lib/python3.10/site-packages/torch/nn/modules/module.py", line 780, in _apply
    module._apply(fn)
  File "/home/abdenour/anaconda3/envs/fl/lib/python3.10/site-packages/torch/nn/modules/module.py", line 780, in _apply
    module._apply(fn)
  File "/home/abdenour/anaconda3/envs/fl/lib/python3.10/site-packages/torch/nn/modules/module.py", line 805, in _apply
    param_applied = fn(param)
  File "/home/abdenour/anaconda3/envs/fl/lib/python3.10/site-packages/torch/nn/modules/module.py", line 1160, in convert
    return t.to(
torch.OutOfMemoryError: CUDA out of memory. Tried to allocate 392.00 MiB. GPU 0 has a total capacity of 47.33 GiB of which 50.81 MiB is free. Process 2279413 has 11.11 GiB memory in use. Process 2265701 has 2.37 GiB memory in use. Process 2279412 has 11.11 GiB memory in use. Process 2362925 has 11.11 GiB memory in use. Process 2349203 has 2.37 GiB memory in use. Process 2362924 has 8.04 GiB memory in use. Process 2362923 has 816.00 MiB memory in use. Including non-PyTorch memory, this process has 322.00 MiB memory in use. Of the allocated memory 57.01 MiB is allocated by PyTorch, and 4.99 MiB is reserved by PyTorch but unallocated. If reserved but unallocated memory is large try setting PYTORCH_CUDA_ALLOC_CONF=expandable_segments:True to avoid fragmentation.  See documentation for Memory Management  (https://pytorch.org/docs/stable/notes/cuda.html#environment-variables)

The above exception was the direct cause of the following exception:

[36mray::ClientAppActor.run()[39m (pid=2362922, ip=115.145.172.224, actor_id=b553081c8efb20e91541068301000000, repr=<flwr.simulation.ray_transport.ray_actor.ClientAppActor object at 0x7f8ea0279750>)
  File "/home/abdenour/.local/lib/python3.10/site-packages/flwr/simulation/ray_transport/ray_actor.py", line 63, in run
    raise ClientAppException(str(ex)) from ex
flwr.client.client_app.ClientAppException: 
Exception ClientAppException occurred. Message: CUDA out of memory. Tried to allocate 392.00 MiB. GPU 0 has a total capacity of 47.33 GiB of which 50.81 MiB is free. Process 2279413 has 11.11 GiB memory in use. Process 2265701 has 2.37 GiB memory in use. Process 2279412 has 11.11 GiB memory in use. Process 2362925 has 11.11 GiB memory in use. Process 2349203 has 2.37 GiB memory in use. Process 2362924 has 8.04 GiB memory in use. Process 2362923 has 816.00 MiB memory in use. Including non-PyTorch memory, this process has 322.00 MiB memory in use. Of the allocated memory 57.01 MiB is allocated by PyTorch, and 4.99 MiB is reserved by PyTorch but unallocated. If reserved but unallocated memory is large try setting PYTORCH_CUDA_ALLOC_CONF=expandable_segments:True to avoid fragmentation.  See documentation for Memory Management  (https://pytorch.org/docs/stable/notes/cuda.html#environment-variables)

[2024-09-19 01:28:14,309][flwr][ERROR] - [36mray::ClientAppActor.run()[39m (pid=2362922, ip=115.145.172.224, actor_id=b553081c8efb20e91541068301000000, repr=<flwr.simulation.ray_transport.ray_actor.ClientAppActor object at 0x7f8ea0279750>)
  File "/home/abdenour/.local/lib/python3.10/site-packages/flwr/client/client_app.py", line 143, in __call__
    return self._call(message, context)
  File "/home/abdenour/.local/lib/python3.10/site-packages/flwr/client/client_app.py", line 126, in ffn
    out_message = handle_legacy_message_from_msgtype(
  File "/home/abdenour/.local/lib/python3.10/site-packages/flwr/client/message_handler/message_handler.py", line 95, in handle_legacy_message_from_msgtype
    client = client_fn(context)
  File "/home/abdenour/fl_with_flower/fednova_vgg16/fednova_vgg16/client.py", line 129, in client_fn
    return FlowerClient(trainset, valset, num_classes, config_fit, client_dataset_ratio, context.node_config).to_client()
  File "/home/abdenour/fl_with_flower/fednova_vgg16/fednova_vgg16/client.py", line 36, in __init__
    self.model = self.model.to(self.device)
  File "/home/abdenour/anaconda3/envs/fl/lib/python3.10/site-packages/torch/nn/modules/module.py", line 1174, in to
    return self._apply(convert)
  File "/home/abdenour/anaconda3/envs/fl/lib/python3.10/site-packages/torch/nn/modules/module.py", line 780, in _apply
    module._apply(fn)
  File "/home/abdenour/anaconda3/envs/fl/lib/python3.10/site-packages/torch/nn/modules/module.py", line 780, in _apply
    module._apply(fn)
  File "/home/abdenour/anaconda3/envs/fl/lib/python3.10/site-packages/torch/nn/modules/module.py", line 805, in _apply
    param_applied = fn(param)
  File "/home/abdenour/anaconda3/envs/fl/lib/python3.10/site-packages/torch/nn/modules/module.py", line 1160, in convert
    return t.to(
torch.OutOfMemoryError: CUDA out of memory. Tried to allocate 392.00 MiB. GPU 0 has a total capacity of 47.33 GiB of which 50.81 MiB is free. Process 2279413 has 11.11 GiB memory in use. Process 2265701 has 2.37 GiB memory in use. Process 2279412 has 11.11 GiB memory in use. Process 2362925 has 11.11 GiB memory in use. Process 2349203 has 2.37 GiB memory in use. Process 2362924 has 8.04 GiB memory in use. Process 2362923 has 816.00 MiB memory in use. Including non-PyTorch memory, this process has 322.00 MiB memory in use. Of the allocated memory 57.01 MiB is allocated by PyTorch, and 4.99 MiB is reserved by PyTorch but unallocated. If reserved but unallocated memory is large try setting PYTORCH_CUDA_ALLOC_CONF=expandable_segments:True to avoid fragmentation.  See documentation for Memory Management  (https://pytorch.org/docs/stable/notes/cuda.html#environment-variables)

The above exception was the direct cause of the following exception:

[36mray::ClientAppActor.run()[39m (pid=2362922, ip=115.145.172.224, actor_id=b553081c8efb20e91541068301000000, repr=<flwr.simulation.ray_transport.ray_actor.ClientAppActor object at 0x7f8ea0279750>)
  File "/home/abdenour/.local/lib/python3.10/site-packages/flwr/simulation/ray_transport/ray_actor.py", line 63, in run
    raise ClientAppException(str(ex)) from ex
flwr.client.client_app.ClientAppException: 
Exception ClientAppException occurred. Message: CUDA out of memory. Tried to allocate 392.00 MiB. GPU 0 has a total capacity of 47.33 GiB of which 50.81 MiB is free. Process 2279413 has 11.11 GiB memory in use. Process 2265701 has 2.37 GiB memory in use. Process 2279412 has 11.11 GiB memory in use. Process 2362925 has 11.11 GiB memory in use. Process 2349203 has 2.37 GiB memory in use. Process 2362924 has 8.04 GiB memory in use. Process 2362923 has 816.00 MiB memory in use. Including non-PyTorch memory, this process has 322.00 MiB memory in use. Of the allocated memory 57.01 MiB is allocated by PyTorch, and 4.99 MiB is reserved by PyTorch but unallocated. If reserved but unallocated memory is large try setting PYTORCH_CUDA_ALLOC_CONF=expandable_segments:True to avoid fragmentation.  See documentation for Memory Management  (https://pytorch.org/docs/stable/notes/cuda.html#environment-variables)
[2024-09-19 01:28:15,910][flwr][INFO] - aggregate_fit: received 2 results and 3 failures
