[2024-09-19 01:30:23,614][flwr][INFO] - Starting Flower simulation, config: num_rounds=100, no round_timeout
[2024-09-19 01:30:27,036][flwr][INFO] - Flower VCE: Ray initialized with resources: {'memory': 149025173709.0, 'GPU': 1.0, 'accelerator_type:G': 1.0, 'CPU': 256.0, 'node:__internal_head__': 1.0, 'node:115.145.172.224': 1.0, 'object_store_memory': 68153645875.0}
[2024-09-19 01:30:27,037][flwr][INFO] - Optimize your simulation with Flower VCE: https://flower.ai/docs/framework/how-to-run-simulations.html
[2024-09-19 01:30:27,037][flwr][INFO] - Flower VCE: Resources for each Virtual Client: {'num_cpus': 64, 'num_gpus': 0.25}
[2024-09-19 01:30:27,052][flwr][INFO] - Flower VCE: Creating VirtualClientEngineActorPool with 4 actors
[2024-09-19 01:30:27,052][flwr][INFO] - [INIT]
[2024-09-19 01:30:27,052][flwr][INFO] - Requesting initial parameters from one random client
[2024-09-19 01:30:34,021][flwr][INFO] - Received initial parameters from one random client
[2024-09-19 01:30:34,021][flwr][INFO] - Evaluating initial global parameters
[2024-09-19 01:30:45,558][flwr][INFO] - initial parameters (loss, other metrics): 227.41200876235962, {'accuracy': 0.1394329143525285}
[2024-09-19 01:30:45,559][flwr][INFO] - 
[2024-09-19 01:30:45,559][flwr][INFO] - [ROUND 1]
[2024-09-19 01:30:45,559][flwr][INFO] - configure_fit: strategy sampled 5 clients (out of 50)
[2024-09-19 01:30:53,854][flwr][ERROR] - Traceback (most recent call last):
  File "/home/abdenour/.local/lib/python3.10/site-packages/flwr/simulation/ray_transport/ray_client_proxy.py", line 94, in _submit_job
    out_mssg, updated_context = self.actor_pool.get_client_result(
  File "/home/abdenour/.local/lib/python3.10/site-packages/flwr/simulation/ray_transport/ray_actor.py", line 398, in get_client_result
    return self._fetch_future_result(cid)
  File "/home/abdenour/.local/lib/python3.10/site-packages/flwr/simulation/ray_transport/ray_actor.py", line 279, in _fetch_future_result
    res_cid, out_mssg, updated_context = ray.get(
  File "/home/abdenour/.local/lib/python3.10/site-packages/ray/_private/auto_init_hook.py", line 21, in auto_init_wrapper
    return fn(*args, **kwargs)
  File "/home/abdenour/.local/lib/python3.10/site-packages/ray/_private/client_mode_hook.py", line 103, in wrapper
    return func(*args, **kwargs)
  File "/home/abdenour/.local/lib/python3.10/site-packages/ray/_private/worker.py", line 2667, in get
    values, debugger_breakpoint = worker.get_objects(object_refs, timeout=timeout)
  File "/home/abdenour/.local/lib/python3.10/site-packages/ray/_private/worker.py", line 864, in get_objects
    raise value.as_instanceof_cause()
ray.exceptions.RayTaskError(ClientAppException): [36mray::ClientAppActor.run()[39m (pid=2426096, ip=115.145.172.224, actor_id=82017147e17b846cf810e85f01000000, repr=<flwr.simulation.ray_transport.ray_actor.ClientAppActor object at 0x7fd01c585780>)
  File "/home/abdenour/.local/lib/python3.10/site-packages/flwr/client/client_app.py", line 143, in __call__
    return self._call(message, context)
  File "/home/abdenour/.local/lib/python3.10/site-packages/flwr/client/client_app.py", line 126, in ffn
    out_message = handle_legacy_message_from_msgtype(
  File "/home/abdenour/.local/lib/python3.10/site-packages/flwr/client/message_handler/message_handler.py", line 95, in handle_legacy_message_from_msgtype
    client = client_fn(context)
  File "/home/abdenour/fl_with_flower/fednova_vgg16/fednova_vgg16/client.py", line 129, in client_fn
    return FlowerClient(trainset, valset, num_classes, config_fit, client_dataset_ratio, context.node_config).to_client()
  File "/home/abdenour/fl_with_flower/fednova_vgg16/fednova_vgg16/client.py", line 36, in __init__
    self.model = self.model.to(self.device)
  File "/home/abdenour/anaconda3/envs/fl/lib/python3.10/site-packages/torch/nn/modules/module.py", line 1174, in to
    return self._apply(convert)
  File "/home/abdenour/anaconda3/envs/fl/lib/python3.10/site-packages/torch/nn/modules/module.py", line 780, in _apply
    module._apply(fn)
  File "/home/abdenour/anaconda3/envs/fl/lib/python3.10/site-packages/torch/nn/modules/module.py", line 780, in _apply
    module._apply(fn)
  File "/home/abdenour/anaconda3/envs/fl/lib/python3.10/site-packages/torch/nn/modules/module.py", line 805, in _apply
    param_applied = fn(param)
  File "/home/abdenour/anaconda3/envs/fl/lib/python3.10/site-packages/torch/nn/modules/module.py", line 1160, in convert
    return t.to(
RuntimeError: CUDA error: out of memory
CUDA kernel errors might be asynchronously reported at some other API call, so the stacktrace below might be incorrect.
For debugging consider passing CUDA_LAUNCH_BLOCKING=1
Compile with `TORCH_USE_CUDA_DSA` to enable device-side assertions.


The above exception was the direct cause of the following exception:

[36mray::ClientAppActor.run()[39m (pid=2426096, ip=115.145.172.224, actor_id=82017147e17b846cf810e85f01000000, repr=<flwr.simulation.ray_transport.ray_actor.ClientAppActor object at 0x7fd01c585780>)
  File "/home/abdenour/.local/lib/python3.10/site-packages/flwr/simulation/ray_transport/ray_actor.py", line 63, in run
    raise ClientAppException(str(ex)) from ex
flwr.client.client_app.ClientAppException: 
Exception ClientAppException occurred. Message: CUDA error: out of memory
CUDA kernel errors might be asynchronously reported at some other API call, so the stacktrace below might be incorrect.
For debugging consider passing CUDA_LAUNCH_BLOCKING=1
Compile with `TORCH_USE_CUDA_DSA` to enable device-side assertions.

[2024-09-19 01:30:53,854][flwr][ERROR] - [36mray::ClientAppActor.run()[39m (pid=2426096, ip=115.145.172.224, actor_id=82017147e17b846cf810e85f01000000, repr=<flwr.simulation.ray_transport.ray_actor.ClientAppActor object at 0x7fd01c585780>)
  File "/home/abdenour/.local/lib/python3.10/site-packages/flwr/client/client_app.py", line 143, in __call__
    return self._call(message, context)
  File "/home/abdenour/.local/lib/python3.10/site-packages/flwr/client/client_app.py", line 126, in ffn
    out_message = handle_legacy_message_from_msgtype(
  File "/home/abdenour/.local/lib/python3.10/site-packages/flwr/client/message_handler/message_handler.py", line 95, in handle_legacy_message_from_msgtype
    client = client_fn(context)
  File "/home/abdenour/fl_with_flower/fednova_vgg16/fednova_vgg16/client.py", line 129, in client_fn
    return FlowerClient(trainset, valset, num_classes, config_fit, client_dataset_ratio, context.node_config).to_client()
  File "/home/abdenour/fl_with_flower/fednova_vgg16/fednova_vgg16/client.py", line 36, in __init__
    self.model = self.model.to(self.device)
  File "/home/abdenour/anaconda3/envs/fl/lib/python3.10/site-packages/torch/nn/modules/module.py", line 1174, in to
    return self._apply(convert)
  File "/home/abdenour/anaconda3/envs/fl/lib/python3.10/site-packages/torch/nn/modules/module.py", line 780, in _apply
    module._apply(fn)
  File "/home/abdenour/anaconda3/envs/fl/lib/python3.10/site-packages/torch/nn/modules/module.py", line 780, in _apply
    module._apply(fn)
  File "/home/abdenour/anaconda3/envs/fl/lib/python3.10/site-packages/torch/nn/modules/module.py", line 805, in _apply
    param_applied = fn(param)
  File "/home/abdenour/anaconda3/envs/fl/lib/python3.10/site-packages/torch/nn/modules/module.py", line 1160, in convert
    return t.to(
RuntimeError: CUDA error: out of memory
CUDA kernel errors might be asynchronously reported at some other API call, so the stacktrace below might be incorrect.
For debugging consider passing CUDA_LAUNCH_BLOCKING=1
Compile with `TORCH_USE_CUDA_DSA` to enable device-side assertions.


The above exception was the direct cause of the following exception:

[36mray::ClientAppActor.run()[39m (pid=2426096, ip=115.145.172.224, actor_id=82017147e17b846cf810e85f01000000, repr=<flwr.simulation.ray_transport.ray_actor.ClientAppActor object at 0x7fd01c585780>)
  File "/home/abdenour/.local/lib/python3.10/site-packages/flwr/simulation/ray_transport/ray_actor.py", line 63, in run
    raise ClientAppException(str(ex)) from ex
flwr.client.client_app.ClientAppException: 
Exception ClientAppException occurred. Message: CUDA error: out of memory
CUDA kernel errors might be asynchronously reported at some other API call, so the stacktrace below might be incorrect.
For debugging consider passing CUDA_LAUNCH_BLOCKING=1
Compile with `TORCH_USE_CUDA_DSA` to enable device-side assertions.
[2024-09-19 01:30:53,966][flwr][ERROR] - Traceback (most recent call last):
  File "/home/abdenour/.local/lib/python3.10/site-packages/flwr/simulation/ray_transport/ray_client_proxy.py", line 94, in _submit_job
    out_mssg, updated_context = self.actor_pool.get_client_result(
  File "/home/abdenour/.local/lib/python3.10/site-packages/flwr/simulation/ray_transport/ray_actor.py", line 398, in get_client_result
    return self._fetch_future_result(cid)
  File "/home/abdenour/.local/lib/python3.10/site-packages/flwr/simulation/ray_transport/ray_actor.py", line 279, in _fetch_future_result
    res_cid, out_mssg, updated_context = ray.get(
  File "/home/abdenour/.local/lib/python3.10/site-packages/ray/_private/auto_init_hook.py", line 21, in auto_init_wrapper
    return fn(*args, **kwargs)
  File "/home/abdenour/.local/lib/python3.10/site-packages/ray/_private/client_mode_hook.py", line 103, in wrapper
    return func(*args, **kwargs)
  File "/home/abdenour/.local/lib/python3.10/site-packages/ray/_private/worker.py", line 2667, in get
    values, debugger_breakpoint = worker.get_objects(object_refs, timeout=timeout)
  File "/home/abdenour/.local/lib/python3.10/site-packages/ray/_private/worker.py", line 864, in get_objects
    raise value.as_instanceof_cause()
ray.exceptions.RayTaskError(ClientAppException): [36mray::ClientAppActor.run()[39m (pid=2426095, ip=115.145.172.224, actor_id=c630370c3b42bbca740ca2f401000000, repr=<flwr.simulation.ray_transport.ray_actor.ClientAppActor object at 0x7fc62078d720>)
  File "/home/abdenour/.local/lib/python3.10/site-packages/flwr/client/client_app.py", line 143, in __call__
    return self._call(message, context)
  File "/home/abdenour/.local/lib/python3.10/site-packages/flwr/client/client_app.py", line 126, in ffn
    out_message = handle_legacy_message_from_msgtype(
  File "/home/abdenour/.local/lib/python3.10/site-packages/flwr/client/message_handler/message_handler.py", line 95, in handle_legacy_message_from_msgtype
    client = client_fn(context)
  File "/home/abdenour/fl_with_flower/fednova_vgg16/fednova_vgg16/client.py", line 129, in client_fn
    return FlowerClient(trainset, valset, num_classes, config_fit, client_dataset_ratio, context.node_config).to_client()
  File "/home/abdenour/fl_with_flower/fednova_vgg16/fednova_vgg16/client.py", line 36, in __init__
    self.model = self.model.to(self.device)
  File "/home/abdenour/anaconda3/envs/fl/lib/python3.10/site-packages/torch/nn/modules/module.py", line 1174, in to
    return self._apply(convert)
  File "/home/abdenour/anaconda3/envs/fl/lib/python3.10/site-packages/torch/nn/modules/module.py", line 780, in _apply
    module._apply(fn)
  File "/home/abdenour/anaconda3/envs/fl/lib/python3.10/site-packages/torch/nn/modules/module.py", line 780, in _apply
    module._apply(fn)
  File "/home/abdenour/anaconda3/envs/fl/lib/python3.10/site-packages/torch/nn/modules/module.py", line 805, in _apply
    param_applied = fn(param)
  File "/home/abdenour/anaconda3/envs/fl/lib/python3.10/site-packages/torch/nn/modules/module.py", line 1160, in convert
    return t.to(
RuntimeError: CUDA error: out of memory
CUDA kernel errors might be asynchronously reported at some other API call, so the stacktrace below might be incorrect.
For debugging consider passing CUDA_LAUNCH_BLOCKING=1
Compile with `TORCH_USE_CUDA_DSA` to enable device-side assertions.


The above exception was the direct cause of the following exception:

[36mray::ClientAppActor.run()[39m (pid=2426095, ip=115.145.172.224, actor_id=c630370c3b42bbca740ca2f401000000, repr=<flwr.simulation.ray_transport.ray_actor.ClientAppActor object at 0x7fc62078d720>)
  File "/home/abdenour/.local/lib/python3.10/site-packages/flwr/simulation/ray_transport/ray_actor.py", line 63, in run
    raise ClientAppException(str(ex)) from ex
flwr.client.client_app.ClientAppException: 
Exception ClientAppException occurred. Message: CUDA error: out of memory
CUDA kernel errors might be asynchronously reported at some other API call, so the stacktrace below might be incorrect.
For debugging consider passing CUDA_LAUNCH_BLOCKING=1
Compile with `TORCH_USE_CUDA_DSA` to enable device-side assertions.

[2024-09-19 01:30:53,966][flwr][ERROR] - [36mray::ClientAppActor.run()[39m (pid=2426095, ip=115.145.172.224, actor_id=c630370c3b42bbca740ca2f401000000, repr=<flwr.simulation.ray_transport.ray_actor.ClientAppActor object at 0x7fc62078d720>)
  File "/home/abdenour/.local/lib/python3.10/site-packages/flwr/client/client_app.py", line 143, in __call__
    return self._call(message, context)
  File "/home/abdenour/.local/lib/python3.10/site-packages/flwr/client/client_app.py", line 126, in ffn
    out_message = handle_legacy_message_from_msgtype(
  File "/home/abdenour/.local/lib/python3.10/site-packages/flwr/client/message_handler/message_handler.py", line 95, in handle_legacy_message_from_msgtype
    client = client_fn(context)
  File "/home/abdenour/fl_with_flower/fednova_vgg16/fednova_vgg16/client.py", line 129, in client_fn
    return FlowerClient(trainset, valset, num_classes, config_fit, client_dataset_ratio, context.node_config).to_client()
  File "/home/abdenour/fl_with_flower/fednova_vgg16/fednova_vgg16/client.py", line 36, in __init__
    self.model = self.model.to(self.device)
  File "/home/abdenour/anaconda3/envs/fl/lib/python3.10/site-packages/torch/nn/modules/module.py", line 1174, in to
    return self._apply(convert)
  File "/home/abdenour/anaconda3/envs/fl/lib/python3.10/site-packages/torch/nn/modules/module.py", line 780, in _apply
    module._apply(fn)
  File "/home/abdenour/anaconda3/envs/fl/lib/python3.10/site-packages/torch/nn/modules/module.py", line 780, in _apply
    module._apply(fn)
  File "/home/abdenour/anaconda3/envs/fl/lib/python3.10/site-packages/torch/nn/modules/module.py", line 805, in _apply
    param_applied = fn(param)
  File "/home/abdenour/anaconda3/envs/fl/lib/python3.10/site-packages/torch/nn/modules/module.py", line 1160, in convert
    return t.to(
RuntimeError: CUDA error: out of memory
CUDA kernel errors might be asynchronously reported at some other API call, so the stacktrace below might be incorrect.
For debugging consider passing CUDA_LAUNCH_BLOCKING=1
Compile with `TORCH_USE_CUDA_DSA` to enable device-side assertions.


The above exception was the direct cause of the following exception:

[36mray::ClientAppActor.run()[39m (pid=2426095, ip=115.145.172.224, actor_id=c630370c3b42bbca740ca2f401000000, repr=<flwr.simulation.ray_transport.ray_actor.ClientAppActor object at 0x7fc62078d720>)
  File "/home/abdenour/.local/lib/python3.10/site-packages/flwr/simulation/ray_transport/ray_actor.py", line 63, in run
    raise ClientAppException(str(ex)) from ex
flwr.client.client_app.ClientAppException: 
Exception ClientAppException occurred. Message: CUDA error: out of memory
CUDA kernel errors might be asynchronously reported at some other API call, so the stacktrace below might be incorrect.
For debugging consider passing CUDA_LAUNCH_BLOCKING=1
Compile with `TORCH_USE_CUDA_DSA` to enable device-side assertions.
[2024-09-19 01:30:54,530][flwr][ERROR] - Traceback (most recent call last):
  File "/home/abdenour/.local/lib/python3.10/site-packages/flwr/simulation/ray_transport/ray_client_proxy.py", line 94, in _submit_job
    out_mssg, updated_context = self.actor_pool.get_client_result(
  File "/home/abdenour/.local/lib/python3.10/site-packages/flwr/simulation/ray_transport/ray_actor.py", line 398, in get_client_result
    return self._fetch_future_result(cid)
  File "/home/abdenour/.local/lib/python3.10/site-packages/flwr/simulation/ray_transport/ray_actor.py", line 279, in _fetch_future_result
    res_cid, out_mssg, updated_context = ray.get(
  File "/home/abdenour/.local/lib/python3.10/site-packages/ray/_private/auto_init_hook.py", line 21, in auto_init_wrapper
    return fn(*args, **kwargs)
  File "/home/abdenour/.local/lib/python3.10/site-packages/ray/_private/client_mode_hook.py", line 103, in wrapper
    return func(*args, **kwargs)
  File "/home/abdenour/.local/lib/python3.10/site-packages/ray/_private/worker.py", line 2667, in get
    values, debugger_breakpoint = worker.get_objects(object_refs, timeout=timeout)
  File "/home/abdenour/.local/lib/python3.10/site-packages/ray/_private/worker.py", line 864, in get_objects
    raise value.as_instanceof_cause()
ray.exceptions.RayTaskError(ClientAppException): [36mray::ClientAppActor.run()[39m (pid=2426094, ip=115.145.172.224, actor_id=4a42e340aa567aa4a80ff6d401000000, repr=<flwr.simulation.ray_transport.ray_actor.ClientAppActor object at 0x7f0044179750>)
  File "/home/abdenour/.local/lib/python3.10/site-packages/flwr/client/client_app.py", line 143, in __call__
    return self._call(message, context)
  File "/home/abdenour/.local/lib/python3.10/site-packages/flwr/client/client_app.py", line 126, in ffn
    out_message = handle_legacy_message_from_msgtype(
  File "/home/abdenour/.local/lib/python3.10/site-packages/flwr/client/message_handler/message_handler.py", line 95, in handle_legacy_message_from_msgtype
    client = client_fn(context)
  File "/home/abdenour/fl_with_flower/fednova_vgg16/fednova_vgg16/client.py", line 129, in client_fn
    return FlowerClient(trainset, valset, num_classes, config_fit, client_dataset_ratio, context.node_config).to_client()
  File "/home/abdenour/fl_with_flower/fednova_vgg16/fednova_vgg16/client.py", line 36, in __init__
    self.model = self.model.to(self.device)
  File "/home/abdenour/anaconda3/envs/fl/lib/python3.10/site-packages/torch/nn/modules/module.py", line 1174, in to
    return self._apply(convert)
  File "/home/abdenour/anaconda3/envs/fl/lib/python3.10/site-packages/torch/nn/modules/module.py", line 780, in _apply
    module._apply(fn)
  File "/home/abdenour/anaconda3/envs/fl/lib/python3.10/site-packages/torch/nn/modules/module.py", line 780, in _apply
    module._apply(fn)
  File "/home/abdenour/anaconda3/envs/fl/lib/python3.10/site-packages/torch/nn/modules/module.py", line 805, in _apply
    param_applied = fn(param)
  File "/home/abdenour/anaconda3/envs/fl/lib/python3.10/site-packages/torch/nn/modules/module.py", line 1160, in convert
    return t.to(
RuntimeError: CUDA error: out of memory
CUDA kernel errors might be asynchronously reported at some other API call, so the stacktrace below might be incorrect.
For debugging consider passing CUDA_LAUNCH_BLOCKING=1
Compile with `TORCH_USE_CUDA_DSA` to enable device-side assertions.


The above exception was the direct cause of the following exception:

[36mray::ClientAppActor.run()[39m (pid=2426094, ip=115.145.172.224, actor_id=4a42e340aa567aa4a80ff6d401000000, repr=<flwr.simulation.ray_transport.ray_actor.ClientAppActor object at 0x7f0044179750>)
  File "/home/abdenour/.local/lib/python3.10/site-packages/flwr/simulation/ray_transport/ray_actor.py", line 63, in run
    raise ClientAppException(str(ex)) from ex
flwr.client.client_app.ClientAppException: 
Exception ClientAppException occurred. Message: CUDA error: out of memory
CUDA kernel errors might be asynchronously reported at some other API call, so the stacktrace below might be incorrect.
For debugging consider passing CUDA_LAUNCH_BLOCKING=1
Compile with `TORCH_USE_CUDA_DSA` to enable device-side assertions.

[2024-09-19 01:30:54,531][flwr][ERROR] - [36mray::ClientAppActor.run()[39m (pid=2426094, ip=115.145.172.224, actor_id=4a42e340aa567aa4a80ff6d401000000, repr=<flwr.simulation.ray_transport.ray_actor.ClientAppActor object at 0x7f0044179750>)
  File "/home/abdenour/.local/lib/python3.10/site-packages/flwr/client/client_app.py", line 143, in __call__
    return self._call(message, context)
  File "/home/abdenour/.local/lib/python3.10/site-packages/flwr/client/client_app.py", line 126, in ffn
    out_message = handle_legacy_message_from_msgtype(
  File "/home/abdenour/.local/lib/python3.10/site-packages/flwr/client/message_handler/message_handler.py", line 95, in handle_legacy_message_from_msgtype
    client = client_fn(context)
  File "/home/abdenour/fl_with_flower/fednova_vgg16/fednova_vgg16/client.py", line 129, in client_fn
    return FlowerClient(trainset, valset, num_classes, config_fit, client_dataset_ratio, context.node_config).to_client()
  File "/home/abdenour/fl_with_flower/fednova_vgg16/fednova_vgg16/client.py", line 36, in __init__
    self.model = self.model.to(self.device)
  File "/home/abdenour/anaconda3/envs/fl/lib/python3.10/site-packages/torch/nn/modules/module.py", line 1174, in to
    return self._apply(convert)
  File "/home/abdenour/anaconda3/envs/fl/lib/python3.10/site-packages/torch/nn/modules/module.py", line 780, in _apply
    module._apply(fn)
  File "/home/abdenour/anaconda3/envs/fl/lib/python3.10/site-packages/torch/nn/modules/module.py", line 780, in _apply
    module._apply(fn)
  File "/home/abdenour/anaconda3/envs/fl/lib/python3.10/site-packages/torch/nn/modules/module.py", line 805, in _apply
    param_applied = fn(param)
  File "/home/abdenour/anaconda3/envs/fl/lib/python3.10/site-packages/torch/nn/modules/module.py", line 1160, in convert
    return t.to(
RuntimeError: CUDA error: out of memory
CUDA kernel errors might be asynchronously reported at some other API call, so the stacktrace below might be incorrect.
For debugging consider passing CUDA_LAUNCH_BLOCKING=1
Compile with `TORCH_USE_CUDA_DSA` to enable device-side assertions.


The above exception was the direct cause of the following exception:

[36mray::ClientAppActor.run()[39m (pid=2426094, ip=115.145.172.224, actor_id=4a42e340aa567aa4a80ff6d401000000, repr=<flwr.simulation.ray_transport.ray_actor.ClientAppActor object at 0x7f0044179750>)
  File "/home/abdenour/.local/lib/python3.10/site-packages/flwr/simulation/ray_transport/ray_actor.py", line 63, in run
    raise ClientAppException(str(ex)) from ex
flwr.client.client_app.ClientAppException: 
Exception ClientAppException occurred. Message: CUDA error: out of memory
CUDA kernel errors might be asynchronously reported at some other API call, so the stacktrace below might be incorrect.
For debugging consider passing CUDA_LAUNCH_BLOCKING=1
Compile with `TORCH_USE_CUDA_DSA` to enable device-side assertions.
[2024-09-19 01:30:55,767][flwr][ERROR] - Traceback (most recent call last):
  File "/home/abdenour/.local/lib/python3.10/site-packages/flwr/simulation/ray_transport/ray_client_proxy.py", line 94, in _submit_job
    out_mssg, updated_context = self.actor_pool.get_client_result(
  File "/home/abdenour/.local/lib/python3.10/site-packages/flwr/simulation/ray_transport/ray_actor.py", line 398, in get_client_result
    return self._fetch_future_result(cid)
  File "/home/abdenour/.local/lib/python3.10/site-packages/flwr/simulation/ray_transport/ray_actor.py", line 279, in _fetch_future_result
    res_cid, out_mssg, updated_context = ray.get(
  File "/home/abdenour/.local/lib/python3.10/site-packages/ray/_private/auto_init_hook.py", line 21, in auto_init_wrapper
    return fn(*args, **kwargs)
  File "/home/abdenour/.local/lib/python3.10/site-packages/ray/_private/client_mode_hook.py", line 103, in wrapper
    return func(*args, **kwargs)
  File "/home/abdenour/.local/lib/python3.10/site-packages/ray/_private/worker.py", line 2667, in get
    values, debugger_breakpoint = worker.get_objects(object_refs, timeout=timeout)
  File "/home/abdenour/.local/lib/python3.10/site-packages/ray/_private/worker.py", line 864, in get_objects
    raise value.as_instanceof_cause()
ray.exceptions.RayTaskError(ClientAppException): [36mray::ClientAppActor.run()[39m (pid=2426096, ip=115.145.172.224, actor_id=82017147e17b846cf810e85f01000000, repr=<flwr.simulation.ray_transport.ray_actor.ClientAppActor object at 0x7fd01c585780>)
  File "/home/abdenour/.local/lib/python3.10/site-packages/flwr/client/client_app.py", line 143, in __call__
    return self._call(message, context)
  File "/home/abdenour/.local/lib/python3.10/site-packages/flwr/client/client_app.py", line 126, in ffn
    out_message = handle_legacy_message_from_msgtype(
  File "/home/abdenour/.local/lib/python3.10/site-packages/flwr/client/message_handler/message_handler.py", line 95, in handle_legacy_message_from_msgtype
    client = client_fn(context)
  File "/home/abdenour/fl_with_flower/fednova_vgg16/fednova_vgg16/client.py", line 129, in client_fn
    return FlowerClient(trainset, valset, num_classes, config_fit, client_dataset_ratio, context.node_config).to_client()
  File "/home/abdenour/fl_with_flower/fednova_vgg16/fednova_vgg16/client.py", line 36, in __init__
    self.model = self.model.to(self.device)
  File "/home/abdenour/anaconda3/envs/fl/lib/python3.10/site-packages/torch/nn/modules/module.py", line 1174, in to
    return self._apply(convert)
  File "/home/abdenour/anaconda3/envs/fl/lib/python3.10/site-packages/torch/nn/modules/module.py", line 780, in _apply
    module._apply(fn)
  File "/home/abdenour/anaconda3/envs/fl/lib/python3.10/site-packages/torch/nn/modules/module.py", line 780, in _apply
    module._apply(fn)
  File "/home/abdenour/anaconda3/envs/fl/lib/python3.10/site-packages/torch/nn/modules/module.py", line 805, in _apply
    param_applied = fn(param)
  File "/home/abdenour/anaconda3/envs/fl/lib/python3.10/site-packages/torch/nn/modules/module.py", line 1160, in convert
    return t.to(
RuntimeError: CUDA error: out of memory
CUDA kernel errors might be asynchronously reported at some other API call, so the stacktrace below might be incorrect.
For debugging consider passing CUDA_LAUNCH_BLOCKING=1
Compile with `TORCH_USE_CUDA_DSA` to enable device-side assertions.


The above exception was the direct cause of the following exception:

[36mray::ClientAppActor.run()[39m (pid=2426096, ip=115.145.172.224, actor_id=82017147e17b846cf810e85f01000000, repr=<flwr.simulation.ray_transport.ray_actor.ClientAppActor object at 0x7fd01c585780>)
  File "/home/abdenour/.local/lib/python3.10/site-packages/flwr/simulation/ray_transport/ray_actor.py", line 63, in run
    raise ClientAppException(str(ex)) from ex
flwr.client.client_app.ClientAppException: 
Exception ClientAppException occurred. Message: CUDA error: out of memory
CUDA kernel errors might be asynchronously reported at some other API call, so the stacktrace below might be incorrect.
For debugging consider passing CUDA_LAUNCH_BLOCKING=1
Compile with `TORCH_USE_CUDA_DSA` to enable device-side assertions.

[2024-09-19 01:30:55,767][flwr][ERROR] - [36mray::ClientAppActor.run()[39m (pid=2426096, ip=115.145.172.224, actor_id=82017147e17b846cf810e85f01000000, repr=<flwr.simulation.ray_transport.ray_actor.ClientAppActor object at 0x7fd01c585780>)
  File "/home/abdenour/.local/lib/python3.10/site-packages/flwr/client/client_app.py", line 143, in __call__
    return self._call(message, context)
  File "/home/abdenour/.local/lib/python3.10/site-packages/flwr/client/client_app.py", line 126, in ffn
    out_message = handle_legacy_message_from_msgtype(
  File "/home/abdenour/.local/lib/python3.10/site-packages/flwr/client/message_handler/message_handler.py", line 95, in handle_legacy_message_from_msgtype
    client = client_fn(context)
  File "/home/abdenour/fl_with_flower/fednova_vgg16/fednova_vgg16/client.py", line 129, in client_fn
    return FlowerClient(trainset, valset, num_classes, config_fit, client_dataset_ratio, context.node_config).to_client()
  File "/home/abdenour/fl_with_flower/fednova_vgg16/fednova_vgg16/client.py", line 36, in __init__
    self.model = self.model.to(self.device)
  File "/home/abdenour/anaconda3/envs/fl/lib/python3.10/site-packages/torch/nn/modules/module.py", line 1174, in to
    return self._apply(convert)
  File "/home/abdenour/anaconda3/envs/fl/lib/python3.10/site-packages/torch/nn/modules/module.py", line 780, in _apply
    module._apply(fn)
  File "/home/abdenour/anaconda3/envs/fl/lib/python3.10/site-packages/torch/nn/modules/module.py", line 780, in _apply
    module._apply(fn)
  File "/home/abdenour/anaconda3/envs/fl/lib/python3.10/site-packages/torch/nn/modules/module.py", line 805, in _apply
    param_applied = fn(param)
  File "/home/abdenour/anaconda3/envs/fl/lib/python3.10/site-packages/torch/nn/modules/module.py", line 1160, in convert
    return t.to(
RuntimeError: CUDA error: out of memory
CUDA kernel errors might be asynchronously reported at some other API call, so the stacktrace below might be incorrect.
For debugging consider passing CUDA_LAUNCH_BLOCKING=1
Compile with `TORCH_USE_CUDA_DSA` to enable device-side assertions.


The above exception was the direct cause of the following exception:

[36mray::ClientAppActor.run()[39m (pid=2426096, ip=115.145.172.224, actor_id=82017147e17b846cf810e85f01000000, repr=<flwr.simulation.ray_transport.ray_actor.ClientAppActor object at 0x7fd01c585780>)
  File "/home/abdenour/.local/lib/python3.10/site-packages/flwr/simulation/ray_transport/ray_actor.py", line 63, in run
    raise ClientAppException(str(ex)) from ex
flwr.client.client_app.ClientAppException: 
Exception ClientAppException occurred. Message: CUDA error: out of memory
CUDA kernel errors might be asynchronously reported at some other API call, so the stacktrace below might be incorrect.
For debugging consider passing CUDA_LAUNCH_BLOCKING=1
Compile with `TORCH_USE_CUDA_DSA` to enable device-side assertions.
[2024-09-19 01:30:55,768][flwr][INFO] - aggregate_fit: received 1 results and 4 failures
[2024-09-19 01:30:56,256][flwr][WARNING] - No fit_metrics_aggregation_fn provided
