[2024-09-19 01:31:41,182][flwr][INFO] - Starting Flower simulation, config: num_rounds=100, no round_timeout
[2024-09-19 01:31:44,434][flwr][INFO] - Flower VCE: Ray initialized with resources: {'CPU': 256.0, 'memory': 150279645389.0, 'node:__internal_head__': 1.0, 'object_store_memory': 68691276595.0, 'node:115.145.172.224': 1.0, 'GPU': 1.0, 'accelerator_type:G': 1.0}
[2024-09-19 01:31:44,434][flwr][INFO] - Optimize your simulation with Flower VCE: https://flower.ai/docs/framework/how-to-run-simulations.html
[2024-09-19 01:31:44,434][flwr][INFO] - Flower VCE: Resources for each Virtual Client: {'num_cpus': 64, 'num_gpus': 0.25}
[2024-09-19 01:31:44,446][flwr][INFO] - Flower VCE: Creating VirtualClientEngineActorPool with 4 actors
[2024-09-19 01:31:44,447][flwr][INFO] - [INIT]
[2024-09-19 01:31:44,447][flwr][INFO] - Requesting initial parameters from one random client
[2024-09-19 01:31:51,768][flwr][INFO] - Received initial parameters from one random client
[2024-09-19 01:31:51,768][flwr][INFO] - Evaluating initial global parameters
[2024-09-19 01:32:05,827][flwr][INFO] - initial parameters (loss, other metrics): 227.2936887741089, {'accuracy': 0.12715580239695995}
[2024-09-19 01:32:05,827][flwr][INFO] - 
[2024-09-19 01:32:05,827][flwr][INFO] - [ROUND 1]
[2024-09-19 01:32:05,827][flwr][INFO] - configure_fit: strategy sampled 5 clients (out of 50)
[2024-09-19 01:32:13,779][flwr][ERROR] - Traceback (most recent call last):
  File "/home/abdenour/.local/lib/python3.10/site-packages/flwr/simulation/ray_transport/ray_client_proxy.py", line 94, in _submit_job
    out_mssg, updated_context = self.actor_pool.get_client_result(
  File "/home/abdenour/.local/lib/python3.10/site-packages/flwr/simulation/ray_transport/ray_actor.py", line 398, in get_client_result
    return self._fetch_future_result(cid)
  File "/home/abdenour/.local/lib/python3.10/site-packages/flwr/simulation/ray_transport/ray_actor.py", line 279, in _fetch_future_result
    res_cid, out_mssg, updated_context = ray.get(
  File "/home/abdenour/.local/lib/python3.10/site-packages/ray/_private/auto_init_hook.py", line 21, in auto_init_wrapper
    return fn(*args, **kwargs)
  File "/home/abdenour/.local/lib/python3.10/site-packages/ray/_private/client_mode_hook.py", line 103, in wrapper
    return func(*args, **kwargs)
  File "/home/abdenour/.local/lib/python3.10/site-packages/ray/_private/worker.py", line 2667, in get
    values, debugger_breakpoint = worker.get_objects(object_refs, timeout=timeout)
  File "/home/abdenour/.local/lib/python3.10/site-packages/ray/_private/worker.py", line 864, in get_objects
    raise value.as_instanceof_cause()
ray.exceptions.RayTaskError(ClientAppException): [36mray::ClientAppActor.run()[39m (pid=2457609, ip=115.145.172.224, actor_id=85989a3f5d1196247876e93b01000000, repr=<flwr.simulation.ray_transport.ray_actor.ClientAppActor object at 0x7f66a419d7b0>)
  File "/home/abdenour/.local/lib/python3.10/site-packages/flwr/client/client_app.py", line 143, in __call__
    return self._call(message, context)
  File "/home/abdenour/.local/lib/python3.10/site-packages/flwr/client/client_app.py", line 126, in ffn
    out_message = handle_legacy_message_from_msgtype(
  File "/home/abdenour/.local/lib/python3.10/site-packages/flwr/client/message_handler/message_handler.py", line 95, in handle_legacy_message_from_msgtype
    client = client_fn(context)
  File "/home/abdenour/fl_with_flower/fednova_vgg16/fednova_vgg16/client.py", line 129, in client_fn
    return FlowerClient(trainset, valset, num_classes, config_fit, client_dataset_ratio, context.node_config).to_client()
  File "/home/abdenour/fl_with_flower/fednova_vgg16/fednova_vgg16/client.py", line 36, in __init__
    self.model = self.model.to(self.device)
  File "/home/abdenour/anaconda3/envs/fl/lib/python3.10/site-packages/torch/nn/modules/module.py", line 1174, in to
    return self._apply(convert)
  File "/home/abdenour/anaconda3/envs/fl/lib/python3.10/site-packages/torch/nn/modules/module.py", line 780, in _apply
    module._apply(fn)
  File "/home/abdenour/anaconda3/envs/fl/lib/python3.10/site-packages/torch/nn/modules/module.py", line 780, in _apply
    module._apply(fn)
  File "/home/abdenour/anaconda3/envs/fl/lib/python3.10/site-packages/torch/nn/modules/module.py", line 805, in _apply
    param_applied = fn(param)
  File "/home/abdenour/anaconda3/envs/fl/lib/python3.10/site-packages/torch/nn/modules/module.py", line 1160, in convert
    return t.to(
torch.OutOfMemoryError: CUDA out of memory. Tried to allocate 392.00 MiB. GPU 0 has a total capacity of 47.33 GiB of which 284.12 MiB is free. Process 2279413 has 11.11 GiB memory in use. Process 2265701 has 2.37 GiB memory in use. Process 2279412 has 11.11 GiB memory in use. Process 2457611 has 11.11 GiB memory in use. Process 2443889 has 2.37 GiB memory in use. Process 2457610 has 8.61 GiB memory in use. Including non-PyTorch memory, this process has 322.00 MiB memory in use. Of the allocated memory 57.01 MiB is allocated by PyTorch, and 4.99 MiB is reserved by PyTorch but unallocated. If reserved but unallocated memory is large try setting PYTORCH_CUDA_ALLOC_CONF=expandable_segments:True to avoid fragmentation.  See documentation for Memory Management  (https://pytorch.org/docs/stable/notes/cuda.html#environment-variables)

The above exception was the direct cause of the following exception:

[36mray::ClientAppActor.run()[39m (pid=2457609, ip=115.145.172.224, actor_id=85989a3f5d1196247876e93b01000000, repr=<flwr.simulation.ray_transport.ray_actor.ClientAppActor object at 0x7f66a419d7b0>)
  File "/home/abdenour/.local/lib/python3.10/site-packages/flwr/simulation/ray_transport/ray_actor.py", line 63, in run
    raise ClientAppException(str(ex)) from ex
flwr.client.client_app.ClientAppException: 
Exception ClientAppException occurred. Message: CUDA out of memory. Tried to allocate 392.00 MiB. GPU 0 has a total capacity of 47.33 GiB of which 284.12 MiB is free. Process 2279413 has 11.11 GiB memory in use. Process 2265701 has 2.37 GiB memory in use. Process 2279412 has 11.11 GiB memory in use. Process 2457611 has 11.11 GiB memory in use. Process 2443889 has 2.37 GiB memory in use. Process 2457610 has 8.61 GiB memory in use. Including non-PyTorch memory, this process has 322.00 MiB memory in use. Of the allocated memory 57.01 MiB is allocated by PyTorch, and 4.99 MiB is reserved by PyTorch but unallocated. If reserved but unallocated memory is large try setting PYTORCH_CUDA_ALLOC_CONF=expandable_segments:True to avoid fragmentation.  See documentation for Memory Management  (https://pytorch.org/docs/stable/notes/cuda.html#environment-variables)

[2024-09-19 01:32:13,779][flwr][ERROR] - [36mray::ClientAppActor.run()[39m (pid=2457609, ip=115.145.172.224, actor_id=85989a3f5d1196247876e93b01000000, repr=<flwr.simulation.ray_transport.ray_actor.ClientAppActor object at 0x7f66a419d7b0>)
  File "/home/abdenour/.local/lib/python3.10/site-packages/flwr/client/client_app.py", line 143, in __call__
    return self._call(message, context)
  File "/home/abdenour/.local/lib/python3.10/site-packages/flwr/client/client_app.py", line 126, in ffn
    out_message = handle_legacy_message_from_msgtype(
  File "/home/abdenour/.local/lib/python3.10/site-packages/flwr/client/message_handler/message_handler.py", line 95, in handle_legacy_message_from_msgtype
    client = client_fn(context)
  File "/home/abdenour/fl_with_flower/fednova_vgg16/fednova_vgg16/client.py", line 129, in client_fn
    return FlowerClient(trainset, valset, num_classes, config_fit, client_dataset_ratio, context.node_config).to_client()
  File "/home/abdenour/fl_with_flower/fednova_vgg16/fednova_vgg16/client.py", line 36, in __init__
    self.model = self.model.to(self.device)
  File "/home/abdenour/anaconda3/envs/fl/lib/python3.10/site-packages/torch/nn/modules/module.py", line 1174, in to
    return self._apply(convert)
  File "/home/abdenour/anaconda3/envs/fl/lib/python3.10/site-packages/torch/nn/modules/module.py", line 780, in _apply
    module._apply(fn)
  File "/home/abdenour/anaconda3/envs/fl/lib/python3.10/site-packages/torch/nn/modules/module.py", line 780, in _apply
    module._apply(fn)
  File "/home/abdenour/anaconda3/envs/fl/lib/python3.10/site-packages/torch/nn/modules/module.py", line 805, in _apply
    param_applied = fn(param)
  File "/home/abdenour/anaconda3/envs/fl/lib/python3.10/site-packages/torch/nn/modules/module.py", line 1160, in convert
    return t.to(
torch.OutOfMemoryError: CUDA out of memory. Tried to allocate 392.00 MiB. GPU 0 has a total capacity of 47.33 GiB of which 284.12 MiB is free. Process 2279413 has 11.11 GiB memory in use. Process 2265701 has 2.37 GiB memory in use. Process 2279412 has 11.11 GiB memory in use. Process 2457611 has 11.11 GiB memory in use. Process 2443889 has 2.37 GiB memory in use. Process 2457610 has 8.61 GiB memory in use. Including non-PyTorch memory, this process has 322.00 MiB memory in use. Of the allocated memory 57.01 MiB is allocated by PyTorch, and 4.99 MiB is reserved by PyTorch but unallocated. If reserved but unallocated memory is large try setting PYTORCH_CUDA_ALLOC_CONF=expandable_segments:True to avoid fragmentation.  See documentation for Memory Management  (https://pytorch.org/docs/stable/notes/cuda.html#environment-variables)

The above exception was the direct cause of the following exception:

[36mray::ClientAppActor.run()[39m (pid=2457609, ip=115.145.172.224, actor_id=85989a3f5d1196247876e93b01000000, repr=<flwr.simulation.ray_transport.ray_actor.ClientAppActor object at 0x7f66a419d7b0>)
  File "/home/abdenour/.local/lib/python3.10/site-packages/flwr/simulation/ray_transport/ray_actor.py", line 63, in run
    raise ClientAppException(str(ex)) from ex
flwr.client.client_app.ClientAppException: 
Exception ClientAppException occurred. Message: CUDA out of memory. Tried to allocate 392.00 MiB. GPU 0 has a total capacity of 47.33 GiB of which 284.12 MiB is free. Process 2279413 has 11.11 GiB memory in use. Process 2265701 has 2.37 GiB memory in use. Process 2279412 has 11.11 GiB memory in use. Process 2457611 has 11.11 GiB memory in use. Process 2443889 has 2.37 GiB memory in use. Process 2457610 has 8.61 GiB memory in use. Including non-PyTorch memory, this process has 322.00 MiB memory in use. Of the allocated memory 57.01 MiB is allocated by PyTorch, and 4.99 MiB is reserved by PyTorch but unallocated. If reserved but unallocated memory is large try setting PYTORCH_CUDA_ALLOC_CONF=expandable_segments:True to avoid fragmentation.  See documentation for Memory Management  (https://pytorch.org/docs/stable/notes/cuda.html#environment-variables)
[2024-09-19 01:32:15,050][flwr][ERROR] - Traceback (most recent call last):
  File "/home/abdenour/.local/lib/python3.10/site-packages/flwr/simulation/ray_transport/ray_client_proxy.py", line 94, in _submit_job
    out_mssg, updated_context = self.actor_pool.get_client_result(
  File "/home/abdenour/.local/lib/python3.10/site-packages/flwr/simulation/ray_transport/ray_actor.py", line 398, in get_client_result
    return self._fetch_future_result(cid)
  File "/home/abdenour/.local/lib/python3.10/site-packages/flwr/simulation/ray_transport/ray_actor.py", line 279, in _fetch_future_result
    res_cid, out_mssg, updated_context = ray.get(
  File "/home/abdenour/.local/lib/python3.10/site-packages/ray/_private/auto_init_hook.py", line 21, in auto_init_wrapper
    return fn(*args, **kwargs)
  File "/home/abdenour/.local/lib/python3.10/site-packages/ray/_private/client_mode_hook.py", line 103, in wrapper
    return func(*args, **kwargs)
  File "/home/abdenour/.local/lib/python3.10/site-packages/ray/_private/worker.py", line 2667, in get
    values, debugger_breakpoint = worker.get_objects(object_refs, timeout=timeout)
  File "/home/abdenour/.local/lib/python3.10/site-packages/ray/_private/worker.py", line 864, in get_objects
    raise value.as_instanceof_cause()
ray.exceptions.RayTaskError(ClientAppException): [36mray::ClientAppActor.run()[39m (pid=2457608, ip=115.145.172.224, actor_id=4c290b3574534b722102b43101000000, repr=<flwr.simulation.ray_transport.ray_actor.ClientAppActor object at 0x7efcf017d780>)
  File "/home/abdenour/.local/lib/python3.10/site-packages/flwr/client/client_app.py", line 143, in __call__
    return self._call(message, context)
  File "/home/abdenour/.local/lib/python3.10/site-packages/flwr/client/client_app.py", line 126, in ffn
    out_message = handle_legacy_message_from_msgtype(
  File "/home/abdenour/.local/lib/python3.10/site-packages/flwr/client/message_handler/message_handler.py", line 95, in handle_legacy_message_from_msgtype
    client = client_fn(context)
  File "/home/abdenour/fl_with_flower/fednova_vgg16/fednova_vgg16/client.py", line 129, in client_fn
    return FlowerClient(trainset, valset, num_classes, config_fit, client_dataset_ratio, context.node_config).to_client()
  File "/home/abdenour/fl_with_flower/fednova_vgg16/fednova_vgg16/client.py", line 36, in __init__
    self.model = self.model.to(self.device)
  File "/home/abdenour/anaconda3/envs/fl/lib/python3.10/site-packages/torch/nn/modules/module.py", line 1174, in to
    return self._apply(convert)
  File "/home/abdenour/anaconda3/envs/fl/lib/python3.10/site-packages/torch/nn/modules/module.py", line 780, in _apply
    module._apply(fn)
  File "/home/abdenour/anaconda3/envs/fl/lib/python3.10/site-packages/torch/nn/modules/module.py", line 780, in _apply
    module._apply(fn)
  File "/home/abdenour/anaconda3/envs/fl/lib/python3.10/site-packages/torch/nn/modules/module.py", line 805, in _apply
    param_applied = fn(param)
  File "/home/abdenour/anaconda3/envs/fl/lib/python3.10/site-packages/torch/nn/modules/module.py", line 1160, in convert
    return t.to(
RuntimeError: CUDA error: out of memory
CUDA kernel errors might be asynchronously reported at some other API call, so the stacktrace below might be incorrect.
For debugging consider passing CUDA_LAUNCH_BLOCKING=1
Compile with `TORCH_USE_CUDA_DSA` to enable device-side assertions.


The above exception was the direct cause of the following exception:

[36mray::ClientAppActor.run()[39m (pid=2457608, ip=115.145.172.224, actor_id=4c290b3574534b722102b43101000000, repr=<flwr.simulation.ray_transport.ray_actor.ClientAppActor object at 0x7efcf017d780>)
  File "/home/abdenour/.local/lib/python3.10/site-packages/flwr/simulation/ray_transport/ray_actor.py", line 63, in run
    raise ClientAppException(str(ex)) from ex
flwr.client.client_app.ClientAppException: 
Exception ClientAppException occurred. Message: CUDA error: out of memory
CUDA kernel errors might be asynchronously reported at some other API call, so the stacktrace below might be incorrect.
For debugging consider passing CUDA_LAUNCH_BLOCKING=1
Compile with `TORCH_USE_CUDA_DSA` to enable device-side assertions.

[2024-09-19 01:32:15,050][flwr][ERROR] - [36mray::ClientAppActor.run()[39m (pid=2457608, ip=115.145.172.224, actor_id=4c290b3574534b722102b43101000000, repr=<flwr.simulation.ray_transport.ray_actor.ClientAppActor object at 0x7efcf017d780>)
  File "/home/abdenour/.local/lib/python3.10/site-packages/flwr/client/client_app.py", line 143, in __call__
    return self._call(message, context)
  File "/home/abdenour/.local/lib/python3.10/site-packages/flwr/client/client_app.py", line 126, in ffn
    out_message = handle_legacy_message_from_msgtype(
  File "/home/abdenour/.local/lib/python3.10/site-packages/flwr/client/message_handler/message_handler.py", line 95, in handle_legacy_message_from_msgtype
    client = client_fn(context)
  File "/home/abdenour/fl_with_flower/fednova_vgg16/fednova_vgg16/client.py", line 129, in client_fn
    return FlowerClient(trainset, valset, num_classes, config_fit, client_dataset_ratio, context.node_config).to_client()
  File "/home/abdenour/fl_with_flower/fednova_vgg16/fednova_vgg16/client.py", line 36, in __init__
    self.model = self.model.to(self.device)
  File "/home/abdenour/anaconda3/envs/fl/lib/python3.10/site-packages/torch/nn/modules/module.py", line 1174, in to
    return self._apply(convert)
  File "/home/abdenour/anaconda3/envs/fl/lib/python3.10/site-packages/torch/nn/modules/module.py", line 780, in _apply
    module._apply(fn)
  File "/home/abdenour/anaconda3/envs/fl/lib/python3.10/site-packages/torch/nn/modules/module.py", line 780, in _apply
    module._apply(fn)
  File "/home/abdenour/anaconda3/envs/fl/lib/python3.10/site-packages/torch/nn/modules/module.py", line 805, in _apply
    param_applied = fn(param)
  File "/home/abdenour/anaconda3/envs/fl/lib/python3.10/site-packages/torch/nn/modules/module.py", line 1160, in convert
    return t.to(
RuntimeError: CUDA error: out of memory
CUDA kernel errors might be asynchronously reported at some other API call, so the stacktrace below might be incorrect.
For debugging consider passing CUDA_LAUNCH_BLOCKING=1
Compile with `TORCH_USE_CUDA_DSA` to enable device-side assertions.


The above exception was the direct cause of the following exception:

[36mray::ClientAppActor.run()[39m (pid=2457608, ip=115.145.172.224, actor_id=4c290b3574534b722102b43101000000, repr=<flwr.simulation.ray_transport.ray_actor.ClientAppActor object at 0x7efcf017d780>)
  File "/home/abdenour/.local/lib/python3.10/site-packages/flwr/simulation/ray_transport/ray_actor.py", line 63, in run
    raise ClientAppException(str(ex)) from ex
flwr.client.client_app.ClientAppException: 
Exception ClientAppException occurred. Message: CUDA error: out of memory
CUDA kernel errors might be asynchronously reported at some other API call, so the stacktrace below might be incorrect.
For debugging consider passing CUDA_LAUNCH_BLOCKING=1
Compile with `TORCH_USE_CUDA_DSA` to enable device-side assertions.
[2024-09-19 01:32:21,241][flwr][INFO] - aggregate_fit: received 3 results and 2 failures
[2024-09-19 01:32:22,157][flwr][WARNING] - No fit_metrics_aggregation_fn provided
[2024-09-19 01:32:33,350][flwr][INFO] - fit progress: (1, 284.8904778957367, {'accuracy': 0.08301666179479684}, 27.52251266129315)
[2024-09-19 01:32:33,351][flwr][INFO] - configure_evaluate: strategy sampled 2 clients (out of 50)
[2024-09-19 01:32:37,172][flwr][INFO] - aggregate_evaluate: received 2 results and 0 failures
[2024-09-19 01:32:37,173][flwr][INFO] - 
[2024-09-19 01:32:37,173][flwr][INFO] - [ROUND 2]
[2024-09-19 01:32:37,173][flwr][INFO] - configure_fit: strategy sampled 5 clients (out of 50)
[2024-09-19 01:32:42,793][flwr][ERROR] - Traceback (most recent call last):
  File "/home/abdenour/.local/lib/python3.10/site-packages/flwr/simulation/ray_transport/ray_client_proxy.py", line 94, in _submit_job
    out_mssg, updated_context = self.actor_pool.get_client_result(
  File "/home/abdenour/.local/lib/python3.10/site-packages/flwr/simulation/ray_transport/ray_actor.py", line 398, in get_client_result
    return self._fetch_future_result(cid)
  File "/home/abdenour/.local/lib/python3.10/site-packages/flwr/simulation/ray_transport/ray_actor.py", line 279, in _fetch_future_result
    res_cid, out_mssg, updated_context = ray.get(
  File "/home/abdenour/.local/lib/python3.10/site-packages/ray/_private/auto_init_hook.py", line 21, in auto_init_wrapper
    return fn(*args, **kwargs)
  File "/home/abdenour/.local/lib/python3.10/site-packages/ray/_private/client_mode_hook.py", line 103, in wrapper
    return func(*args, **kwargs)
  File "/home/abdenour/.local/lib/python3.10/site-packages/ray/_private/worker.py", line 2667, in get
    values, debugger_breakpoint = worker.get_objects(object_refs, timeout=timeout)
  File "/home/abdenour/.local/lib/python3.10/site-packages/ray/_private/worker.py", line 864, in get_objects
    raise value.as_instanceof_cause()
ray.exceptions.RayTaskError(ClientAppException): [36mray::ClientAppActor.run()[39m (pid=2457608, ip=115.145.172.224, actor_id=4c290b3574534b722102b43101000000, repr=<flwr.simulation.ray_transport.ray_actor.ClientAppActor object at 0x7efcf017d780>)
  File "/home/abdenour/.local/lib/python3.10/site-packages/flwr/client/client_app.py", line 143, in __call__
    return self._call(message, context)
  File "/home/abdenour/.local/lib/python3.10/site-packages/flwr/client/client_app.py", line 126, in ffn
    out_message = handle_legacy_message_from_msgtype(
  File "/home/abdenour/.local/lib/python3.10/site-packages/flwr/client/message_handler/message_handler.py", line 95, in handle_legacy_message_from_msgtype
    client = client_fn(context)
  File "/home/abdenour/fl_with_flower/fednova_vgg16/fednova_vgg16/client.py", line 129, in client_fn
    return FlowerClient(trainset, valset, num_classes, config_fit, client_dataset_ratio, context.node_config).to_client()
  File "/home/abdenour/fl_with_flower/fednova_vgg16/fednova_vgg16/client.py", line 36, in __init__
    self.model = self.model.to(self.device)
  File "/home/abdenour/anaconda3/envs/fl/lib/python3.10/site-packages/torch/nn/modules/module.py", line 1174, in to
    return self._apply(convert)
  File "/home/abdenour/anaconda3/envs/fl/lib/python3.10/site-packages/torch/nn/modules/module.py", line 780, in _apply
    module._apply(fn)
  File "/home/abdenour/anaconda3/envs/fl/lib/python3.10/site-packages/torch/nn/modules/module.py", line 780, in _apply
    module._apply(fn)
  File "/home/abdenour/anaconda3/envs/fl/lib/python3.10/site-packages/torch/nn/modules/module.py", line 805, in _apply
    param_applied = fn(param)
  File "/home/abdenour/anaconda3/envs/fl/lib/python3.10/site-packages/torch/nn/modules/module.py", line 1160, in convert
    return t.to(
RuntimeError: CUDA error: out of memory
CUDA kernel errors might be asynchronously reported at some other API call, so the stacktrace below might be incorrect.
For debugging consider passing CUDA_LAUNCH_BLOCKING=1
Compile with `TORCH_USE_CUDA_DSA` to enable device-side assertions.


The above exception was the direct cause of the following exception:

[36mray::ClientAppActor.run()[39m (pid=2457608, ip=115.145.172.224, actor_id=4c290b3574534b722102b43101000000, repr=<flwr.simulation.ray_transport.ray_actor.ClientAppActor object at 0x7efcf017d780>)
  File "/home/abdenour/.local/lib/python3.10/site-packages/flwr/simulation/ray_transport/ray_actor.py", line 63, in run
    raise ClientAppException(str(ex)) from ex
flwr.client.client_app.ClientAppException: 
Exception ClientAppException occurred. Message: CUDA error: out of memory
CUDA kernel errors might be asynchronously reported at some other API call, so the stacktrace below might be incorrect.
For debugging consider passing CUDA_LAUNCH_BLOCKING=1
Compile with `TORCH_USE_CUDA_DSA` to enable device-side assertions.

[2024-09-19 01:32:42,793][flwr][ERROR] - Traceback (most recent call last):
  File "/home/abdenour/.local/lib/python3.10/site-packages/flwr/simulation/ray_transport/ray_client_proxy.py", line 94, in _submit_job
    out_mssg, updated_context = self.actor_pool.get_client_result(
  File "/home/abdenour/.local/lib/python3.10/site-packages/flwr/simulation/ray_transport/ray_actor.py", line 398, in get_client_result
    return self._fetch_future_result(cid)
  File "/home/abdenour/.local/lib/python3.10/site-packages/flwr/simulation/ray_transport/ray_actor.py", line 279, in _fetch_future_result
    res_cid, out_mssg, updated_context = ray.get(
  File "/home/abdenour/.local/lib/python3.10/site-packages/ray/_private/auto_init_hook.py", line 21, in auto_init_wrapper
    return fn(*args, **kwargs)
  File "/home/abdenour/.local/lib/python3.10/site-packages/ray/_private/client_mode_hook.py", line 103, in wrapper
    return func(*args, **kwargs)
  File "/home/abdenour/.local/lib/python3.10/site-packages/ray/_private/worker.py", line 2667, in get
    values, debugger_breakpoint = worker.get_objects(object_refs, timeout=timeout)
  File "/home/abdenour/.local/lib/python3.10/site-packages/ray/_private/worker.py", line 864, in get_objects
    raise value.as_instanceof_cause()
ray.exceptions.RayTaskError(ClientAppException): [36mray::ClientAppActor.run()[39m (pid=2457609, ip=115.145.172.224, actor_id=85989a3f5d1196247876e93b01000000, repr=<flwr.simulation.ray_transport.ray_actor.ClientAppActor object at 0x7f66a419d7b0>)
  File "/home/abdenour/.local/lib/python3.10/site-packages/flwr/client/client_app.py", line 143, in __call__
    return self._call(message, context)
  File "/home/abdenour/.local/lib/python3.10/site-packages/flwr/client/client_app.py", line 126, in ffn
    out_message = handle_legacy_message_from_msgtype(
  File "/home/abdenour/.local/lib/python3.10/site-packages/flwr/client/message_handler/message_handler.py", line 95, in handle_legacy_message_from_msgtype
    client = client_fn(context)
  File "/home/abdenour/fl_with_flower/fednova_vgg16/fednova_vgg16/client.py", line 129, in client_fn
    return FlowerClient(trainset, valset, num_classes, config_fit, client_dataset_ratio, context.node_config).to_client()
  File "/home/abdenour/fl_with_flower/fednova_vgg16/fednova_vgg16/client.py", line 36, in __init__
    self.model = self.model.to(self.device)
  File "/home/abdenour/anaconda3/envs/fl/lib/python3.10/site-packages/torch/nn/modules/module.py", line 1174, in to
    return self._apply(convert)
  File "/home/abdenour/anaconda3/envs/fl/lib/python3.10/site-packages/torch/nn/modules/module.py", line 780, in _apply
    module._apply(fn)
  File "/home/abdenour/anaconda3/envs/fl/lib/python3.10/site-packages/torch/nn/modules/module.py", line 780, in _apply
    module._apply(fn)
  File "/home/abdenour/anaconda3/envs/fl/lib/python3.10/site-packages/torch/nn/modules/module.py", line 805, in _apply
    param_applied = fn(param)
  File "/home/abdenour/anaconda3/envs/fl/lib/python3.10/site-packages/torch/nn/modules/module.py", line 1160, in convert
    return t.to(
torch.OutOfMemoryError: CUDA out of memory. Tried to allocate 392.00 MiB. GPU 0 has a total capacity of 47.33 GiB of which 258.12 MiB is free. Process 2279413 has 11.11 GiB memory in use. Process 2265701 has 2.37 GiB memory in use. Process 2279412 has 11.11 GiB memory in use. Process 2457611 has 11.11 GiB memory in use. Process 2443889 has 2.37 GiB memory in use. Process 2457610 has 8.64 GiB memory in use. Including non-PyTorch memory, this process has 322.00 MiB memory in use. Of the allocated memory 57.01 MiB is allocated by PyTorch, and 4.99 MiB is reserved by PyTorch but unallocated. If reserved but unallocated memory is large try setting PYTORCH_CUDA_ALLOC_CONF=expandable_segments:True to avoid fragmentation.  See documentation for Memory Management  (https://pytorch.org/docs/stable/notes/cuda.html#environment-variables)

The above exception was the direct cause of the following exception:

[36mray::ClientAppActor.run()[39m (pid=2457609, ip=115.145.172.224, actor_id=85989a3f5d1196247876e93b01000000, repr=<flwr.simulation.ray_transport.ray_actor.ClientAppActor object at 0x7f66a419d7b0>)
  File "/home/abdenour/.local/lib/python3.10/site-packages/flwr/simulation/ray_transport/ray_actor.py", line 63, in run
    raise ClientAppException(str(ex)) from ex
flwr.client.client_app.ClientAppException: 
Exception ClientAppException occurred. Message: CUDA out of memory. Tried to allocate 392.00 MiB. GPU 0 has a total capacity of 47.33 GiB of which 258.12 MiB is free. Process 2279413 has 11.11 GiB memory in use. Process 2265701 has 2.37 GiB memory in use. Process 2279412 has 11.11 GiB memory in use. Process 2457611 has 11.11 GiB memory in use. Process 2443889 has 2.37 GiB memory in use. Process 2457610 has 8.64 GiB memory in use. Including non-PyTorch memory, this process has 322.00 MiB memory in use. Of the allocated memory 57.01 MiB is allocated by PyTorch, and 4.99 MiB is reserved by PyTorch but unallocated. If reserved but unallocated memory is large try setting PYTORCH_CUDA_ALLOC_CONF=expandable_segments:True to avoid fragmentation.  See documentation for Memory Management  (https://pytorch.org/docs/stable/notes/cuda.html#environment-variables)

[2024-09-19 01:32:42,793][flwr][ERROR] - [36mray::ClientAppActor.run()[39m (pid=2457608, ip=115.145.172.224, actor_id=4c290b3574534b722102b43101000000, repr=<flwr.simulation.ray_transport.ray_actor.ClientAppActor object at 0x7efcf017d780>)
  File "/home/abdenour/.local/lib/python3.10/site-packages/flwr/client/client_app.py", line 143, in __call__
    return self._call(message, context)
  File "/home/abdenour/.local/lib/python3.10/site-packages/flwr/client/client_app.py", line 126, in ffn
    out_message = handle_legacy_message_from_msgtype(
  File "/home/abdenour/.local/lib/python3.10/site-packages/flwr/client/message_handler/message_handler.py", line 95, in handle_legacy_message_from_msgtype
    client = client_fn(context)
  File "/home/abdenour/fl_with_flower/fednova_vgg16/fednova_vgg16/client.py", line 129, in client_fn
    return FlowerClient(trainset, valset, num_classes, config_fit, client_dataset_ratio, context.node_config).to_client()
  File "/home/abdenour/fl_with_flower/fednova_vgg16/fednova_vgg16/client.py", line 36, in __init__
    self.model = self.model.to(self.device)
  File "/home/abdenour/anaconda3/envs/fl/lib/python3.10/site-packages/torch/nn/modules/module.py", line 1174, in to
    return self._apply(convert)
  File "/home/abdenour/anaconda3/envs/fl/lib/python3.10/site-packages/torch/nn/modules/module.py", line 780, in _apply
    module._apply(fn)
  File "/home/abdenour/anaconda3/envs/fl/lib/python3.10/site-packages/torch/nn/modules/module.py", line 780, in _apply
    module._apply(fn)
  File "/home/abdenour/anaconda3/envs/fl/lib/python3.10/site-packages/torch/nn/modules/module.py", line 805, in _apply
    param_applied = fn(param)
  File "/home/abdenour/anaconda3/envs/fl/lib/python3.10/site-packages/torch/nn/modules/module.py", line 1160, in convert
    return t.to(
RuntimeError: CUDA error: out of memory
CUDA kernel errors might be asynchronously reported at some other API call, so the stacktrace below might be incorrect.
For debugging consider passing CUDA_LAUNCH_BLOCKING=1
Compile with `TORCH_USE_CUDA_DSA` to enable device-side assertions.


The above exception was the direct cause of the following exception:

[36mray::ClientAppActor.run()[39m (pid=2457608, ip=115.145.172.224, actor_id=4c290b3574534b722102b43101000000, repr=<flwr.simulation.ray_transport.ray_actor.ClientAppActor object at 0x7efcf017d780>)
  File "/home/abdenour/.local/lib/python3.10/site-packages/flwr/simulation/ray_transport/ray_actor.py", line 63, in run
    raise ClientAppException(str(ex)) from ex
flwr.client.client_app.ClientAppException: 
Exception ClientAppException occurred. Message: CUDA error: out of memory
CUDA kernel errors might be asynchronously reported at some other API call, so the stacktrace below might be incorrect.
For debugging consider passing CUDA_LAUNCH_BLOCKING=1
Compile with `TORCH_USE_CUDA_DSA` to enable device-side assertions.
[2024-09-19 01:32:42,794][flwr][ERROR] - [36mray::ClientAppActor.run()[39m (pid=2457609, ip=115.145.172.224, actor_id=85989a3f5d1196247876e93b01000000, repr=<flwr.simulation.ray_transport.ray_actor.ClientAppActor object at 0x7f66a419d7b0>)
  File "/home/abdenour/.local/lib/python3.10/site-packages/flwr/client/client_app.py", line 143, in __call__
    return self._call(message, context)
  File "/home/abdenour/.local/lib/python3.10/site-packages/flwr/client/client_app.py", line 126, in ffn
    out_message = handle_legacy_message_from_msgtype(
  File "/home/abdenour/.local/lib/python3.10/site-packages/flwr/client/message_handler/message_handler.py", line 95, in handle_legacy_message_from_msgtype
    client = client_fn(context)
  File "/home/abdenour/fl_with_flower/fednova_vgg16/fednova_vgg16/client.py", line 129, in client_fn
    return FlowerClient(trainset, valset, num_classes, config_fit, client_dataset_ratio, context.node_config).to_client()
  File "/home/abdenour/fl_with_flower/fednova_vgg16/fednova_vgg16/client.py", line 36, in __init__
    self.model = self.model.to(self.device)
  File "/home/abdenour/anaconda3/envs/fl/lib/python3.10/site-packages/torch/nn/modules/module.py", line 1174, in to
    return self._apply(convert)
  File "/home/abdenour/anaconda3/envs/fl/lib/python3.10/site-packages/torch/nn/modules/module.py", line 780, in _apply
    module._apply(fn)
  File "/home/abdenour/anaconda3/envs/fl/lib/python3.10/site-packages/torch/nn/modules/module.py", line 780, in _apply
    module._apply(fn)
  File "/home/abdenour/anaconda3/envs/fl/lib/python3.10/site-packages/torch/nn/modules/module.py", line 805, in _apply
    param_applied = fn(param)
  File "/home/abdenour/anaconda3/envs/fl/lib/python3.10/site-packages/torch/nn/modules/module.py", line 1160, in convert
    return t.to(
torch.OutOfMemoryError: CUDA out of memory. Tried to allocate 392.00 MiB. GPU 0 has a total capacity of 47.33 GiB of which 258.12 MiB is free. Process 2279413 has 11.11 GiB memory in use. Process 2265701 has 2.37 GiB memory in use. Process 2279412 has 11.11 GiB memory in use. Process 2457611 has 11.11 GiB memory in use. Process 2443889 has 2.37 GiB memory in use. Process 2457610 has 8.64 GiB memory in use. Including non-PyTorch memory, this process has 322.00 MiB memory in use. Of the allocated memory 57.01 MiB is allocated by PyTorch, and 4.99 MiB is reserved by PyTorch but unallocated. If reserved but unallocated memory is large try setting PYTORCH_CUDA_ALLOC_CONF=expandable_segments:True to avoid fragmentation.  See documentation for Memory Management  (https://pytorch.org/docs/stable/notes/cuda.html#environment-variables)

The above exception was the direct cause of the following exception:

[36mray::ClientAppActor.run()[39m (pid=2457609, ip=115.145.172.224, actor_id=85989a3f5d1196247876e93b01000000, repr=<flwr.simulation.ray_transport.ray_actor.ClientAppActor object at 0x7f66a419d7b0>)
  File "/home/abdenour/.local/lib/python3.10/site-packages/flwr/simulation/ray_transport/ray_actor.py", line 63, in run
    raise ClientAppException(str(ex)) from ex
flwr.client.client_app.ClientAppException: 
Exception ClientAppException occurred. Message: CUDA out of memory. Tried to allocate 392.00 MiB. GPU 0 has a total capacity of 47.33 GiB of which 258.12 MiB is free. Process 2279413 has 11.11 GiB memory in use. Process 2265701 has 2.37 GiB memory in use. Process 2279412 has 11.11 GiB memory in use. Process 2457611 has 11.11 GiB memory in use. Process 2443889 has 2.37 GiB memory in use. Process 2457610 has 8.64 GiB memory in use. Including non-PyTorch memory, this process has 322.00 MiB memory in use. Of the allocated memory 57.01 MiB is allocated by PyTorch, and 4.99 MiB is reserved by PyTorch but unallocated. If reserved but unallocated memory is large try setting PYTORCH_CUDA_ALLOC_CONF=expandable_segments:True to avoid fragmentation.  See documentation for Memory Management  (https://pytorch.org/docs/stable/notes/cuda.html#environment-variables)
[2024-09-19 01:32:44,726][flwr][ERROR] - Traceback (most recent call last):
  File "/home/abdenour/.local/lib/python3.10/site-packages/flwr/simulation/ray_transport/ray_client_proxy.py", line 94, in _submit_job
    out_mssg, updated_context = self.actor_pool.get_client_result(
  File "/home/abdenour/.local/lib/python3.10/site-packages/flwr/simulation/ray_transport/ray_actor.py", line 398, in get_client_result
    return self._fetch_future_result(cid)
  File "/home/abdenour/.local/lib/python3.10/site-packages/flwr/simulation/ray_transport/ray_actor.py", line 279, in _fetch_future_result
    res_cid, out_mssg, updated_context = ray.get(
  File "/home/abdenour/.local/lib/python3.10/site-packages/ray/_private/auto_init_hook.py", line 21, in auto_init_wrapper
    return fn(*args, **kwargs)
  File "/home/abdenour/.local/lib/python3.10/site-packages/ray/_private/client_mode_hook.py", line 103, in wrapper
    return func(*args, **kwargs)
  File "/home/abdenour/.local/lib/python3.10/site-packages/ray/_private/worker.py", line 2667, in get
    values, debugger_breakpoint = worker.get_objects(object_refs, timeout=timeout)
  File "/home/abdenour/.local/lib/python3.10/site-packages/ray/_private/worker.py", line 864, in get_objects
    raise value.as_instanceof_cause()
ray.exceptions.RayTaskError(ClientAppException): [36mray::ClientAppActor.run()[39m (pid=2457608, ip=115.145.172.224, actor_id=4c290b3574534b722102b43101000000, repr=<flwr.simulation.ray_transport.ray_actor.ClientAppActor object at 0x7efcf017d780>)
  File "/home/abdenour/.local/lib/python3.10/site-packages/flwr/client/client_app.py", line 143, in __call__
    return self._call(message, context)
  File "/home/abdenour/.local/lib/python3.10/site-packages/flwr/client/client_app.py", line 126, in ffn
    out_message = handle_legacy_message_from_msgtype(
  File "/home/abdenour/.local/lib/python3.10/site-packages/flwr/client/message_handler/message_handler.py", line 95, in handle_legacy_message_from_msgtype
    client = client_fn(context)
  File "/home/abdenour/fl_with_flower/fednova_vgg16/fednova_vgg16/client.py", line 129, in client_fn
    return FlowerClient(trainset, valset, num_classes, config_fit, client_dataset_ratio, context.node_config).to_client()
  File "/home/abdenour/fl_with_flower/fednova_vgg16/fednova_vgg16/client.py", line 36, in __init__
    self.model = self.model.to(self.device)
  File "/home/abdenour/anaconda3/envs/fl/lib/python3.10/site-packages/torch/nn/modules/module.py", line 1174, in to
    return self._apply(convert)
  File "/home/abdenour/anaconda3/envs/fl/lib/python3.10/site-packages/torch/nn/modules/module.py", line 780, in _apply
    module._apply(fn)
  File "/home/abdenour/anaconda3/envs/fl/lib/python3.10/site-packages/torch/nn/modules/module.py", line 780, in _apply
    module._apply(fn)
  File "/home/abdenour/anaconda3/envs/fl/lib/python3.10/site-packages/torch/nn/modules/module.py", line 805, in _apply
    param_applied = fn(param)
  File "/home/abdenour/anaconda3/envs/fl/lib/python3.10/site-packages/torch/nn/modules/module.py", line 1160, in convert
    return t.to(
RuntimeError: CUDA error: out of memory
CUDA kernel errors might be asynchronously reported at some other API call, so the stacktrace below might be incorrect.
For debugging consider passing CUDA_LAUNCH_BLOCKING=1
Compile with `TORCH_USE_CUDA_DSA` to enable device-side assertions.


The above exception was the direct cause of the following exception:

[36mray::ClientAppActor.run()[39m (pid=2457608, ip=115.145.172.224, actor_id=4c290b3574534b722102b43101000000, repr=<flwr.simulation.ray_transport.ray_actor.ClientAppActor object at 0x7efcf017d780>)
  File "/home/abdenour/.local/lib/python3.10/site-packages/flwr/simulation/ray_transport/ray_actor.py", line 63, in run
    raise ClientAppException(str(ex)) from ex
flwr.client.client_app.ClientAppException: 
Exception ClientAppException occurred. Message: CUDA error: out of memory
CUDA kernel errors might be asynchronously reported at some other API call, so the stacktrace below might be incorrect.
For debugging consider passing CUDA_LAUNCH_BLOCKING=1
Compile with `TORCH_USE_CUDA_DSA` to enable device-side assertions.

[2024-09-19 01:32:44,726][flwr][ERROR] - [36mray::ClientAppActor.run()[39m (pid=2457608, ip=115.145.172.224, actor_id=4c290b3574534b722102b43101000000, repr=<flwr.simulation.ray_transport.ray_actor.ClientAppActor object at 0x7efcf017d780>)
  File "/home/abdenour/.local/lib/python3.10/site-packages/flwr/client/client_app.py", line 143, in __call__
    return self._call(message, context)
  File "/home/abdenour/.local/lib/python3.10/site-packages/flwr/client/client_app.py", line 126, in ffn
    out_message = handle_legacy_message_from_msgtype(
  File "/home/abdenour/.local/lib/python3.10/site-packages/flwr/client/message_handler/message_handler.py", line 95, in handle_legacy_message_from_msgtype
    client = client_fn(context)
  File "/home/abdenour/fl_with_flower/fednova_vgg16/fednova_vgg16/client.py", line 129, in client_fn
    return FlowerClient(trainset, valset, num_classes, config_fit, client_dataset_ratio, context.node_config).to_client()
  File "/home/abdenour/fl_with_flower/fednova_vgg16/fednova_vgg16/client.py", line 36, in __init__
    self.model = self.model.to(self.device)
  File "/home/abdenour/anaconda3/envs/fl/lib/python3.10/site-packages/torch/nn/modules/module.py", line 1174, in to
    return self._apply(convert)
  File "/home/abdenour/anaconda3/envs/fl/lib/python3.10/site-packages/torch/nn/modules/module.py", line 780, in _apply
    module._apply(fn)
  File "/home/abdenour/anaconda3/envs/fl/lib/python3.10/site-packages/torch/nn/modules/module.py", line 780, in _apply
    module._apply(fn)
  File "/home/abdenour/anaconda3/envs/fl/lib/python3.10/site-packages/torch/nn/modules/module.py", line 805, in _apply
    param_applied = fn(param)
  File "/home/abdenour/anaconda3/envs/fl/lib/python3.10/site-packages/torch/nn/modules/module.py", line 1160, in convert
    return t.to(
RuntimeError: CUDA error: out of memory
CUDA kernel errors might be asynchronously reported at some other API call, so the stacktrace below might be incorrect.
For debugging consider passing CUDA_LAUNCH_BLOCKING=1
Compile with `TORCH_USE_CUDA_DSA` to enable device-side assertions.


The above exception was the direct cause of the following exception:

[36mray::ClientAppActor.run()[39m (pid=2457608, ip=115.145.172.224, actor_id=4c290b3574534b722102b43101000000, repr=<flwr.simulation.ray_transport.ray_actor.ClientAppActor object at 0x7efcf017d780>)
  File "/home/abdenour/.local/lib/python3.10/site-packages/flwr/simulation/ray_transport/ray_actor.py", line 63, in run
    raise ClientAppException(str(ex)) from ex
flwr.client.client_app.ClientAppException: 
Exception ClientAppException occurred. Message: CUDA error: out of memory
CUDA kernel errors might be asynchronously reported at some other API call, so the stacktrace below might be incorrect.
For debugging consider passing CUDA_LAUNCH_BLOCKING=1
Compile with `TORCH_USE_CUDA_DSA` to enable device-side assertions.
[2024-09-19 01:32:45,083][flwr][INFO] - aggregate_fit: received 2 results and 3 failures
