[2024-09-19 01:28:59,946][flwr][INFO] - Starting Flower simulation, config: num_rounds=100, no round_timeout
[2024-09-19 01:29:03,280][flwr][INFO] - Flower VCE: Ray initialized with resources: {'GPU': 1.0, 'accelerator_type:G': 1.0, 'CPU': 256.0, 'memory': 146616765850.0, 'object_store_memory': 67121471078.0, 'node:115.145.172.224': 1.0, 'node:__internal_head__': 1.0}
[2024-09-19 01:29:03,280][flwr][INFO] - Optimize your simulation with Flower VCE: https://flower.ai/docs/framework/how-to-run-simulations.html
[2024-09-19 01:29:03,281][flwr][INFO] - Flower VCE: Resources for each Virtual Client: {'num_cpus': 64, 'num_gpus': 0.25}
[2024-09-19 01:29:03,296][flwr][INFO] - Flower VCE: Creating VirtualClientEngineActorPool with 4 actors
[2024-09-19 01:29:03,297][flwr][INFO] - [INIT]
[2024-09-19 01:29:03,297][flwr][INFO] - Requesting initial parameters from one random client
[2024-09-19 01:29:10,468][flwr][INFO] - Received initial parameters from one random client
[2024-09-19 01:29:10,468][flwr][INFO] - Evaluating initial global parameters
[2024-09-19 01:29:23,164][flwr][INFO] - initial parameters (loss, other metrics): 218.00374054908752, {'accuracy': 0.2341420637240573}
[2024-09-19 01:29:23,165][flwr][INFO] - 
[2024-09-19 01:29:23,165][flwr][INFO] - [ROUND 1]
[2024-09-19 01:29:23,165][flwr][INFO] - configure_fit: strategy sampled 5 clients (out of 50)
[2024-09-19 01:29:33,137][flwr][ERROR] - Traceback (most recent call last):
  File "/home/abdenour/.local/lib/python3.10/site-packages/flwr/simulation/ray_transport/ray_client_proxy.py", line 94, in _submit_job
    out_mssg, updated_context = self.actor_pool.get_client_result(
  File "/home/abdenour/.local/lib/python3.10/site-packages/flwr/simulation/ray_transport/ray_actor.py", line 398, in get_client_result
    return self._fetch_future_result(cid)
  File "/home/abdenour/.local/lib/python3.10/site-packages/flwr/simulation/ray_transport/ray_actor.py", line 279, in _fetch_future_result
    res_cid, out_mssg, updated_context = ray.get(
  File "/home/abdenour/.local/lib/python3.10/site-packages/ray/_private/auto_init_hook.py", line 21, in auto_init_wrapper
    return fn(*args, **kwargs)
  File "/home/abdenour/.local/lib/python3.10/site-packages/ray/_private/client_mode_hook.py", line 103, in wrapper
    return func(*args, **kwargs)
  File "/home/abdenour/.local/lib/python3.10/site-packages/ray/_private/worker.py", line 2667, in get
    values, debugger_breakpoint = worker.get_objects(object_refs, timeout=timeout)
  File "/home/abdenour/.local/lib/python3.10/site-packages/ray/_private/worker.py", line 864, in get_objects
    raise value.as_instanceof_cause()
ray.exceptions.RayTaskError(ClientAppException): [36mray::ClientAppActor.run()[39m (pid=2394561, ip=115.145.172.224, actor_id=8181e9f2655e637b888f746801000000, repr=<flwr.simulation.ray_transport.ray_actor.ClientAppActor object at 0x7efcb00996f0>)
  File "/home/abdenour/.local/lib/python3.10/site-packages/flwr/client/client_app.py", line 143, in __call__
    return self._call(message, context)
  File "/home/abdenour/.local/lib/python3.10/site-packages/flwr/client/client_app.py", line 126, in ffn
    out_message = handle_legacy_message_from_msgtype(
  File "/home/abdenour/.local/lib/python3.10/site-packages/flwr/client/message_handler/message_handler.py", line 129, in handle_legacy_message_from_msgtype
    fit_res = maybe_call_fit(
  File "/home/abdenour/.local/lib/python3.10/site-packages/flwr/client/client.py", line 234, in maybe_call_fit
    return client.fit(fit_ins)
  File "/home/abdenour/.local/lib/python3.10/site-packages/flwr/client/numpy_client.py", line 238, in _fit
    results = self.numpy_client.fit(parameters, ins.config)  # type: ignore
  File "/home/abdenour/fl_with_flower/fednova_vgg16/fednova_vgg16/client.py", line 69, in fit
    train(self.model, trainloader, self.optimizer, epochs=num_epochs, device=self.device)
  File "/home/abdenour/fl_with_flower/fednova_vgg16/fednova_vgg16/utils.py", line 57, in train
    loss = criterion(net(images), labels)
  File "/home/abdenour/anaconda3/envs/fl/lib/python3.10/site-packages/torch/nn/modules/module.py", line 1553, in _wrapped_call_impl
    return self._call_impl(*args, **kwargs)
  File "/home/abdenour/anaconda3/envs/fl/lib/python3.10/site-packages/torch/nn/modules/module.py", line 1562, in _call_impl
    return forward_call(*args, **kwargs)
  File "/home/abdenour/anaconda3/envs/fl/lib/python3.10/site-packages/torchvision/models/vgg.py", line 66, in forward
    x = self.features(x)
  File "/home/abdenour/anaconda3/envs/fl/lib/python3.10/site-packages/torch/nn/modules/module.py", line 1553, in _wrapped_call_impl
    return self._call_impl(*args, **kwargs)
  File "/home/abdenour/anaconda3/envs/fl/lib/python3.10/site-packages/torch/nn/modules/module.py", line 1562, in _call_impl
    return forward_call(*args, **kwargs)
  File "/home/abdenour/anaconda3/envs/fl/lib/python3.10/site-packages/torch/nn/modules/container.py", line 219, in forward
    input = module(input)
  File "/home/abdenour/anaconda3/envs/fl/lib/python3.10/site-packages/torch/nn/modules/module.py", line 1553, in _wrapped_call_impl
    return self._call_impl(*args, **kwargs)
  File "/home/abdenour/anaconda3/envs/fl/lib/python3.10/site-packages/torch/nn/modules/module.py", line 1562, in _call_impl
    return forward_call(*args, **kwargs)
  File "/home/abdenour/anaconda3/envs/fl/lib/python3.10/site-packages/torch/nn/modules/conv.py", line 458, in forward
    return self._conv_forward(input, self.weight, self.bias)
  File "/home/abdenour/anaconda3/envs/fl/lib/python3.10/site-packages/torch/nn/modules/conv.py", line 454, in _conv_forward
    return F.conv2d(input, weight, bias, self.stride,
torch.OutOfMemoryError: CUDA out of memory. Tried to allocate 784.00 MiB. GPU 0 has a total capacity of 47.33 GiB of which 400.81 MiB is free. Process 2279413 has 11.11 GiB memory in use. Process 2265701 has 2.37 GiB memory in use. Process 2279412 has 11.11 GiB memory in use. Process 2394562 has 11.11 GiB memory in use. Process 2380775 has 2.37 GiB memory in use. Process 2394560 has 6.50 GiB memory in use. Including non-PyTorch memory, this process has 1.61 GiB memory in use. Process 2394559 has 778.00 MiB memory in use. Of the allocated memory 1.30 GiB is allocated by PyTorch, and 6.08 MiB is reserved by PyTorch but unallocated. If reserved but unallocated memory is large try setting PYTORCH_CUDA_ALLOC_CONF=expandable_segments:True to avoid fragmentation.  See documentation for Memory Management  (https://pytorch.org/docs/stable/notes/cuda.html#environment-variables)

The above exception was the direct cause of the following exception:

[36mray::ClientAppActor.run()[39m (pid=2394561, ip=115.145.172.224, actor_id=8181e9f2655e637b888f746801000000, repr=<flwr.simulation.ray_transport.ray_actor.ClientAppActor object at 0x7efcb00996f0>)
  File "/home/abdenour/.local/lib/python3.10/site-packages/flwr/simulation/ray_transport/ray_actor.py", line 63, in run
    raise ClientAppException(str(ex)) from ex
flwr.client.client_app.ClientAppException: 
Exception ClientAppException occurred. Message: CUDA out of memory. Tried to allocate 784.00 MiB. GPU 0 has a total capacity of 47.33 GiB of which 400.81 MiB is free. Process 2279413 has 11.11 GiB memory in use. Process 2265701 has 2.37 GiB memory in use. Process 2279412 has 11.11 GiB memory in use. Process 2394562 has 11.11 GiB memory in use. Process 2380775 has 2.37 GiB memory in use. Process 2394560 has 6.50 GiB memory in use. Including non-PyTorch memory, this process has 1.61 GiB memory in use. Process 2394559 has 778.00 MiB memory in use. Of the allocated memory 1.30 GiB is allocated by PyTorch, and 6.08 MiB is reserved by PyTorch but unallocated. If reserved but unallocated memory is large try setting PYTORCH_CUDA_ALLOC_CONF=expandable_segments:True to avoid fragmentation.  See documentation for Memory Management  (https://pytorch.org/docs/stable/notes/cuda.html#environment-variables)

[2024-09-19 01:29:33,138][flwr][ERROR] - [36mray::ClientAppActor.run()[39m (pid=2394561, ip=115.145.172.224, actor_id=8181e9f2655e637b888f746801000000, repr=<flwr.simulation.ray_transport.ray_actor.ClientAppActor object at 0x7efcb00996f0>)
  File "/home/abdenour/.local/lib/python3.10/site-packages/flwr/client/client_app.py", line 143, in __call__
    return self._call(message, context)
  File "/home/abdenour/.local/lib/python3.10/site-packages/flwr/client/client_app.py", line 126, in ffn
    out_message = handle_legacy_message_from_msgtype(
  File "/home/abdenour/.local/lib/python3.10/site-packages/flwr/client/message_handler/message_handler.py", line 129, in handle_legacy_message_from_msgtype
    fit_res = maybe_call_fit(
  File "/home/abdenour/.local/lib/python3.10/site-packages/flwr/client/client.py", line 234, in maybe_call_fit
    return client.fit(fit_ins)
  File "/home/abdenour/.local/lib/python3.10/site-packages/flwr/client/numpy_client.py", line 238, in _fit
    results = self.numpy_client.fit(parameters, ins.config)  # type: ignore
  File "/home/abdenour/fl_with_flower/fednova_vgg16/fednova_vgg16/client.py", line 69, in fit
    train(self.model, trainloader, self.optimizer, epochs=num_epochs, device=self.device)
  File "/home/abdenour/fl_with_flower/fednova_vgg16/fednova_vgg16/utils.py", line 57, in train
    loss = criterion(net(images), labels)
  File "/home/abdenour/anaconda3/envs/fl/lib/python3.10/site-packages/torch/nn/modules/module.py", line 1553, in _wrapped_call_impl
    return self._call_impl(*args, **kwargs)
  File "/home/abdenour/anaconda3/envs/fl/lib/python3.10/site-packages/torch/nn/modules/module.py", line 1562, in _call_impl
    return forward_call(*args, **kwargs)
  File "/home/abdenour/anaconda3/envs/fl/lib/python3.10/site-packages/torchvision/models/vgg.py", line 66, in forward
    x = self.features(x)
  File "/home/abdenour/anaconda3/envs/fl/lib/python3.10/site-packages/torch/nn/modules/module.py", line 1553, in _wrapped_call_impl
    return self._call_impl(*args, **kwargs)
  File "/home/abdenour/anaconda3/envs/fl/lib/python3.10/site-packages/torch/nn/modules/module.py", line 1562, in _call_impl
    return forward_call(*args, **kwargs)
  File "/home/abdenour/anaconda3/envs/fl/lib/python3.10/site-packages/torch/nn/modules/container.py", line 219, in forward
    input = module(input)
  File "/home/abdenour/anaconda3/envs/fl/lib/python3.10/site-packages/torch/nn/modules/module.py", line 1553, in _wrapped_call_impl
    return self._call_impl(*args, **kwargs)
  File "/home/abdenour/anaconda3/envs/fl/lib/python3.10/site-packages/torch/nn/modules/module.py", line 1562, in _call_impl
    return forward_call(*args, **kwargs)
  File "/home/abdenour/anaconda3/envs/fl/lib/python3.10/site-packages/torch/nn/modules/conv.py", line 458, in forward
    return self._conv_forward(input, self.weight, self.bias)
  File "/home/abdenour/anaconda3/envs/fl/lib/python3.10/site-packages/torch/nn/modules/conv.py", line 454, in _conv_forward
    return F.conv2d(input, weight, bias, self.stride,
torch.OutOfMemoryError: CUDA out of memory. Tried to allocate 784.00 MiB. GPU 0 has a total capacity of 47.33 GiB of which 400.81 MiB is free. Process 2279413 has 11.11 GiB memory in use. Process 2265701 has 2.37 GiB memory in use. Process 2279412 has 11.11 GiB memory in use. Process 2394562 has 11.11 GiB memory in use. Process 2380775 has 2.37 GiB memory in use. Process 2394560 has 6.50 GiB memory in use. Including non-PyTorch memory, this process has 1.61 GiB memory in use. Process 2394559 has 778.00 MiB memory in use. Of the allocated memory 1.30 GiB is allocated by PyTorch, and 6.08 MiB is reserved by PyTorch but unallocated. If reserved but unallocated memory is large try setting PYTORCH_CUDA_ALLOC_CONF=expandable_segments:True to avoid fragmentation.  See documentation for Memory Management  (https://pytorch.org/docs/stable/notes/cuda.html#environment-variables)

The above exception was the direct cause of the following exception:

[36mray::ClientAppActor.run()[39m (pid=2394561, ip=115.145.172.224, actor_id=8181e9f2655e637b888f746801000000, repr=<flwr.simulation.ray_transport.ray_actor.ClientAppActor object at 0x7efcb00996f0>)
  File "/home/abdenour/.local/lib/python3.10/site-packages/flwr/simulation/ray_transport/ray_actor.py", line 63, in run
    raise ClientAppException(str(ex)) from ex
flwr.client.client_app.ClientAppException: 
Exception ClientAppException occurred. Message: CUDA out of memory. Tried to allocate 784.00 MiB. GPU 0 has a total capacity of 47.33 GiB of which 400.81 MiB is free. Process 2279413 has 11.11 GiB memory in use. Process 2265701 has 2.37 GiB memory in use. Process 2279412 has 11.11 GiB memory in use. Process 2394562 has 11.11 GiB memory in use. Process 2380775 has 2.37 GiB memory in use. Process 2394560 has 6.50 GiB memory in use. Including non-PyTorch memory, this process has 1.61 GiB memory in use. Process 2394559 has 778.00 MiB memory in use. Of the allocated memory 1.30 GiB is allocated by PyTorch, and 6.08 MiB is reserved by PyTorch but unallocated. If reserved but unallocated memory is large try setting PYTORCH_CUDA_ALLOC_CONF=expandable_segments:True to avoid fragmentation.  See documentation for Memory Management  (https://pytorch.org/docs/stable/notes/cuda.html#environment-variables)
[2024-09-19 01:29:33,138][flwr][ERROR] - Traceback (most recent call last):
  File "/home/abdenour/.local/lib/python3.10/site-packages/flwr/simulation/ray_transport/ray_client_proxy.py", line 94, in _submit_job
    out_mssg, updated_context = self.actor_pool.get_client_result(
  File "/home/abdenour/.local/lib/python3.10/site-packages/flwr/simulation/ray_transport/ray_actor.py", line 398, in get_client_result
    return self._fetch_future_result(cid)
  File "/home/abdenour/.local/lib/python3.10/site-packages/flwr/simulation/ray_transport/ray_actor.py", line 279, in _fetch_future_result
    res_cid, out_mssg, updated_context = ray.get(
  File "/home/abdenour/.local/lib/python3.10/site-packages/ray/_private/auto_init_hook.py", line 21, in auto_init_wrapper
    return fn(*args, **kwargs)
  File "/home/abdenour/.local/lib/python3.10/site-packages/ray/_private/client_mode_hook.py", line 103, in wrapper
    return func(*args, **kwargs)
  File "/home/abdenour/.local/lib/python3.10/site-packages/ray/_private/worker.py", line 2667, in get
    values, debugger_breakpoint = worker.get_objects(object_refs, timeout=timeout)
  File "/home/abdenour/.local/lib/python3.10/site-packages/ray/_private/worker.py", line 864, in get_objects
    raise value.as_instanceof_cause()
ray.exceptions.RayTaskError(ClientAppException): [36mray::ClientAppActor.run()[39m (pid=2394560, ip=115.145.172.224, actor_id=c079584de6f4d2d60ace6ff001000000, repr=<flwr.simulation.ray_transport.ray_actor.ClientAppActor object at 0x7f209c2717b0>)
  File "/home/abdenour/.local/lib/python3.10/site-packages/flwr/client/client_app.py", line 143, in __call__
    return self._call(message, context)
  File "/home/abdenour/.local/lib/python3.10/site-packages/flwr/client/client_app.py", line 126, in ffn
    out_message = handle_legacy_message_from_msgtype(
  File "/home/abdenour/.local/lib/python3.10/site-packages/flwr/client/message_handler/message_handler.py", line 129, in handle_legacy_message_from_msgtype
    fit_res = maybe_call_fit(
  File "/home/abdenour/.local/lib/python3.10/site-packages/flwr/client/client.py", line 234, in maybe_call_fit
    return client.fit(fit_ins)
  File "/home/abdenour/.local/lib/python3.10/site-packages/flwr/client/numpy_client.py", line 238, in _fit
    results = self.numpy_client.fit(parameters, ins.config)  # type: ignore
  File "/home/abdenour/fl_with_flower/fednova_vgg16/fednova_vgg16/client.py", line 69, in fit
    train(self.model, trainloader, self.optimizer, epochs=num_epochs, device=self.device)
  File "/home/abdenour/fl_with_flower/fednova_vgg16/fednova_vgg16/utils.py", line 58, in train
    loss.backward()
  File "/home/abdenour/anaconda3/envs/fl/lib/python3.10/site-packages/torch/_tensor.py", line 521, in backward
    torch.autograd.backward(
  File "/home/abdenour/anaconda3/envs/fl/lib/python3.10/site-packages/torch/autograd/__init__.py", line 289, in backward
    _engine_run_backward(
  File "/home/abdenour/anaconda3/envs/fl/lib/python3.10/site-packages/torch/autograd/graph.py", line 769, in _engine_run_backward
    return Variable._execution_engine.run_backward(  # Calls into the C++ engine to run the backward pass
torch.OutOfMemoryError: CUDA out of memory. Tried to allocate 392.00 MiB. GPU 0 has a total capacity of 47.33 GiB of which 370.81 MiB is free. Process 2279413 has 11.11 GiB memory in use. Process 2265701 has 2.37 GiB memory in use. Process 2279412 has 11.11 GiB memory in use. Process 2394562 has 11.11 GiB memory in use. Process 2380775 has 2.37 GiB memory in use. Including non-PyTorch memory, this process has 6.43 GiB memory in use. Process 2394561 has 1.61 GiB memory in use. Process 2394559 has 816.00 MiB memory in use. Of the allocated memory 5.95 GiB is allocated by PyTorch, and 154.11 MiB is reserved by PyTorch but unallocated. If reserved but unallocated memory is large try setting PYTORCH_CUDA_ALLOC_CONF=expandable_segments:True to avoid fragmentation.  See documentation for Memory Management  (https://pytorch.org/docs/stable/notes/cuda.html#environment-variables)

The above exception was the direct cause of the following exception:

[36mray::ClientAppActor.run()[39m (pid=2394560, ip=115.145.172.224, actor_id=c079584de6f4d2d60ace6ff001000000, repr=<flwr.simulation.ray_transport.ray_actor.ClientAppActor object at 0x7f209c2717b0>)
  File "/home/abdenour/.local/lib/python3.10/site-packages/flwr/simulation/ray_transport/ray_actor.py", line 63, in run
    raise ClientAppException(str(ex)) from ex
flwr.client.client_app.ClientAppException: 
Exception ClientAppException occurred. Message: CUDA out of memory. Tried to allocate 392.00 MiB. GPU 0 has a total capacity of 47.33 GiB of which 370.81 MiB is free. Process 2279413 has 11.11 GiB memory in use. Process 2265701 has 2.37 GiB memory in use. Process 2279412 has 11.11 GiB memory in use. Process 2394562 has 11.11 GiB memory in use. Process 2380775 has 2.37 GiB memory in use. Including non-PyTorch memory, this process has 6.43 GiB memory in use. Process 2394561 has 1.61 GiB memory in use. Process 2394559 has 816.00 MiB memory in use. Of the allocated memory 5.95 GiB is allocated by PyTorch, and 154.11 MiB is reserved by PyTorch but unallocated. If reserved but unallocated memory is large try setting PYTORCH_CUDA_ALLOC_CONF=expandable_segments:True to avoid fragmentation.  See documentation for Memory Management  (https://pytorch.org/docs/stable/notes/cuda.html#environment-variables)

[2024-09-19 01:29:33,139][flwr][ERROR] - Traceback (most recent call last):
  File "/home/abdenour/.local/lib/python3.10/site-packages/flwr/simulation/ray_transport/ray_client_proxy.py", line 94, in _submit_job
    out_mssg, updated_context = self.actor_pool.get_client_result(
  File "/home/abdenour/.local/lib/python3.10/site-packages/flwr/simulation/ray_transport/ray_actor.py", line 398, in get_client_result
    return self._fetch_future_result(cid)
  File "/home/abdenour/.local/lib/python3.10/site-packages/flwr/simulation/ray_transport/ray_actor.py", line 279, in _fetch_future_result
    res_cid, out_mssg, updated_context = ray.get(
  File "/home/abdenour/.local/lib/python3.10/site-packages/ray/_private/auto_init_hook.py", line 21, in auto_init_wrapper
    return fn(*args, **kwargs)
  File "/home/abdenour/.local/lib/python3.10/site-packages/ray/_private/client_mode_hook.py", line 103, in wrapper
    return func(*args, **kwargs)
  File "/home/abdenour/.local/lib/python3.10/site-packages/ray/_private/worker.py", line 2667, in get
    values, debugger_breakpoint = worker.get_objects(object_refs, timeout=timeout)
  File "/home/abdenour/.local/lib/python3.10/site-packages/ray/_private/worker.py", line 864, in get_objects
    raise value.as_instanceof_cause()
ray.exceptions.RayTaskError(ClientAppException): [36mray::ClientAppActor.run()[39m (pid=2394559, ip=115.145.172.224, actor_id=cf20073e66e6425be585749801000000, repr=<flwr.simulation.ray_transport.ray_actor.ClientAppActor object at 0x7fbed0479780>)
  File "/home/abdenour/.local/lib/python3.10/site-packages/flwr/client/client_app.py", line 143, in __call__
    return self._call(message, context)
  File "/home/abdenour/.local/lib/python3.10/site-packages/flwr/client/client_app.py", line 126, in ffn
    out_message = handle_legacy_message_from_msgtype(
  File "/home/abdenour/.local/lib/python3.10/site-packages/flwr/client/message_handler/message_handler.py", line 129, in handle_legacy_message_from_msgtype
    fit_res = maybe_call_fit(
  File "/home/abdenour/.local/lib/python3.10/site-packages/flwr/client/client.py", line 234, in maybe_call_fit
    return client.fit(fit_ins)
  File "/home/abdenour/.local/lib/python3.10/site-packages/flwr/client/numpy_client.py", line 238, in _fit
    results = self.numpy_client.fit(parameters, ins.config)  # type: ignore
  File "/home/abdenour/fl_with_flower/fednova_vgg16/fednova_vgg16/client.py", line 69, in fit
    train(self.model, trainloader, self.optimizer, epochs=num_epochs, device=self.device)
  File "/home/abdenour/fl_with_flower/fednova_vgg16/fednova_vgg16/utils.py", line 57, in train
    loss = criterion(net(images), labels)
  File "/home/abdenour/anaconda3/envs/fl/lib/python3.10/site-packages/torch/nn/modules/module.py", line 1553, in _wrapped_call_impl
    return self._call_impl(*args, **kwargs)
  File "/home/abdenour/anaconda3/envs/fl/lib/python3.10/site-packages/torch/nn/modules/module.py", line 1562, in _call_impl
    return forward_call(*args, **kwargs)
  File "/home/abdenour/anaconda3/envs/fl/lib/python3.10/site-packages/torchvision/models/vgg.py", line 66, in forward
    x = self.features(x)
  File "/home/abdenour/anaconda3/envs/fl/lib/python3.10/site-packages/torch/nn/modules/module.py", line 1553, in _wrapped_call_impl
    return self._call_impl(*args, **kwargs)
  File "/home/abdenour/anaconda3/envs/fl/lib/python3.10/site-packages/torch/nn/modules/module.py", line 1562, in _call_impl
    return forward_call(*args, **kwargs)
  File "/home/abdenour/anaconda3/envs/fl/lib/python3.10/site-packages/torch/nn/modules/container.py", line 219, in forward
    input = module(input)
  File "/home/abdenour/anaconda3/envs/fl/lib/python3.10/site-packages/torch/nn/modules/module.py", line 1553, in _wrapped_call_impl
    return self._call_impl(*args, **kwargs)
  File "/home/abdenour/anaconda3/envs/fl/lib/python3.10/site-packages/torch/nn/modules/module.py", line 1562, in _call_impl
    return forward_call(*args, **kwargs)
  File "/home/abdenour/anaconda3/envs/fl/lib/python3.10/site-packages/torch/nn/modules/conv.py", line 458, in forward
    return self._conv_forward(input, self.weight, self.bias)
  File "/home/abdenour/anaconda3/envs/fl/lib/python3.10/site-packages/torch/nn/modules/conv.py", line 454, in _conv_forward
    return F.conv2d(input, weight, bias, self.stride,
torch.OutOfMemoryError: CUDA out of memory. Tried to allocate 784.00 MiB. GPU 0 has a total capacity of 47.33 GiB of which 368.81 MiB is free. Process 2279413 has 11.11 GiB memory in use. Process 2265701 has 2.37 GiB memory in use. Process 2279412 has 11.11 GiB memory in use. Process 2394562 has 11.11 GiB memory in use. Process 2380775 has 2.37 GiB memory in use. Process 2394560 has 6.43 GiB memory in use. Process 2394561 has 1.61 GiB memory in use. Including non-PyTorch memory, this process has 816.00 MiB memory in use. Of the allocated memory 549.92 MiB is allocated by PyTorch, and 6.08 MiB is reserved by PyTorch but unallocated. If reserved but unallocated memory is large try setting PYTORCH_CUDA_ALLOC_CONF=expandable_segments:True to avoid fragmentation.  See documentation for Memory Management  (https://pytorch.org/docs/stable/notes/cuda.html#environment-variables)

The above exception was the direct cause of the following exception:

[36mray::ClientAppActor.run()[39m (pid=2394559, ip=115.145.172.224, actor_id=cf20073e66e6425be585749801000000, repr=<flwr.simulation.ray_transport.ray_actor.ClientAppActor object at 0x7fbed0479780>)
  File "/home/abdenour/.local/lib/python3.10/site-packages/flwr/simulation/ray_transport/ray_actor.py", line 63, in run
    raise ClientAppException(str(ex)) from ex
flwr.client.client_app.ClientAppException: 
Exception ClientAppException occurred. Message: CUDA out of memory. Tried to allocate 784.00 MiB. GPU 0 has a total capacity of 47.33 GiB of which 368.81 MiB is free. Process 2279413 has 11.11 GiB memory in use. Process 2265701 has 2.37 GiB memory in use. Process 2279412 has 11.11 GiB memory in use. Process 2394562 has 11.11 GiB memory in use. Process 2380775 has 2.37 GiB memory in use. Process 2394560 has 6.43 GiB memory in use. Process 2394561 has 1.61 GiB memory in use. Including non-PyTorch memory, this process has 816.00 MiB memory in use. Of the allocated memory 549.92 MiB is allocated by PyTorch, and 6.08 MiB is reserved by PyTorch but unallocated. If reserved but unallocated memory is large try setting PYTORCH_CUDA_ALLOC_CONF=expandable_segments:True to avoid fragmentation.  See documentation for Memory Management  (https://pytorch.org/docs/stable/notes/cuda.html#environment-variables)

[2024-09-19 01:29:33,139][flwr][ERROR] - [36mray::ClientAppActor.run()[39m (pid=2394560, ip=115.145.172.224, actor_id=c079584de6f4d2d60ace6ff001000000, repr=<flwr.simulation.ray_transport.ray_actor.ClientAppActor object at 0x7f209c2717b0>)
  File "/home/abdenour/.local/lib/python3.10/site-packages/flwr/client/client_app.py", line 143, in __call__
    return self._call(message, context)
  File "/home/abdenour/.local/lib/python3.10/site-packages/flwr/client/client_app.py", line 126, in ffn
    out_message = handle_legacy_message_from_msgtype(
  File "/home/abdenour/.local/lib/python3.10/site-packages/flwr/client/message_handler/message_handler.py", line 129, in handle_legacy_message_from_msgtype
    fit_res = maybe_call_fit(
  File "/home/abdenour/.local/lib/python3.10/site-packages/flwr/client/client.py", line 234, in maybe_call_fit
    return client.fit(fit_ins)
  File "/home/abdenour/.local/lib/python3.10/site-packages/flwr/client/numpy_client.py", line 238, in _fit
    results = self.numpy_client.fit(parameters, ins.config)  # type: ignore
  File "/home/abdenour/fl_with_flower/fednova_vgg16/fednova_vgg16/client.py", line 69, in fit
    train(self.model, trainloader, self.optimizer, epochs=num_epochs, device=self.device)
  File "/home/abdenour/fl_with_flower/fednova_vgg16/fednova_vgg16/utils.py", line 58, in train
    loss.backward()
  File "/home/abdenour/anaconda3/envs/fl/lib/python3.10/site-packages/torch/_tensor.py", line 521, in backward
    torch.autograd.backward(
  File "/home/abdenour/anaconda3/envs/fl/lib/python3.10/site-packages/torch/autograd/__init__.py", line 289, in backward
    _engine_run_backward(
  File "/home/abdenour/anaconda3/envs/fl/lib/python3.10/site-packages/torch/autograd/graph.py", line 769, in _engine_run_backward
    return Variable._execution_engine.run_backward(  # Calls into the C++ engine to run the backward pass
torch.OutOfMemoryError: CUDA out of memory. Tried to allocate 392.00 MiB. GPU 0 has a total capacity of 47.33 GiB of which 370.81 MiB is free. Process 2279413 has 11.11 GiB memory in use. Process 2265701 has 2.37 GiB memory in use. Process 2279412 has 11.11 GiB memory in use. Process 2394562 has 11.11 GiB memory in use. Process 2380775 has 2.37 GiB memory in use. Including non-PyTorch memory, this process has 6.43 GiB memory in use. Process 2394561 has 1.61 GiB memory in use. Process 2394559 has 816.00 MiB memory in use. Of the allocated memory 5.95 GiB is allocated by PyTorch, and 154.11 MiB is reserved by PyTorch but unallocated. If reserved but unallocated memory is large try setting PYTORCH_CUDA_ALLOC_CONF=expandable_segments:True to avoid fragmentation.  See documentation for Memory Management  (https://pytorch.org/docs/stable/notes/cuda.html#environment-variables)

The above exception was the direct cause of the following exception:

[36mray::ClientAppActor.run()[39m (pid=2394560, ip=115.145.172.224, actor_id=c079584de6f4d2d60ace6ff001000000, repr=<flwr.simulation.ray_transport.ray_actor.ClientAppActor object at 0x7f209c2717b0>)
  File "/home/abdenour/.local/lib/python3.10/site-packages/flwr/simulation/ray_transport/ray_actor.py", line 63, in run
    raise ClientAppException(str(ex)) from ex
flwr.client.client_app.ClientAppException: 
Exception ClientAppException occurred. Message: CUDA out of memory. Tried to allocate 392.00 MiB. GPU 0 has a total capacity of 47.33 GiB of which 370.81 MiB is free. Process 2279413 has 11.11 GiB memory in use. Process 2265701 has 2.37 GiB memory in use. Process 2279412 has 11.11 GiB memory in use. Process 2394562 has 11.11 GiB memory in use. Process 2380775 has 2.37 GiB memory in use. Including non-PyTorch memory, this process has 6.43 GiB memory in use. Process 2394561 has 1.61 GiB memory in use. Process 2394559 has 816.00 MiB memory in use. Of the allocated memory 5.95 GiB is allocated by PyTorch, and 154.11 MiB is reserved by PyTorch but unallocated. If reserved but unallocated memory is large try setting PYTORCH_CUDA_ALLOC_CONF=expandable_segments:True to avoid fragmentation.  See documentation for Memory Management  (https://pytorch.org/docs/stable/notes/cuda.html#environment-variables)
[2024-09-19 01:29:33,140][flwr][ERROR] - [36mray::ClientAppActor.run()[39m (pid=2394559, ip=115.145.172.224, actor_id=cf20073e66e6425be585749801000000, repr=<flwr.simulation.ray_transport.ray_actor.ClientAppActor object at 0x7fbed0479780>)
  File "/home/abdenour/.local/lib/python3.10/site-packages/flwr/client/client_app.py", line 143, in __call__
    return self._call(message, context)
  File "/home/abdenour/.local/lib/python3.10/site-packages/flwr/client/client_app.py", line 126, in ffn
    out_message = handle_legacy_message_from_msgtype(
  File "/home/abdenour/.local/lib/python3.10/site-packages/flwr/client/message_handler/message_handler.py", line 129, in handle_legacy_message_from_msgtype
    fit_res = maybe_call_fit(
  File "/home/abdenour/.local/lib/python3.10/site-packages/flwr/client/client.py", line 234, in maybe_call_fit
    return client.fit(fit_ins)
  File "/home/abdenour/.local/lib/python3.10/site-packages/flwr/client/numpy_client.py", line 238, in _fit
    results = self.numpy_client.fit(parameters, ins.config)  # type: ignore
  File "/home/abdenour/fl_with_flower/fednova_vgg16/fednova_vgg16/client.py", line 69, in fit
    train(self.model, trainloader, self.optimizer, epochs=num_epochs, device=self.device)
  File "/home/abdenour/fl_with_flower/fednova_vgg16/fednova_vgg16/utils.py", line 57, in train
    loss = criterion(net(images), labels)
  File "/home/abdenour/anaconda3/envs/fl/lib/python3.10/site-packages/torch/nn/modules/module.py", line 1553, in _wrapped_call_impl
    return self._call_impl(*args, **kwargs)
  File "/home/abdenour/anaconda3/envs/fl/lib/python3.10/site-packages/torch/nn/modules/module.py", line 1562, in _call_impl
    return forward_call(*args, **kwargs)
  File "/home/abdenour/anaconda3/envs/fl/lib/python3.10/site-packages/torchvision/models/vgg.py", line 66, in forward
    x = self.features(x)
  File "/home/abdenour/anaconda3/envs/fl/lib/python3.10/site-packages/torch/nn/modules/module.py", line 1553, in _wrapped_call_impl
    return self._call_impl(*args, **kwargs)
  File "/home/abdenour/anaconda3/envs/fl/lib/python3.10/site-packages/torch/nn/modules/module.py", line 1562, in _call_impl
    return forward_call(*args, **kwargs)
  File "/home/abdenour/anaconda3/envs/fl/lib/python3.10/site-packages/torch/nn/modules/container.py", line 219, in forward
    input = module(input)
  File "/home/abdenour/anaconda3/envs/fl/lib/python3.10/site-packages/torch/nn/modules/module.py", line 1553, in _wrapped_call_impl
    return self._call_impl(*args, **kwargs)
  File "/home/abdenour/anaconda3/envs/fl/lib/python3.10/site-packages/torch/nn/modules/module.py", line 1562, in _call_impl
    return forward_call(*args, **kwargs)
  File "/home/abdenour/anaconda3/envs/fl/lib/python3.10/site-packages/torch/nn/modules/conv.py", line 458, in forward
    return self._conv_forward(input, self.weight, self.bias)
  File "/home/abdenour/anaconda3/envs/fl/lib/python3.10/site-packages/torch/nn/modules/conv.py", line 454, in _conv_forward
    return F.conv2d(input, weight, bias, self.stride,
torch.OutOfMemoryError: CUDA out of memory. Tried to allocate 784.00 MiB. GPU 0 has a total capacity of 47.33 GiB of which 368.81 MiB is free. Process 2279413 has 11.11 GiB memory in use. Process 2265701 has 2.37 GiB memory in use. Process 2279412 has 11.11 GiB memory in use. Process 2394562 has 11.11 GiB memory in use. Process 2380775 has 2.37 GiB memory in use. Process 2394560 has 6.43 GiB memory in use. Process 2394561 has 1.61 GiB memory in use. Including non-PyTorch memory, this process has 816.00 MiB memory in use. Of the allocated memory 549.92 MiB is allocated by PyTorch, and 6.08 MiB is reserved by PyTorch but unallocated. If reserved but unallocated memory is large try setting PYTORCH_CUDA_ALLOC_CONF=expandable_segments:True to avoid fragmentation.  See documentation for Memory Management  (https://pytorch.org/docs/stable/notes/cuda.html#environment-variables)

The above exception was the direct cause of the following exception:

[36mray::ClientAppActor.run()[39m (pid=2394559, ip=115.145.172.224, actor_id=cf20073e66e6425be585749801000000, repr=<flwr.simulation.ray_transport.ray_actor.ClientAppActor object at 0x7fbed0479780>)
  File "/home/abdenour/.local/lib/python3.10/site-packages/flwr/simulation/ray_transport/ray_actor.py", line 63, in run
    raise ClientAppException(str(ex)) from ex
flwr.client.client_app.ClientAppException: 
Exception ClientAppException occurred. Message: CUDA out of memory. Tried to allocate 784.00 MiB. GPU 0 has a total capacity of 47.33 GiB of which 368.81 MiB is free. Process 2279413 has 11.11 GiB memory in use. Process 2265701 has 2.37 GiB memory in use. Process 2279412 has 11.11 GiB memory in use. Process 2394562 has 11.11 GiB memory in use. Process 2380775 has 2.37 GiB memory in use. Process 2394560 has 6.43 GiB memory in use. Process 2394561 has 1.61 GiB memory in use. Including non-PyTorch memory, this process has 816.00 MiB memory in use. Of the allocated memory 549.92 MiB is allocated by PyTorch, and 6.08 MiB is reserved by PyTorch but unallocated. If reserved but unallocated memory is large try setting PYTORCH_CUDA_ALLOC_CONF=expandable_segments:True to avoid fragmentation.  See documentation for Memory Management  (https://pytorch.org/docs/stable/notes/cuda.html#environment-variables)
[2024-09-19 01:29:34,708][flwr][ERROR] - Traceback (most recent call last):
  File "/home/abdenour/.local/lib/python3.10/site-packages/flwr/simulation/ray_transport/ray_client_proxy.py", line 94, in _submit_job
    out_mssg, updated_context = self.actor_pool.get_client_result(
  File "/home/abdenour/.local/lib/python3.10/site-packages/flwr/simulation/ray_transport/ray_actor.py", line 398, in get_client_result
    return self._fetch_future_result(cid)
  File "/home/abdenour/.local/lib/python3.10/site-packages/flwr/simulation/ray_transport/ray_actor.py", line 279, in _fetch_future_result
    res_cid, out_mssg, updated_context = ray.get(
  File "/home/abdenour/.local/lib/python3.10/site-packages/ray/_private/auto_init_hook.py", line 21, in auto_init_wrapper
    return fn(*args, **kwargs)
  File "/home/abdenour/.local/lib/python3.10/site-packages/ray/_private/client_mode_hook.py", line 103, in wrapper
    return func(*args, **kwargs)
  File "/home/abdenour/.local/lib/python3.10/site-packages/ray/_private/worker.py", line 2667, in get
    values, debugger_breakpoint = worker.get_objects(object_refs, timeout=timeout)
  File "/home/abdenour/.local/lib/python3.10/site-packages/ray/_private/worker.py", line 864, in get_objects
    raise value.as_instanceof_cause()
ray.exceptions.RayTaskError(ClientAppException): [36mray::ClientAppActor.run()[39m (pid=2394561, ip=115.145.172.224, actor_id=8181e9f2655e637b888f746801000000, repr=<flwr.simulation.ray_transport.ray_actor.ClientAppActor object at 0x7efcb00996f0>)
  File "/home/abdenour/.local/lib/python3.10/site-packages/flwr/client/client_app.py", line 143, in __call__
    return self._call(message, context)
  File "/home/abdenour/.local/lib/python3.10/site-packages/flwr/client/client_app.py", line 126, in ffn
    out_message = handle_legacy_message_from_msgtype(
  File "/home/abdenour/.local/lib/python3.10/site-packages/flwr/client/message_handler/message_handler.py", line 129, in handle_legacy_message_from_msgtype
    fit_res = maybe_call_fit(
  File "/home/abdenour/.local/lib/python3.10/site-packages/flwr/client/client.py", line 234, in maybe_call_fit
    return client.fit(fit_ins)
  File "/home/abdenour/.local/lib/python3.10/site-packages/flwr/client/numpy_client.py", line 238, in _fit
    results = self.numpy_client.fit(parameters, ins.config)  # type: ignore
  File "/home/abdenour/fl_with_flower/fednova_vgg16/fednova_vgg16/client.py", line 69, in fit
    train(self.model, trainloader, self.optimizer, epochs=num_epochs, device=self.device)
  File "/home/abdenour/fl_with_flower/fednova_vgg16/fednova_vgg16/utils.py", line 57, in train
    loss = criterion(net(images), labels)
  File "/home/abdenour/anaconda3/envs/fl/lib/python3.10/site-packages/torch/nn/modules/module.py", line 1553, in _wrapped_call_impl
    return self._call_impl(*args, **kwargs)
  File "/home/abdenour/anaconda3/envs/fl/lib/python3.10/site-packages/torch/nn/modules/module.py", line 1562, in _call_impl
    return forward_call(*args, **kwargs)
  File "/home/abdenour/anaconda3/envs/fl/lib/python3.10/site-packages/torchvision/models/vgg.py", line 66, in forward
    x = self.features(x)
  File "/home/abdenour/anaconda3/envs/fl/lib/python3.10/site-packages/torch/nn/modules/module.py", line 1553, in _wrapped_call_impl
    return self._call_impl(*args, **kwargs)
  File "/home/abdenour/anaconda3/envs/fl/lib/python3.10/site-packages/torch/nn/modules/module.py", line 1562, in _call_impl
    return forward_call(*args, **kwargs)
  File "/home/abdenour/anaconda3/envs/fl/lib/python3.10/site-packages/torch/nn/modules/container.py", line 219, in forward
    input = module(input)
  File "/home/abdenour/anaconda3/envs/fl/lib/python3.10/site-packages/torch/nn/modules/module.py", line 1553, in _wrapped_call_impl
    return self._call_impl(*args, **kwargs)
  File "/home/abdenour/anaconda3/envs/fl/lib/python3.10/site-packages/torch/nn/modules/module.py", line 1562, in _call_impl
    return forward_call(*args, **kwargs)
  File "/home/abdenour/anaconda3/envs/fl/lib/python3.10/site-packages/torch/nn/modules/conv.py", line 458, in forward
    return self._conv_forward(input, self.weight, self.bias)
  File "/home/abdenour/anaconda3/envs/fl/lib/python3.10/site-packages/torch/nn/modules/conv.py", line 454, in _conv_forward
    return F.conv2d(input, weight, bias, self.stride,
torch.OutOfMemoryError: CUDA out of memory. Tried to allocate 784.00 MiB. GPU 0 has a total capacity of 47.33 GiB of which 370.81 MiB is free. Process 2279413 has 11.11 GiB memory in use. Process 2265701 has 2.37 GiB memory in use. Process 2279412 has 11.11 GiB memory in use. Process 2394562 has 11.11 GiB memory in use. Process 2380775 has 2.37 GiB memory in use. Process 2394560 has 6.43 GiB memory in use. Including non-PyTorch memory, this process has 1.61 GiB memory in use. Process 2394559 has 816.00 MiB memory in use. Of the allocated memory 1.30 GiB is allocated by PyTorch, and 6.08 MiB is reserved by PyTorch but unallocated. If reserved but unallocated memory is large try setting PYTORCH_CUDA_ALLOC_CONF=expandable_segments:True to avoid fragmentation.  See documentation for Memory Management  (https://pytorch.org/docs/stable/notes/cuda.html#environment-variables)

The above exception was the direct cause of the following exception:

[36mray::ClientAppActor.run()[39m (pid=2394561, ip=115.145.172.224, actor_id=8181e9f2655e637b888f746801000000, repr=<flwr.simulation.ray_transport.ray_actor.ClientAppActor object at 0x7efcb00996f0>)
  File "/home/abdenour/.local/lib/python3.10/site-packages/flwr/simulation/ray_transport/ray_actor.py", line 63, in run
    raise ClientAppException(str(ex)) from ex
flwr.client.client_app.ClientAppException: 
Exception ClientAppException occurred. Message: CUDA out of memory. Tried to allocate 784.00 MiB. GPU 0 has a total capacity of 47.33 GiB of which 370.81 MiB is free. Process 2279413 has 11.11 GiB memory in use. Process 2265701 has 2.37 GiB memory in use. Process 2279412 has 11.11 GiB memory in use. Process 2394562 has 11.11 GiB memory in use. Process 2380775 has 2.37 GiB memory in use. Process 2394560 has 6.43 GiB memory in use. Including non-PyTorch memory, this process has 1.61 GiB memory in use. Process 2394559 has 816.00 MiB memory in use. Of the allocated memory 1.30 GiB is allocated by PyTorch, and 6.08 MiB is reserved by PyTorch but unallocated. If reserved but unallocated memory is large try setting PYTORCH_CUDA_ALLOC_CONF=expandable_segments:True to avoid fragmentation.  See documentation for Memory Management  (https://pytorch.org/docs/stable/notes/cuda.html#environment-variables)

[2024-09-19 01:29:34,708][flwr][ERROR] - [36mray::ClientAppActor.run()[39m (pid=2394561, ip=115.145.172.224, actor_id=8181e9f2655e637b888f746801000000, repr=<flwr.simulation.ray_transport.ray_actor.ClientAppActor object at 0x7efcb00996f0>)
  File "/home/abdenour/.local/lib/python3.10/site-packages/flwr/client/client_app.py", line 143, in __call__
    return self._call(message, context)
  File "/home/abdenour/.local/lib/python3.10/site-packages/flwr/client/client_app.py", line 126, in ffn
    out_message = handle_legacy_message_from_msgtype(
  File "/home/abdenour/.local/lib/python3.10/site-packages/flwr/client/message_handler/message_handler.py", line 129, in handle_legacy_message_from_msgtype
    fit_res = maybe_call_fit(
  File "/home/abdenour/.local/lib/python3.10/site-packages/flwr/client/client.py", line 234, in maybe_call_fit
    return client.fit(fit_ins)
  File "/home/abdenour/.local/lib/python3.10/site-packages/flwr/client/numpy_client.py", line 238, in _fit
    results = self.numpy_client.fit(parameters, ins.config)  # type: ignore
  File "/home/abdenour/fl_with_flower/fednova_vgg16/fednova_vgg16/client.py", line 69, in fit
    train(self.model, trainloader, self.optimizer, epochs=num_epochs, device=self.device)
  File "/home/abdenour/fl_with_flower/fednova_vgg16/fednova_vgg16/utils.py", line 57, in train
    loss = criterion(net(images), labels)
  File "/home/abdenour/anaconda3/envs/fl/lib/python3.10/site-packages/torch/nn/modules/module.py", line 1553, in _wrapped_call_impl
    return self._call_impl(*args, **kwargs)
  File "/home/abdenour/anaconda3/envs/fl/lib/python3.10/site-packages/torch/nn/modules/module.py", line 1562, in _call_impl
    return forward_call(*args, **kwargs)
  File "/home/abdenour/anaconda3/envs/fl/lib/python3.10/site-packages/torchvision/models/vgg.py", line 66, in forward
    x = self.features(x)
  File "/home/abdenour/anaconda3/envs/fl/lib/python3.10/site-packages/torch/nn/modules/module.py", line 1553, in _wrapped_call_impl
    return self._call_impl(*args, **kwargs)
  File "/home/abdenour/anaconda3/envs/fl/lib/python3.10/site-packages/torch/nn/modules/module.py", line 1562, in _call_impl
    return forward_call(*args, **kwargs)
  File "/home/abdenour/anaconda3/envs/fl/lib/python3.10/site-packages/torch/nn/modules/container.py", line 219, in forward
    input = module(input)
  File "/home/abdenour/anaconda3/envs/fl/lib/python3.10/site-packages/torch/nn/modules/module.py", line 1553, in _wrapped_call_impl
    return self._call_impl(*args, **kwargs)
  File "/home/abdenour/anaconda3/envs/fl/lib/python3.10/site-packages/torch/nn/modules/module.py", line 1562, in _call_impl
    return forward_call(*args, **kwargs)
  File "/home/abdenour/anaconda3/envs/fl/lib/python3.10/site-packages/torch/nn/modules/conv.py", line 458, in forward
    return self._conv_forward(input, self.weight, self.bias)
  File "/home/abdenour/anaconda3/envs/fl/lib/python3.10/site-packages/torch/nn/modules/conv.py", line 454, in _conv_forward
    return F.conv2d(input, weight, bias, self.stride,
torch.OutOfMemoryError: CUDA out of memory. Tried to allocate 784.00 MiB. GPU 0 has a total capacity of 47.33 GiB of which 370.81 MiB is free. Process 2279413 has 11.11 GiB memory in use. Process 2265701 has 2.37 GiB memory in use. Process 2279412 has 11.11 GiB memory in use. Process 2394562 has 11.11 GiB memory in use. Process 2380775 has 2.37 GiB memory in use. Process 2394560 has 6.43 GiB memory in use. Including non-PyTorch memory, this process has 1.61 GiB memory in use. Process 2394559 has 816.00 MiB memory in use. Of the allocated memory 1.30 GiB is allocated by PyTorch, and 6.08 MiB is reserved by PyTorch but unallocated. If reserved but unallocated memory is large try setting PYTORCH_CUDA_ALLOC_CONF=expandable_segments:True to avoid fragmentation.  See documentation for Memory Management  (https://pytorch.org/docs/stable/notes/cuda.html#environment-variables)

The above exception was the direct cause of the following exception:

[36mray::ClientAppActor.run()[39m (pid=2394561, ip=115.145.172.224, actor_id=8181e9f2655e637b888f746801000000, repr=<flwr.simulation.ray_transport.ray_actor.ClientAppActor object at 0x7efcb00996f0>)
  File "/home/abdenour/.local/lib/python3.10/site-packages/flwr/simulation/ray_transport/ray_actor.py", line 63, in run
    raise ClientAppException(str(ex)) from ex
flwr.client.client_app.ClientAppException: 
Exception ClientAppException occurred. Message: CUDA out of memory. Tried to allocate 784.00 MiB. GPU 0 has a total capacity of 47.33 GiB of which 370.81 MiB is free. Process 2279413 has 11.11 GiB memory in use. Process 2265701 has 2.37 GiB memory in use. Process 2279412 has 11.11 GiB memory in use. Process 2394562 has 11.11 GiB memory in use. Process 2380775 has 2.37 GiB memory in use. Process 2394560 has 6.43 GiB memory in use. Including non-PyTorch memory, this process has 1.61 GiB memory in use. Process 2394559 has 816.00 MiB memory in use. Of the allocated memory 1.30 GiB is allocated by PyTorch, and 6.08 MiB is reserved by PyTorch but unallocated. If reserved but unallocated memory is large try setting PYTORCH_CUDA_ALLOC_CONF=expandable_segments:True to avoid fragmentation.  See documentation for Memory Management  (https://pytorch.org/docs/stable/notes/cuda.html#environment-variables)
[2024-09-19 01:29:34,709][flwr][INFO] - aggregate_fit: received 1 results and 4 failures
[2024-09-19 01:29:35,122][flwr][WARNING] - No fit_metrics_aggregation_fn provided
[2024-09-19 01:29:46,458][flwr][INFO] - fit progress: (1, 339.11098527908325, {'accuracy': 0.07132417421806489}, 23.293164694216102)
[2024-09-19 01:29:46,460][flwr][INFO] - configure_evaluate: strategy sampled 2 clients (out of 50)
