[2024-09-19 01:19:31,554][flwr][INFO] - Starting Flower simulation, config: num_rounds=100, no round_timeout
[2024-09-19 01:19:34,994][flwr][INFO] - Flower VCE: Ray initialized with resources: {'CPU': 256.0, 'memory': 150560957850.0, 'GPU': 1.0, 'accelerator_type:G': 1.0, 'object_store_memory': 68811839078.0, 'node:115.145.172.224': 1.0, 'node:__internal_head__': 1.0}
[2024-09-19 01:19:34,995][flwr][INFO] - Optimize your simulation with Flower VCE: https://flower.ai/docs/framework/how-to-run-simulations.html
[2024-09-19 01:19:34,995][flwr][INFO] - Flower VCE: Resources for each Virtual Client: {'num_cpus': 64, 'num_gpus': 0.1}
[2024-09-19 01:19:35,012][flwr][INFO] - Flower VCE: Creating VirtualClientEngineActorPool with 4 actors
[2024-09-19 01:19:35,012][flwr][INFO] - [INIT]
[2024-09-19 01:19:35,012][flwr][INFO] - Requesting initial parameters from one random client
[2024-09-19 01:19:40,301][flwr][ERROR] - Traceback (most recent call last):
  File "/home/abdenour/.local/lib/python3.10/site-packages/flwr/simulation/ray_transport/ray_client_proxy.py", line 94, in _submit_job
    out_mssg, updated_context = self.actor_pool.get_client_result(
  File "/home/abdenour/.local/lib/python3.10/site-packages/flwr/simulation/ray_transport/ray_actor.py", line 398, in get_client_result
    return self._fetch_future_result(cid)
  File "/home/abdenour/.local/lib/python3.10/site-packages/flwr/simulation/ray_transport/ray_actor.py", line 279, in _fetch_future_result
    res_cid, out_mssg, updated_context = ray.get(
  File "/home/abdenour/.local/lib/python3.10/site-packages/ray/_private/auto_init_hook.py", line 21, in auto_init_wrapper
    return fn(*args, **kwargs)
  File "/home/abdenour/.local/lib/python3.10/site-packages/ray/_private/client_mode_hook.py", line 103, in wrapper
    return func(*args, **kwargs)
  File "/home/abdenour/.local/lib/python3.10/site-packages/ray/_private/worker.py", line 2667, in get
    values, debugger_breakpoint = worker.get_objects(object_refs, timeout=timeout)
  File "/home/abdenour/.local/lib/python3.10/site-packages/ray/_private/worker.py", line 864, in get_objects
    raise value.as_instanceof_cause()
ray.exceptions.RayTaskError(ClientAppException): [36mray::ClientAppActor.run()[39m (pid=2299387, ip=115.145.172.224, actor_id=266eda842cba35ea0f9c26b801000000, repr=<flwr.simulation.ray_transport.ray_actor.ClientAppActor object at 0x7f4da454d780>)
  File "/home/abdenour/.local/lib/python3.10/site-packages/flwr/client/client_app.py", line 143, in __call__
    return self._call(message, context)
  File "/home/abdenour/.local/lib/python3.10/site-packages/flwr/client/client_app.py", line 126, in ffn
    out_message = handle_legacy_message_from_msgtype(
  File "/home/abdenour/.local/lib/python3.10/site-packages/flwr/client/message_handler/message_handler.py", line 95, in handle_legacy_message_from_msgtype
    client = client_fn(context)
  File "/home/abdenour/fl_with_flower/fednova_vgg16/fednova_vgg16/client.py", line 130, in client_fn
    return FlowerClient(trainset, valset, num_classes, config_fit, client_dataset_ratio, context.node_config).to_client()
  File "/home/abdenour/fl_with_flower/fednova_vgg16/fednova_vgg16/client.py", line 34, in __init__
    self.model.classifier[1] = nn.Linear(self.model.last_channel, num_classes)
  File "/home/abdenour/anaconda3/envs/fl/lib/python3.10/site-packages/torch/nn/modules/module.py", line 1729, in __getattr__
    raise AttributeError(f"'{type(self).__name__}' object has no attribute '{name}'")
AttributeError: 'VGG' object has no attribute 'last_channel'

The above exception was the direct cause of the following exception:

[36mray::ClientAppActor.run()[39m (pid=2299387, ip=115.145.172.224, actor_id=266eda842cba35ea0f9c26b801000000, repr=<flwr.simulation.ray_transport.ray_actor.ClientAppActor object at 0x7f4da454d780>)
  File "/home/abdenour/.local/lib/python3.10/site-packages/flwr/simulation/ray_transport/ray_actor.py", line 63, in run
    raise ClientAppException(str(ex)) from ex
flwr.client.client_app.ClientAppException: 
Exception ClientAppException occurred. Message: 'VGG' object has no attribute 'last_channel'

[2024-09-19 01:19:40,301][flwr][ERROR] - [36mray::ClientAppActor.run()[39m (pid=2299387, ip=115.145.172.224, actor_id=266eda842cba35ea0f9c26b801000000, repr=<flwr.simulation.ray_transport.ray_actor.ClientAppActor object at 0x7f4da454d780>)
  File "/home/abdenour/.local/lib/python3.10/site-packages/flwr/client/client_app.py", line 143, in __call__
    return self._call(message, context)
  File "/home/abdenour/.local/lib/python3.10/site-packages/flwr/client/client_app.py", line 126, in ffn
    out_message = handle_legacy_message_from_msgtype(
  File "/home/abdenour/.local/lib/python3.10/site-packages/flwr/client/message_handler/message_handler.py", line 95, in handle_legacy_message_from_msgtype
    client = client_fn(context)
  File "/home/abdenour/fl_with_flower/fednova_vgg16/fednova_vgg16/client.py", line 130, in client_fn
    return FlowerClient(trainset, valset, num_classes, config_fit, client_dataset_ratio, context.node_config).to_client()
  File "/home/abdenour/fl_with_flower/fednova_vgg16/fednova_vgg16/client.py", line 34, in __init__
    self.model.classifier[1] = nn.Linear(self.model.last_channel, num_classes)
  File "/home/abdenour/anaconda3/envs/fl/lib/python3.10/site-packages/torch/nn/modules/module.py", line 1729, in __getattr__
    raise AttributeError(f"'{type(self).__name__}' object has no attribute '{name}'")
AttributeError: 'VGG' object has no attribute 'last_channel'

The above exception was the direct cause of the following exception:

[36mray::ClientAppActor.run()[39m (pid=2299387, ip=115.145.172.224, actor_id=266eda842cba35ea0f9c26b801000000, repr=<flwr.simulation.ray_transport.ray_actor.ClientAppActor object at 0x7f4da454d780>)
  File "/home/abdenour/.local/lib/python3.10/site-packages/flwr/simulation/ray_transport/ray_actor.py", line 63, in run
    raise ClientAppException(str(ex)) from ex
flwr.client.client_app.ClientAppException: 
Exception ClientAppException occurred. Message: 'VGG' object has no attribute 'last_channel'
[2024-09-19 01:19:40,302][flwr][ERROR] - [36mray::ClientAppActor.run()[39m (pid=2299387, ip=115.145.172.224, actor_id=266eda842cba35ea0f9c26b801000000, repr=<flwr.simulation.ray_transport.ray_actor.ClientAppActor object at 0x7f4da454d780>)
  File "/home/abdenour/.local/lib/python3.10/site-packages/flwr/client/client_app.py", line 143, in __call__
    return self._call(message, context)
  File "/home/abdenour/.local/lib/python3.10/site-packages/flwr/client/client_app.py", line 126, in ffn
    out_message = handle_legacy_message_from_msgtype(
  File "/home/abdenour/.local/lib/python3.10/site-packages/flwr/client/message_handler/message_handler.py", line 95, in handle_legacy_message_from_msgtype
    client = client_fn(context)
  File "/home/abdenour/fl_with_flower/fednova_vgg16/fednova_vgg16/client.py", line 130, in client_fn
    return FlowerClient(trainset, valset, num_classes, config_fit, client_dataset_ratio, context.node_config).to_client()
  File "/home/abdenour/fl_with_flower/fednova_vgg16/fednova_vgg16/client.py", line 34, in __init__
    self.model.classifier[1] = nn.Linear(self.model.last_channel, num_classes)
  File "/home/abdenour/anaconda3/envs/fl/lib/python3.10/site-packages/torch/nn/modules/module.py", line 1729, in __getattr__
    raise AttributeError(f"'{type(self).__name__}' object has no attribute '{name}'")
AttributeError: 'VGG' object has no attribute 'last_channel'

The above exception was the direct cause of the following exception:

[36mray::ClientAppActor.run()[39m (pid=2299387, ip=115.145.172.224, actor_id=266eda842cba35ea0f9c26b801000000, repr=<flwr.simulation.ray_transport.ray_actor.ClientAppActor object at 0x7f4da454d780>)
  File "/home/abdenour/.local/lib/python3.10/site-packages/flwr/simulation/ray_transport/ray_actor.py", line 63, in run
    raise ClientAppException(str(ex)) from ex
flwr.client.client_app.ClientAppException: 
Exception ClientAppException occurred. Message: 'VGG' object has no attribute 'last_channel'
[2024-09-19 01:19:40,302][flwr][ERROR] - Traceback (most recent call last):
  File "/home/abdenour/.local/lib/python3.10/site-packages/flwr/simulation/app.py", line 339, in start_simulation
    hist = run_fl(
  File "/home/abdenour/.local/lib/python3.10/site-packages/flwr/server/server.py", line 490, in run_fl
    hist, elapsed_time = server.fit(
  File "/home/abdenour/.local/lib/python3.10/site-packages/flwr/server/server.py", line 93, in fit
    self.parameters = self._get_initial_parameters(server_round=0, timeout=timeout)
  File "/home/abdenour/.local/lib/python3.10/site-packages/flwr/server/server.py", line 282, in _get_initial_parameters
    get_parameters_res = random_client.get_parameters(
  File "/home/abdenour/.local/lib/python3.10/site-packages/flwr/simulation/ray_transport/ray_client_proxy.py", line 168, in get_parameters
    message_out = self._submit_job(message, timeout)
  File "/home/abdenour/.local/lib/python3.10/site-packages/flwr/simulation/ray_transport/ray_client_proxy.py", line 108, in _submit_job
    raise ex
  File "/home/abdenour/.local/lib/python3.10/site-packages/flwr/simulation/ray_transport/ray_client_proxy.py", line 94, in _submit_job
    out_mssg, updated_context = self.actor_pool.get_client_result(
  File "/home/abdenour/.local/lib/python3.10/site-packages/flwr/simulation/ray_transport/ray_actor.py", line 398, in get_client_result
    return self._fetch_future_result(cid)
  File "/home/abdenour/.local/lib/python3.10/site-packages/flwr/simulation/ray_transport/ray_actor.py", line 279, in _fetch_future_result
    res_cid, out_mssg, updated_context = ray.get(
  File "/home/abdenour/.local/lib/python3.10/site-packages/ray/_private/auto_init_hook.py", line 21, in auto_init_wrapper
    return fn(*args, **kwargs)
  File "/home/abdenour/.local/lib/python3.10/site-packages/ray/_private/client_mode_hook.py", line 103, in wrapper
    return func(*args, **kwargs)
  File "/home/abdenour/.local/lib/python3.10/site-packages/ray/_private/worker.py", line 2667, in get
    values, debugger_breakpoint = worker.get_objects(object_refs, timeout=timeout)
  File "/home/abdenour/.local/lib/python3.10/site-packages/ray/_private/worker.py", line 864, in get_objects
    raise value.as_instanceof_cause()
ray.exceptions.RayTaskError(ClientAppException): [36mray::ClientAppActor.run()[39m (pid=2299387, ip=115.145.172.224, actor_id=266eda842cba35ea0f9c26b801000000, repr=<flwr.simulation.ray_transport.ray_actor.ClientAppActor object at 0x7f4da454d780>)
  File "/home/abdenour/.local/lib/python3.10/site-packages/flwr/client/client_app.py", line 143, in __call__
    return self._call(message, context)
  File "/home/abdenour/.local/lib/python3.10/site-packages/flwr/client/client_app.py", line 126, in ffn
    out_message = handle_legacy_message_from_msgtype(
  File "/home/abdenour/.local/lib/python3.10/site-packages/flwr/client/message_handler/message_handler.py", line 95, in handle_legacy_message_from_msgtype
    client = client_fn(context)
  File "/home/abdenour/fl_with_flower/fednova_vgg16/fednova_vgg16/client.py", line 130, in client_fn
    return FlowerClient(trainset, valset, num_classes, config_fit, client_dataset_ratio, context.node_config).to_client()
  File "/home/abdenour/fl_with_flower/fednova_vgg16/fednova_vgg16/client.py", line 34, in __init__
    self.model.classifier[1] = nn.Linear(self.model.last_channel, num_classes)
  File "/home/abdenour/anaconda3/envs/fl/lib/python3.10/site-packages/torch/nn/modules/module.py", line 1729, in __getattr__
    raise AttributeError(f"'{type(self).__name__}' object has no attribute '{name}'")
AttributeError: 'VGG' object has no attribute 'last_channel'

The above exception was the direct cause of the following exception:

[36mray::ClientAppActor.run()[39m (pid=2299387, ip=115.145.172.224, actor_id=266eda842cba35ea0f9c26b801000000, repr=<flwr.simulation.ray_transport.ray_actor.ClientAppActor object at 0x7f4da454d780>)
  File "/home/abdenour/.local/lib/python3.10/site-packages/flwr/simulation/ray_transport/ray_actor.py", line 63, in run
    raise ClientAppException(str(ex)) from ex
flwr.client.client_app.ClientAppException: 
Exception ClientAppException occurred. Message: 'VGG' object has no attribute 'last_channel'

[2024-09-19 01:19:40,308][flwr][ERROR] - Your simulation crashed :(. This could be because of several reasons. The most common are: 
	 > Sometimes, issues in the simulation code itself can cause crashes. It's always a good idea to double-check your code for any potential bugs or inconsistencies that might be contributing to the problem. For example: 
		 - You might be using a class attribute in your clients that hasn't been defined.
		 - There could be an incorrect method call to a 3rd party library (e.g., PyTorch).
		 - The return types of methods in your clients/strategies might be incorrect.
	 > Your system couldn't fit a single VirtualClient: try lowering `client_resources`.
	 > All the actors in your pool crashed. This could be because: 
		 - You clients hit an out-of-memory (OOM) error and actors couldn't recover from it. Try launching your simulation with more generous `client_resources` setting (i.e. it seems {'num_cpus': 64, 'num_gpus': 0.1} is not enough for your run). Use fewer concurrent actors. 
		 - You were running a multi-node simulation and all worker nodes disconnected. The head node might still be alive but cannot accommodate any actor with resources: {'num_cpus': 64, 'num_gpus': 0.1}.
Take a look at the Flower simulation examples for guidance <https://flower.ai/docs/framework/how-to-run-simulations.html>.
